Workbook

Sheet Fr-01
B1: รายละเอียดขององค์กร | I1: TCFO_R_01 Version 04 : 21/2/2020
B3: ชื่อฟอร์ม | C3: บัญชีรายการก๊าซเรือนกระจก | E3: องค์กร | G3: =B6 | I3: หน้าที่ | J3: 1
B4: รหัสฟอร์ม | C4: Fr-01 | E4: ผู้จัดทำ | G4: บริษัท อีโค เซ็นทริก คอร์ปอเรชั่น จำกัด | I4: วันที่จัดทำ | J4: 243820
B6: บริษัท มัลติแบกซ์ จำกัด (มหาชน)
A8: รูปขององค์กร | F8: ขอบเขตขององค์กร
F9: ประเภท 1 | H9: ='Fr-04.1'!B10
H10: ='Fr-04.1'!B11
H11: ='Fr-04.1'!B12
H12: ='Fr-04.1'!B13
H13: ='Fr-04.1'!B14
H14: ='Fr-04.1'!B15
H15: ='Fr-04.1'!B16
H16: ='Fr-04.1'!B17
H17: ='Fr-04.1'!B19
H18: ='Fr-04.1'!B21
H19: ='Fr-04.1'!B22
H20: ='Fr-04.1'!B24
H21: ='Fr-04.1'!B25
H22: ='Fr-04.1'!B26
H23: ='Fr-04.1'!B27
H24: ='Fr-04.1'!B28
H25: ='Fr-04.1'!B29
H26: ='Fr-04.1'!B30
H27: ='Fr-04.1'!B31
H28: ='Fr-04.1'!B32
F29: ประเภท 2 | H29: ='Fr-04.1'!B45
F32: ประเภท 3 | H32: ='Fr-04.1'!B50
H33: ='Fr-04.1'!B51
H34: ='Fr-04.1'!B52
H35: ='Fr-04.1'!B53
F36: ระยะเวลาเก็บข้อมูล | H36: 1 มกราคม - 31 ธันวาคม 2566
F37: ผลผลิต | H37: 9586 | J37: ตัน
F38: ปีฐาน | H38: 1 มกราคม - 31 ธันวาคม 2566
F39: ผลผลิตปีฐาน | H39: 9586 | J39: =J37
F40: ข้อมูลองค์กร
F41: 1 | G41: ผลิตสินค้าเม็ดพลาสติก
F42: 2 | G42: ผลิตสินค้าถุงพลาสติก
F43: 3
F44: 4
F45: 5
...

Sheet Fr-02
B1: แผนภาพองค์กร | L1: TCFO_R_01 Version 04 : 21/2/2020
B3: ชื่อฟอร์ม | C3: บัญชีรายการก๊าซเรือนกระจก | F3: องค์กร | G3: ='Fr-01'!$B$6 | L3: หน้าที่ | M3: 2
B4: รหัสฟอร์ม | C4: Fr-02 | F4: ผู้จัดทำ | G4: ='Fr-01'!$G$4 | L4: วันที่ | M4: ='Fr-01'!J4

Sheet Fr-03.1
B1: แผนภาพแสดงโครงสร้างขององค์กรและหน้าที่ความรับผิดชอบ | L1: TCFO_R_01 Version 04 : 21/2/2020
B3: ชื่อฟอร์ม | C3: บัญชีรายการก๊าซเรือนกระจก | F3: องค์กร | G3: ='Fr-01'!$B$6 | L3: หน้าที่ | M3: 3
B4: รหัสฟอร์ม | C4: Fr-03.1 | F4: ผู้จัดทำ | G4: ='Fr-01'!$G$4 | L4: วันที่ | M4: ='Fr-01'!J4
A35: จัดทำโดย | B35: ='Fr-01'!G4 | J35: เสร็จสิ้นวันที่ | K35: 243829

Sheet Fr-03.2
B1: ประเมินความมีนัยสำคัญของการปล่อยก๊าซเรือนกระจกทางอ้อม (SCOPE 3) | O1: TCFO_R_01 Version 04 : 21/2/2020
B3: ชื่อฟอร์ม | C3: ประเมินความมีนัยสำคัญ Scope3 | E3: องค์กร | F3: ='Fr-01'!G3 | O3: หน้าที่ | P3: 3
B4: รหัสฟอร์ม | C4: Fr-03.2 | E4: ผู้จัดทำ | F4: ='Fr-01'!G4 | O4: วันที่ | P4: ='Fr-01'!J4
A6: คำอธิบาย | B6: องค์กรจะต้องคัดเลือกแหล่งปล่อยก๊าซเรือนกระจกทางอ้อม (Scope 3) โดยกำหนดเกณฑ์ในการประเมินความมีนัยสำคัญของการปล่อยก๊าซเรือนกระจกทางอ้อม (Scope 3)
A8: ประเด็นที่ต้องพิจารณา | C8: คำอธิบาย
A9: Source of GHG | C9: องค์กรมีแหล่งปล่อยก๊าซเรือนกระจกนี้หรือไม่
A10: ขนาด (Magnitude or Size) | C10: เป็นกิจกรรมการปล่อยหรือดูดกลับก๊าซเรือนกระจกทางอ้อมซึ่งถูกสันนิษฐานว่ามีปริมาณการปล่อยหรือดูดกลับก๊าซเรือนกระจกในปริมาณมากอย่างมีนัยสำคัญ
A11: ระดับของแรงจูงใจ (Level of influence (Reduction of potential)) | C11: เป็นกิจกรรมการปล่อยหรือดูดกลับก๊าซเรือนกระจกที่องค์กรมีความสามารถในการตรวจติดตามและลดปริมาณการปล่อยหรือดูดกลับก๊าซเรือนกระจกจากกิจกรรมนั้น(ตัวอย่างเช่นเป็นกิจกรรมที่เกี่ยวข้องกับการประเมินประสิทธิภาพพลังงาน การออกแบบเชิงนิเวศเศรษฐกิจ, เกี่ยวข้องกับข้อตกลงที่มีกับลูกค้า, เกี่ยวข้องกับข้อกำหนดขอบเขตงานจากผู้ว่าจ้าง)
A12: ความเสี่ยง หรือ โอกาส Risk or opportunity | C12: เป็นกิจกรรมการปล่อยหรือดูดกลับก๊าซเรือนกระจกทางอ้อมซึ่งมีส่วนทำให้องค์กรได้รับความเสี่ยง (ตัวอย่างของความเสี่ยงที่มีความเชื่อมโยงกับการเปลี่ยนแปลงสภาพภูมิอากาศ เช่น ความเสี่ยงทางด้านการเงิน, ความเสี่ยงทางด้านกฎระเบียบข้อบังคับ, ความเสี่ยงตลอดห่วงโซ่อุปทาน, ความเสี่ยงเกี่ยวกับสินค้าและลูกค้า, ความเสี่ยงเกี่ยวกับการดำเนินคดี และ ความเสี่ยงด้านชื่อเสียง) หรือได้รับโอกาสต่างๆ ทางธุรกิจ (เช่น การเข้าสู่ช่องทางตลาดใหม่ การเข้าสู่ระบบธุรกิจในรูปแบบใหม่)
A13: Sector Guidance | C13: เป็นกิจกรรมการปล่อยก๊าซเรือนกระจกที่ถูกถือว่ามีนัยสำคัญสำหรับอุตสาหกรรมที่กำลังพิจารณา ตามที่กำหนดไว้ในคู่มือหรือแนวทางที่เฉพาะเจาะจงสำหรับอุตสาหกรรมนั้น
A14: Outsourcing | C14: เป็นกิจกรรมการปล่อยและดูดกลับก๊าซเรือนกระจกทางอ้อมที่เกิดจากการจัดจ้างบุคคลหรือหน่วยงานภายนอกเข้ามาดำเนินกิจกรรมที่ถือว่า เป็นกิจกรรมหลักในการดำเนินธุรกิจขององค์กร
A15: Employee engagement | C15: เป็นกิจกรรมการปล่อยก๊าซเรือนกระจกทางอ้อมที่สามารถส่งเสริมให้เกิดการกระตุ้นให้พนักงานมีส่วนร่วมในการลดการปล่อยก๊าซเรือนกระจก ผ่านการลดการใช้พลังงาน หรือการทำงานร่วมกันเป็นทีมภายใต้หลักคิดที่เกี่ยวข้องกับการเปลี่ยนแปลงสภาพภูมิอากาศ (เช่น การสร้างแรงจูงใจในการอนุรักษ์พลังงาน, การเดินทาง โดยใช้รถร่วมกัน, การประเมินราคาคาร์บอนภายในองค์กร เป็นต้น)
A16: ที่มา : หัวข้อที่ 12 ข้อกำหนดในการคำนวณและรายงานคาร์บอนฟุตพริ้นท์ขององค์กร พิมพ์ครั้งที่ 7 (ฉบับปรับปรุงครั้งที่ 5, มกราคม 2564)
C19: น้ำหนักประเด็นที่พิจารณา | F19: 0.6 | G19: 0.2 | H19: 0.1 | I19: 0.1
A20: No. TGO | B20: Scope in ISO 14064-1 | C20: Category | D20: Source of GHG | E20: Source of EF | F20: Magnitude | G20: Level of influence (Reduction of potential) | H20: Risk | I20: Oppoturnity | J20: ผลคะแนน | K20: ผลการประเมิน | L20: ผลการคัดเลือก | M20: GHG (tCO2eq.) | N20: %
A21: 3.1 | B21: 4.1 | C21: Purchased Goods & Services
C22: ='Screen scope 3'!C3 | D22: 1 | E22: 1 | F22: 3 | G22: 3 | H22: 3 | I22: 5 | J22: =D22+E22+(F22*$F$19)+(G22*$G$19)+(H22*$H$19)+(I22*$I$19) | K22: มีนัยสำคัญ | L22: เลือกประเมิน | M22: ='Screen scope 3'!I3 | N22: ='Screen scope 3'!J3
C23: ='Screen scope 3'!C4 | D23: 1 | E23: 1 | F23: 3 | G23: 3 | H23: 3 | I23: 5 | J23: =D23+E23+(F23*$F$19)+(G23*$G$19)+(H23*$H$19)+(I23*$I$19) | K23: มีนัยสำคัญ | L23: เลือกประเมิน | M23: ='Screen scope 3'!I4 | N23: ='Screen scope 3'!J4
C24: ='Screen scope 3'!C5 | D24: 1 | E24: 1 | F24: 3 | G24: 3 | H24: 3 | I24: 5 | J24: =D24+E24+(F24*$F$19)+(G24*$G$19)+(H24*$H$19)+(I24*$I$19) | K24: มีนัยสำคัญ | L24: เลือกประเมิน | M24: ='Screen scope 3'!I5 | N24: ='Screen scope 3'!J5
C25: ='Screen scope 3'!C6 | D25: 1 | E25: 1 | F25: 1 | G25: 1 | H25: 1 | I25: 1 | J25: =D25+E25+(F25*$F$19)+(G25*$G$19)+(H25*$H$19)+(I25*$I$19) | K25: ไม่มีนัยสำคัญ | M25: ='Screen scope 3'!I6 | N25: ='Screen scope 3'!J6
C26: ='Screen scope 3'!C7 | D26: 1 | E26: 1 | F26: 1 | G26: 1 | H26: 1 | I26: 1 | J26: =D26+E26+(F26*$F$19)+(G26*$G$19)+(H26*$H$19)+(I26*$I$19) | K26: ไม่มีนัยสำคัญ | M26: ='Screen scope 3'!I7 | N26: ='Screen scope 3'!J7
C27: ='Screen scope 3'!C8 | D27: 1 | E27: 1 | F27: 1 | G27: 1 | H27: 1 | I27: 1 | J27: =D27+E27+(F27*$F$19)+(G27*$G$19)+(H27*$H$19)+(I27*$I$19) | K27: ไม่มีนัยสำคัญ | M27: ='Screen scope 3'!I8 | N27: ='Screen scope 3'!J8
C28: ='Screen scope 3'!C9 | D28: 1 | E28: 1 | F28: 1 | G28: 1 | H28: 1 | I28: 1 | J28: =D28+E28+(F28*$F$19)+(G28*$G$19)+(H28*$H$19)+(I28*$I$19) | K28: ไม่มีนัยสำคัญ | M28: ='Screen scope 3'!I9 | N28: ='Screen scope 3'!J9
C29: ='Screen scope 3'!C10 | D29: 1 | E29: 1 | F29: 1 | G29: 1 | H29: 1 | I29: 1 | J29: =D29+E29+(F29*$F$19)+(G29*$G$19)+(H29*$H$19)+(I29*$I$19) | K29: ไม่มีนัยสำคัญ | M29: ='Screen scope 3'!I10 | N29: ='Screen scope 3'!J10
C30: ='Screen scope 3'!C11 | D30: 1 | E30: 1 | F30: 1 | G30: 1 | H30: 1 | I30: 1 | J30: =D30+E30+(F30*$F$19)+(G30*$G$19)+(H30*$H$19)+(I30*$I$19) | K30: ไม่มีนัยสำคัญ | M30: ='Screen scope 3'!I11 | N30: ='Screen scope 3'!J11
C31: ='Screen scope 3'!C12 | D31: 1 | E31: 1 | F31: 1 | G31: 1 | H31: 1 | I31: 1 | J31: =D31+E31+(F31*$F$19)+(G31*$G$19)+(H31*$H$19)+(I31*$I$19) | K31: ไม่มีนัยสำคัญ | M31: ='Screen scope 3'!I12 | N31: ='Screen scope 3'!J12
C32: ='Screen scope 3'!C13 | D32: 1 | E32: 1 | F32: 1 | G32: 1 | H32: 1 | I32: 1 | J32: =D32+E32+(F32*$F$19)+(G32*$G$19)+(H32*$H$19)+(I32*$I$19) | K32: ไม่มีนัยสำคัญ | M32: ='Screen scope 3'!I13+'Screen scope 3'!I14 | N32: ='Screen scope 3'!J13+'Screen scope 3'!J14
A33: 3.2 | B33: 4.2 | C33: Capital goods | D33: 1 | E33: 0 | J33: =D33+E33+(F33*$F$19)+(G33*$G$19)+(H33*$H$19)+(I33*$I$19) | K33: ไม่มีนัยสำคัญ/มีนัยสำคัญ
A34: 3.3 | B34: 2.2 | C34: Fuel- and energy related activities
C35: ='Screen scope 3'!C16 | D35: 1 | E35: 1 | F35: 1 | G35: 1 | H35: 1 | I35: 1 | J35: =D35+E35+(F35*$F$19)+(G35*$G$19)+(H35*$H$19)+(I35*$I$19) | K35: ไม่มีนัยสำคัญ | M35: ='Screen scope 3'!I16 | N35: ='Screen scope 3'!J16
C36: ='Screen scope 3'!C17 | D36: 1 | E36: 1 | F36: 1 | G36: 1 | H36: 1 | I36: 1 | J36: =D36+E36+(F36*$F$19)+(G36*$G$19)+(H36*$H$19)+(I36*$I$19) | K36: ไม่มีนัยสำคัญ | M36: ='Screen scope 3'!I17 | N36: ='Screen scope 3'!J17
C37: ='Screen scope 3'!C18 | D37: 1 | E37: 1 | F37: 1 | G37: 1 | H37: 1 | I37: 1 | J37: =D37+E37+(F37*$F$19)+(G37*$G$19)+(H37*$H$19)+(I37*$I$19) | K37: ไม่มีนัยสำคัญ | M37: ='Screen scope 3'!I18 | N37: ='Screen scope 3'!J18
C38: ='Screen scope 3'!C19 | D38: 1 | E38: 1 | F38: 1 | G38: 1 | H38: 1 | I38: 1 | J38: =D38+E38+(F38*$F$19)+(G38*$G$19)+(H38*$H$19)+(I38*$I$19) | K38: ไม่มีนัยสำคัญ | M38: ='Screen scope 3'!I19 | N38: ='Screen scope 3'!J19
A39: 3.4 | B39: 3.1 | C39: Upstream transportation and distribution
C40: ='Screen scope 3'!C21 | D40: 1 | E40: 1 | F40: 1 | G40: 1 | H40: 1 | I40: 1 | J40: =D40+E40+(F40*$F$19)+(G40*$G$19)+(H40*$H$19)+(I40*$I$19) | K40: ไม่มีนัยสำคัญ | M40: ='Screen scope 3'!I21 | N40: ='Screen scope 3'!J21
C41: ='Screen scope 3'!C22 | D41: 1 | E41: 1 | F41: 1 | G41: 1 | H41: 1 | I41: 1 | J41: =D41+E41+(F41*$F$19)+(G41*$G$19)+(H41*$H$19)+(I41*$I$19) | K41: ไม่มีนัยสำคัญ | M41: ='Screen scope 3'!I22 | N41: ='Screen scope 3'!J22
C42: ='Screen scope 3'!C23 | D42: 1 | E42: 1 | F42: 1 | G42: 1 | H42: 1 | I42: 1 | J42: =D42+E42+(F42*$F$19)+(G42*$G$19)+(H42*$H$19)+(I42*$I$19) | K42: ไม่มีนัยสำคัญ | M42: ='Screen scope 3'!I23 | N42: ='Screen scope 3'!J23
C43: ='Screen scope 3'!C24 | D43: 1 | E43: 1 | F43: 1 | G43: 1 | H43: 1 | I43: 1 | J43: =D43+E43+(F43*$F$19)+(G43*$G$19)+(H43*$H$19)+(I43*$I$19) | K43: ไม่มีนัยสำคัญ | M43: ='Screen scope 3'!I24 | N43: ='Screen scope 3'!J24
C44: ='Screen scope 3'!C25 | D44: 1 | E44: 1 | F44: 1 | G44: 1 | H44: 1 | I44: 1 | J44: =D44+E44+(F44*$F$19)+(G44*$G$19)+(H44*$H$19)+(I44*$I$19) | K44: ไม่มีนัยสำคัญ | M44: ='Screen scope 3'!I25 | N44: ='Screen scope 3'!J25
C45: ='Screen scope 3'!C26 | D45: 1 | E45: 1 | F45: 1 | G45: 1 | H45: 1 | I45: 1 | J45: =D45+E45+(F45*$F$19)+(G45*$G$19)+(H45*$H$19)+(I45*$I$19) | K45: ไม่มีนัยสำคัญ | M45: ='Screen scope 3'!I26 | N45: ='Screen scope 3'!J26
...

Sheet Screen scope 3
A1: No. TGO | B1: Scope in ISO 14064-1 | C1: Category | D1: หน่วย | E1: ปริมาณ (ต่อปี) | F1: หมายเหตุ | G1: หลักฐานอ้างอิง (การได้มาซึ่งข้อมูล) | H1: ค่าการปล่อยก๊าซเรือนกระจก (EF) | I1: GHG (tCO2eq.) | J1: % | K1: หลักฐานอ้างอิง (Emission Factor)
A2: Scope 3.1 | B2: Scope 4.1 in ISO 14064-1 | C2: Purchased Goods & Services
C3: ='Scope 3.1.1 วัตถุดิบผลิต'!A4 | D3: ='Scope 3.1.1 วัตถุดิบผลิต'!E4 | E3: ='Scope 3.1.1 วัตถุดิบผลิต'!F4 | G3: ระบบ ERP | H3: =2.6258 | I3: =E3*H3/1000 | J3: =I3/$I$46*100 | K3: TGO-CFP-EF-(ก.ค. 65)-6 LDPE
C4: ='Scope 3.1.1 วัตถุดิบผลิต'!A7 | D4: ='Scope 3.1.1 วัตถุดิบผลิต'!E7 | E4: ='Scope 3.1.1 วัตถุดิบผลิต'!F7 | G4: ระบบ ERP | H4: =2.1356 | I4: =E4*H4/1000 | J4: =I4/$I$46*100 | K4: TGO-CFP-EF-(ก.ค. 65)-5 LLDPE
C5: ='Scope 3.1.1 วัตถุดิบผลิต'!A12 | D5: ='Scope 3.1.1 วัตถุดิบผลิต'!E12 | E5: ='Scope 3.1.1 วัตถุดิบผลิต'!F12 | G5: ระบบ ERP | H5: =6.7071 | I5: =E5*H5/1000 | J5: =I5/$I$46*100 | K5: TGO-CFP-EF-(ก.ค. 65)-3 HDPE
C6: ='Scope 3.1.1 วัตถุดิบผลิต'!A15 | D6: ='Scope 3.1.1 วัตถุดิบผลิต'!E15 | E6: ='Scope 3.1.1 วัตถุดิบผลิต'!F15 | G6: ระบบ ERP | H6: 1.8679 | I6: =E6*H6/1000 | J6: =I6/$I$46*100 | K6: TGO-CFP-EF-(ก.ค. 65)-597 กระดาษกล่องขาวเคลือบแป้ง/กระดาษกล่องแป้งหลังเทา
C7: ='Scope 3.1.1 วัตถุดิบผลิต'!A19 | D7: ='Scope 3.1.1 วัตถุดิบผลิต'!E19 | E7: ='Scope 3.1.1 วัตถุดิบผลิต'!F19 | G7: ระบบ ERP | H7: 1.6184 | I7: =E7*H7/1000 | J7: =I7/$I$46*100 | K7: TGO-CFP-EF-(ก.ค. 65)-596 กระดาษคราฟท์ ชนิดท าลอน
C8: ='Scope 3.1.2 น้ำประปา'!A3 | D8: ='Scope 3.1.2 น้ำประปา'!D3 | E8: ='Scope 3.1.2 น้ำประปา'!E3 | G8: ='Scope 3.1.2 น้ำประปา'!C3 | H8: 0.2575 | I8: =E8*H8/1000 | J8: =I8/$I$46*100 | K8: TGO-CFP-EF-(ก.ค. 65)-62 น้ำประปา-การนิคมอุตสาหกรรม
C9: ='Scope 3.1.2 น้ำประปา'!A8 | D9: ='Scope 3.1.2 น้ำประปา'!D8 | E9: ='Scope 3.1.2 น้ำประปา'!E8 | G9: ='Scope 3.1.2 น้ำประปา'!C8 | H9: 0.7948 | I9: =E9*H9/1000 | J9: =I9/$I$46*100 | K9: TGO-CFP-EF-(ก.ค. 65)-60 น้ำประปา-การประปานครหลวง
C10: ='Scope 3.1.3 กระดาษ A4'!A5 | D10: ='Scope 3.1.3 กระดาษ A4'!C5 | E10: ='Scope 3.1.3 กระดาษ A4'!D5 | G10: ใบสั่งซื้อ | H10: 2.102 | I10: =E10*H10/1000 | J10: =I10/$I$46*100 | K10: TGO-CFP-EF-(ก.ค. 65)-592 กระดาษพิมพ์เขียนแบบไม่เคลือบผิว
C11: ='Scope 3.1.3 กระดาษ A4'!A8 | D11: ='Scope 3.1.3 กระดาษ A4'!C8 | E11: ='Scope 3.1.3 กระดาษ A4'!D8 | G11: ใบสั่งซื้อ | H11: 2.102 | I11: =E11*H11/1000 | J11: =I11/$I$46*100 | K11: TGO-CFP-EF-(ก.ค. 65)-592 กระดาษพิมพ์เขียนแบบไม่เคลือบผิว
C12: ='1.4.4 ปุ๋ย'!A3 | D12: ='1.4.4 ปุ๋ย'!C3 | E12: ='1.4.4 ปุ๋ย'!D3 | G12: ='1.4.4 ปุ๋ย'!B3 | H12: ='1.4.4 ปุ๋ย'!Q4 | I12: =E12*H12/1000 | J12: =I12/$I$46*100 | K12: TGO guildline
C13: ='Scope 3.1.4 จ้างเหมารถพนักงาน'!A4 | D13: L | E13: ='Scope 3.1.4 จ้างเหมารถพนักงาน'!J4 | G13: ใบแจ้งหนี้ | H13: ='EF TGO AR5'!H29 | I13: =E13*H13/1000 | J13: =I13/$I$46*100 | K13: TGO-CFO-EF: sheet ET TGO AR5
C14: ='Scope 3.1.4 จ้างเหมารถพนักงาน'!A4 | D14: kg | E14: =E13*0.83 | G14: ใบแจ้งหนี้ | H14: 0.3522 | I14: =E14*H14/1000 | J14: =I14/$I$46*100 | K14: TGO-CFP-EF-(ก.ค. 65)-55 Diesel (น้ำมันดีเซล / น้ำมันโซล่าร์)
A15: Scope 3.3 | B15: Scope 2.2 in ISO 14064-1 | C15: Capital goods
C16: การได้มาของไฟฟ้า | D16: kwh | E16: ='Scope 2.1 Purchased Electricity'!E3+'Scope 2.1 Purchased Electricity'!E7+'Scope 2.1 Purchased Electricity'!E12+'Scope 2.1 Purchased Electricity'!E15 | G16: ใบแจ้งหนี้/หนังสือแจ้งค่าไฟฟ้า | H16: =0.5986-0.4999 | I16: =E16*H16/1000 | J16: =I16/$I$46*100 | K16: CFO-EF - CFP-EF-ไฟฟ้า
C17: การได้มา Acetylene | D17: kg | E17: ='1.1 Stationary'!D11 | G17: บิลเงินสด/ใบเสร็จรับเงิน | H17: 2.2804 | I17: =E17*H17/1000 | J17: =I17/$I$46*100 | K17: TGO-CFP-EF-(ก.ค. 65)-654 acetylene
C18: การได้มา Diesel | D18: kg | E18: =('1.1 Stationary'!D9+'1.2 Mobile'!F13+'1.2 Mobile'!F57)*0.83 | G18: Fleet card/ใบเสร็จรับเงิน | H18: 0.3522 | I18: =E18*H18/1000 | J18: =I18/$I$46*100 | K18: TGO-CFP-EF-(ก.ค. 65)-55 Diesel (น้ำมันดีเซล / น้ำมันโซล่าร์)
C19: การได้มา Gasoline | D19: kg | E19: =('1.1 Stationary'!D10+'1.2 Mobile'!F43)*0.75 | G19: Fleet card/ใบเสร็จรับเงิน | H19: 0.4024 | I19: =E19*H19/1000 | J19: =I19/$I$46*100 | K19: TGO-CFP-EF-(ก.ค. 65)-52 Gasoline (แก๊สโซลีน)
A20: Scope 3.4 | B20: Scope 3.1 in ISO 14064-1 | C20: Upstream transportation and distribution
C21: รถตู้บรรทุก 10 ล้อ 100% loading | D21: tkm | E21: ='Scope 3.4'!I4 | G21: ใบส่งสินค้า/ใบกำกับภาษี | H21: 0.0454 | I21: =E21*H21/1000 | J21: =I21/$I$46*100 | K21: TGO-CFP-EF-(ก.ค. 65)-125 รถตู้บรรทุก 10 ล้อ วิ่งปกติ 100% Loading
C22: รถตู้บรรทุก 10 ล้อ 0% loading | D22: km | E22: ='Scope 3.4'!J4 | G22: ใบส่งสินค้า/ใบกำกับภาษี | H22: 0.5747 | I22: =E22*H22/1000 | J22: =I22/$I$46*100 | K22: TGO-CFP-EF-(ก.ค. 65)-122 รถตู้บรรทุก 10 ล้อ วิ่งปกติ 0% Loading
C23: รถตู้บรรทุก 6 ล้อ ขนาดใหญ่ 100% loading | D23: tkm | E23: ='Scope 3.4'!K4 | G23: ใบส่งสินค้า/ใบกำกับภาษี | H23: 0.0547 | I23: =E23*H23/1000 | J23: =I23/$I$46*100 | K23: TGO-CFP-EF-(ก.ค. 65)-109 รถตู้บรรทุก 6 ล้อ ขนาดใหญ่ วิ่งปกติ 100% Loading
C24: รถตู้บรรทุก 6 ล้อ ขนาดใหญ่ 0% loading | D24: km | E24: ='Scope 3.4'!L4 | G24: ใบส่งสินค้า/ใบกำกับภาษี | H24: 0.4373 | I24: =E24*H24/1000 | J24: =I24/$I$46*100 | K24: TGO-CFP-EF-(ก.ค. 65)-106 รถตู้บรรทุก 6 ล้อ ขนาดใหญ่ วิ่งปกติ 0% Loading
C25: รถตู้บรรทุก 4 ล้อ 100% loading | D25: tkm | E25: ='Scope 3.4'!M4 | G25: ใบส่งสินค้า/ใบกำกับภาษี | H25: 0.1835 | I25: =E25*H25/1000 | J25: =I25/$I$46*100 | K25: TGO-CFP-EF-(ก.ค. 65)-77 รถตู้บรรทุก 4 ล้อ วิ่งแบบปกติ 100% Loading
C26: รถตู้บรรทุก 4 ล้อ 0% loading | D26: km | E26: ='Scope 3.4'!N4 | G26: ใบส่งสินค้า/ใบกำกับภาษี | H26: 0.3345 | I26: =E26*H26/1000 | J26: =I26/$I$46*100 | K26: TGO-CFP-EF-(ก.ค. 65)-74 รถตู้บรรทุก 4 ล้อ วิ่งแบบปกติ 0% Loading
C27: เรือบรรทุก container | D27: tkm | E27: ='Scope 3.4'!O4 | G27: ใบส่งสินค้า/ใบกำกับภาษี | H27: 0.0107 | I27: =E27*H27/1000 | J27: =I27/$I$46*100 | K27: TGO-CFP-EF-(ก.ค. 65)-255 เรือบรรทุก container
A28: Scope 3.5 | B28: Scope 4.3 in ISO 14064-1 | C28: Waste generated in operations
C29: การกำจัดของเสีย
C30: ='Scope 3.5'!A4 | D30: kg | E30: ='Scope 3.5'!F4 | G30: ใบกำกับการขนส่งขยะมูลฝอย | H30: 0.7933 | I30: =E30*H30/1000 | J30: =I30/$I$46*100 | K30: TGO-CFP-EF-(ก.ค. 65)-การฝังกลบขยะมูลฝอยชุมชนแบบถูกหลักสุขาภิบาล
C31: ='Scope 3.5'!A5 | D31: kg | E31: ='Scope 3.5'!F5 | G31: ใบกำกับการขนส่งของเสียอันตราย | H31: 0.7933 | I31: =E31*H31/1000 | J31: =I31/$I$46*100 | K31: TGO-CFP-EF-(ก.ค. 65)-การฝังกลบขยะมูลฝอยชุมชนแบบถูกหลักสุขาภิบาล (แทน)
C32: การขนส่ง
C33: รถกระบะบรรทุก 10 ล้อ วิ่งปกติ 100% loading | D33: tkm | E33: ='Scope 3.5'!F23 | G33: การประมาณการ | H33: 0.0533 | I33: =E33*H33/1000 | J33: =I33/$I$46*100
C34: รถกระบะบรรทุก 10 ล้อ วิ่งปกติ 0% loading | D34: km | E34: ='Scope 3.5'!G23 | G34: การประมาณการ | H34: 0.59 | I34: =E34*H34/1000 | J34: =I34/$I$46*100
C35: รถบรรทุกขยะ 6 ล้อ 100% loading | D35: tkm | E35: ='Scope 3.5'!J23 | G35: การประมาณการ | H35: 0.0475 | I35: =E35*H35/1000 | J35: =I35/$I$46*100 | K35: TGO-CFP-EF-(ก.ค. 65)-รถบรรทุกขยะ 6 ล้อ วิ่ง แบบปกติ 100% Loading
C36: รถบรรทุกขยะ 6 ล้อ 0% loading | D36: km | E36: ='Scope 3.5'!K23 | G36: การประมาณการ | H36: 0.4923 | I36: =E36*H36/1000 | J36: =I36/$I$46*100 | K36: TGO-CFP-EF-(ก.ค. 65)-รถบรรทุกขยะ 6 ล้อ วิ่งแบบปกติ 0% Loading
A37: Scope 3.7 | B37: Scope 3.3 in ISO 14064-1 | C37: Employee commuting
C38: น้ำมัน Gasoline จากการเดินทางของพนักงาน | D38: L | E38: ='Scope 3.7'!Q4 | G38: แบบสำรวจการเดินทางของพนักงาน | H38: ='EF TGO AR5'!H30 | I38: =E38*H38/1000 | J38: =I38/$I$46*100 | K38: TGO-CFO-EF-(เม.ย. 65)-Motor Gasoline - Mobile on road
C39: น้ำมัน Diesel จากการเดินทางของพนักงาน | D39: L | E39: ='Scope 3.7'!P4 | G39: แบบสำรวจการเดินทางของพนักงาน | H39: ='EF TGO AR5'!H32 | I39: =E39*H39/1000 | J39: =I39/$I$46*100 | K39: TGO-CFO-EF-(เม.ย. 65)-Gas/ Diesel Oil-Mobile on road
A40: Scope 3.9 | B40: Scope 3.2 in ISO 14064-1 | C40: Downstream transportation and distribution
...

Sheet Fr-04.1
B1: บัญชีรายการก๊าซเรือนกระจก | AO1: TCFO_R_01 Version 04 : 21/2/2020
B3: ชื่อฟอร์ม | C3: บัญชีรายการก๊าซเรือนกระจก | H3: องค์กร | I3: ='Fr-01'!$B$6 | AB3: ปีที่เก็บข้อมูล | AE3: ='Fr-01'!H36 | AO3: หน้าที่ | AR3: 4
B4: รหัสฟอร์ม | C4: Fr-04.1 | H4: ผู้จัดทำ | I4: ='Fr-01'!$G$4 | AO4: วันที่ | AR4: 45494
A6: ขอบเขต | B6: รายการ | C6: ค่า LCI | E6: GHG ที่ต้องรายงานตามข้อกำหนด | O6: GHG ที่อยู่นอกข้อกำหนด | Q6: Total (kgCO2e/หน่วย) | R6: ที่มา | Y6: Subsitute | Z6: แหล่งอ้างอิง | AA6: ผลคูณ (Ton GHG) | AG6: ผลคูณ (TonCO2e) | AO6: Total GHG | AP6: สัดส่วน (%) | AQ6: สัดส่วน (%) (SCOPE 1+2) | AR6: สัดส่วน (%) (SCOPE 1+2+3) | AS6: คำอธิบายเพิ่มเติม | AU6: GWP100
R7: 1st | T7: 2nd | X7: Other | AU7: ที่มา | AV7: IPCC, AR5
E8: ค่า EF (kg GHG/หน่วย) | M8: GWP100 | O8: ค่า EF (kg GHG/หน่วย) | P8: GWP100 | R8: Self collct | S8: Supplier | T8: TH LCI DB | U8: TGO EF | V8: Thai Res. | W8: Int. DB | AO8: (TonCO2e) | AU8: CO2 | AV8: 1
C9: หน่วย | D9: ปริมาณ | E9: CO2 | F9: Fossil CH4 | G9: CH4 | H9: N2O | I9: SF6 | J9: NF3 | K9: HFCs | L9: PFCs | M9: HFCs | N9: PFCs | AA9: CO2 | AB9: Fossil CH4 | AC9: CH4 | AD9: N2O | AE9: SF6 | AF9: NF3 | AG9: Fossil CH4 | AH9: CH4 | AI9: N2O | AJ9: SF6 | AK9: NF3 | AL9: HFCs | AM9: PFCs | AN9: Other | AU9: Fossil CH4 | AV9: 30
A10: ขอบเขต 1 | B10: Stationary combustion | Q10: =(E10*$AV$8)+(F10*$AV$9)+(G10*$AV$10)+(H10*$AV$11)+(I10*$AV$12)+(J10*$AV$13)+(K10*M10)+(L10*N10) | AA10: =D10*E10/1000 | AB10: =D10*F10/1000 | AC10: =D10*G10/1000 | AD10: =D10*H10/1000 | AE10: =D10*I10/1000 | AF10: =D10*J10/1000 | AG10: =D10*F10*$AV$9/1000 | AH10: =D10*G10*$AV$10/1000 | AI10: =D10*H10*$AV$11/1000 | AJ10: =D10*I10*$AV$12/1000 | AK10: =D10*J10*$AV$13/1000 | AL10: =D10*K10*M10/1000 | AM10: =D10*L10*N10/1000 | AO10: =D10*Q10/1000 | AP10: =AO10/$AO$36 | AQ10: =AO10/$AO$58 | AR10: =AO10/$AO$59 | AU10: CH4 | AV10: 28
B11: ='1.1 Stationary'!A9 | C11: ='1.1 Stationary'!C9 | D11: ='1.1 Stationary'!G4 | E11: ='EF TGO AR5'!D11 | F11: ='EF TGO AR5'!E11 | G11: ='EF TGO AR5'!F11 | H11: ='EF TGO AR5'!G11 | Q11: =(E11*$AV$8)+(F11*$AV$9)+(G11*$AV$10)+(H11*$AV$11)+(I11*$AV$12)+(J11*$AV$13)+(K11*M11)+(L11*N11) | U11: / | Z11: TGO CFO EF (เมษายน 2565):Gas/Diesel oil | AA11: =D11*E11/1000 | AB11: =D11*F11/1000 | AC11: =D11*G11/1000 | AD11: =D11*H11/1000 | AE11: =D11*I11/1000 | AF11: =D11*J11/1000 | AG11: =D11*F11*AJ13/1000 | AH11: =D11*G11*$AV$10/1000 | AI11: =D11*H11*$AV$11/1000 | AJ11: =D11*I11*$AV$12/1000 | AK11: =D11*J11*$AV$13/1000 | AL11: =D11*K11*M11/1000 | AM11: =D11*L11*N11/1000 | AO11: =D11*Q11/1000 | AP11: =AO11/$AO$36 | AQ11: =AO11/$AO$58 | AR11: =AO11/$AO$59 | AU11: N2O | AV11: 265
B12: ='1.1 Stationary'!A10 | C12: ='1.1 Stationary'!C10 | D12: ='1.1 Stationary'!J5 | E12: ='EF TGO AR5'!D17 | F12: ='EF TGO AR5'!E17 | G12: ='EF TGO AR5'!F17 | H12: ='EF TGO AR5'!G17 | Q12: =(E12*$AV$8)+(F12*$AV$9)+(G12*$AV$10)+(H12*$AV$11)+(I12*$AV$12)+(J12*$AV$13)+(K12*M12)+(L12*N12) | U12: / | Z12: TGO CFO EF (เมษายน 2565): Motor Gasoline | AA12: =D12*E12/1000 | AB12: =D12*F12/1000 | AC12: =D12*G12/1000 | AD12: =D12*H12/1000 | AE12: =D12*I12/1000 | AF12: =D12*J12/1000 | AG12: =D12*F12*$AV$9/1000 | AH12: =D12*G12*$AV$10/1000 | AI12: =D12*H12*$AV$11/1000 | AJ12: =D12*I12*$AV$12/1000 | AK12: =D12*J12*$AV$13/1000 | AL12: =D12*K12*M12/1000 | AM12: =D12*L12*N12/1000 | AO12: =D12*Q12/1000 | AP12: =AO12/$AO$36 | AQ12: =AO12/$AO$58 | AR12: =AO12/$AO$59 | AU12: SF6 | AV12: 23500 | AX12: =0.0025*265
B13: ='1.1 Stationary'!A11 | C13: ='1.1 Stationary'!C11 | D13: ='1.1 Stationary'!D11 | E13: ='EF (1)'!B9 | Q13: =(E13*$AV$8)+(F13*$AV$9)+(G13*$AV$10)+(H13*$AV$11)+(I13*$AV$12)+(J13*$AV$13)+(K13*M13)+(L13*N13) | X13: / | Z13: EF (1) สมการเคมี | AA13: =D13*E13/1000 | AB13: =D13*F13/1000 | AC13: =D13*G13/1000 | AD13: =D13*H13/1000 | AE13: =D13*I13/1000 | AF13: =D13*J13/1000 | AG13: =D13*F13*$AV$9/1000 | AH13: =D13*G13*$AV$10/1000 | AI13: =D13*H13*$AV$11/1000 | AJ13: =D13*I13*$AV$12/1000 | AK13: =D13*J13*$AV$13/1000 | AL13: =D13*K13*M13/1000 | AM13: =D13*L13*N13/1000 | AO13: =D13*Q13/1000 | AP13: =AO13/$AO$36 | AQ13: =AO13/$AO$58 | AR13: =AO13/$AO$59 | AU13: NF3 | AV13: 16100
B14: Biodiesel (Stationary combustion) | C14: kg | D14: ='1.1 Stationary'!I4 | G14: ='EF (1)'!F28*'EF (1)'!D28 | H14: ='EF (1)'!F28*'EF (1)'!E28 | Q14: =(E14*$AV$8)+(F14*$AV$9)+(G14*$AV$10)+(H14*$AV$11)+(I14*$AV$12)+(J14*$AV$13)+(K14*M14)+(L14*N14) | W14: / | Z14: IPCC, 2006 | AA14: =D14*E14/1000 | AB14: =D14*F14/1000 | AC14: =D14*G14/1000 | AD14: =D14*H14/1000 | AE14: =D14*I14/1000 | AF14: =D14*J14/1000 | AG14: =D14*F14*$AV$9/1000 | AH14: =D14*G14*$AV$10/1000 | AI14: =D14*H14*$AV$11/1000 | AJ14: =D14*I14*$AV$12/1000 | AK14: =D14*J14*$AV$13/1000 | AL14: =D14*K14*M14/1000 | AM14: =D14*L14*N14/1000 | AO14: =D14*Q14/1000 | AP14: =AO14/$AO$36 | AQ14: =AO14/$AO$58 | AR14: =AO14/$AO$59
B15: Biogasoline (Ethanol) (Stationary combustion) | C15: kg | D15: ='1.1 Stationary'!L5 | G15: ='EF (1)'!F29*'EF (1)'!D29 | H15: ='EF (1)'!F29*'EF (1)'!E29 | Q15: =(E15*$AV$8)+(F15*$AV$9)+(G15*$AV$10)+(H15*$AV$11)+(I15*$AV$12)+(J15*$AV$13)+(K15*M15)+(L15*N15) | W15: / | Z15: IPCC, 2006 | AA15: =D15*E15/1000 | AB15: =D15*F15/1000 | AC15: =D15*G15/1000 | AD15: =D15*H15/1000 | AE15: =D15*I15/1000 | AF15: =D15*J15/1000 | AG15: =D15*F15*$AV$9/1000 | AH15: =D15*G15*$AV$10/1000 | AI15: =D15*H15*$AV$11/1000 | AJ15: =D15*I15*$AV$12/1000 | AK15: =D15*J15*$AV$13/1000 | AL15: =D15*K15*M15/1000 | AM15: =D15*L15*N15/1000 | AO15: =D15*Q15/1000 | AP15: =AO15/$AO$36 | AQ15: =AO15/$AO$58 | AR15: =AO15/$AO$59
B16: Mobile combustion | Q16: =(E16*$AV$8)+(F16*$AV$9)+(G16*$AV$10)+(H16*$AV$11)+(I16*$AV$12)+(J16*$AV$13)+(K16*M16)+(L16*N16) | AA16: =D16*E16/1000 | AB16: =D16*F16/1000 | AC16: =D16*G16/1000 | AD16: =D16*H16/1000 | AE16: =D16*I16/1000 | AF16: =D16*J16/1000 | AG16: =D16*F16*$AV$9/1000 | AH16: =D16*G16*$AV$10/1000 | AI16: =D16*H16*$AV$11/1000 | AJ16: =D16*I16*$AV$12/1000 | AK16: =D16*J16*$AV$13/1000 | AL16: =D16*K16*M16/1000 | AM16: =D16*L16*N16/1000 | AO16: =D16*Q16/1000 | AP16: =AO16/$AO$36 | AQ16: =AO16/$AO$58 | AR16: =AO16/$AO$59
B17: น้ำมัน Diesel B7 รถยนต์องค์กร | C17: L | D17: ='1.2 Mobile'!G5 | E17: ='EF TGO AR5'!D32 | F17: ='EF TGO AR5'!E32 | G17: ='EF TGO AR5'!F32 | H17: ='EF TGO AR5'!G32 | Q17: =(E17*$AV$8)+(F17*$AV$9)+(G17*$AV$10)+(H17*$AV$11)+(I17*$AV$12)+(J17*$AV$13)+(K17*M17)+(L17*N17) | U17: / | Z17: TGO CFO EF (เมษายน 2565):Gas/Diesel (Mobile Combustion) | AA17: =D17*E17/1000 | AB17: =D17*F17/1000 | AC17: =D17*G17/1000 | AD17: =D17*H17/1000 | AE17: =D17*I17/1000 | AF17: =D17*J17/1000 | AG17: =D17*F17*$AV$9/1000 | AH17: =D17*G17*$AV$10/1000 | AI17: =D17*H17*$AV$11/1000 | AJ17: =D17*I17*$AV$12/1000 | AK17: =D17*J17*$AV$13/1000 | AL17: =D17*K17*M17/1000 | AM17: =D17*L17*N17/1000 | AO17: =D17*Q17/1000 | AP17: =AO17/$AO$36 | AQ17: =AO17/$AO$58 | AR17: =AO17/$AO$59
B18: น้ำมัน Diesel B10 รถยนต์องค์กร | C18: L | D18: ='1.2 Mobile'!G6 | E18: ='EF TGO AR5'!D32 | F18: ='EF TGO AR5'!E32 | G18: ='EF TGO AR5'!F32 | H18: ='EF TGO AR5'!G32 | Q18: =(E18*$AV$8)+(F18*$AV$9)+(G18*$AV$10)+(H18*$AV$11)+(I18*$AV$12)+(J18*$AV$13)+(K18*M18)+(L18*N18) | U18: / | Z18: TGO CFO EF (เมษายน 2565):Gas/Diesel (Mobile Combustion) | AA18: =D18*E18/1000 | AB18: =D18*F18/1000 | AC18: =D18*G18/1000 | AD18: =D18*H18/1000 | AE18: =D18*I18/1000 | AF18: =D18*J18/1000 | AG18: =D18*F18*$AV$9/1000 | AH18: =D18*G18*$AV$10/1000 | AI18: =D18*H18*$AV$11/1000 | AJ18: =D18*I18*$AV$12/1000 | AK18: =D18*J18*$AV$13/1000 | AL18: =D18*K18*M18/1000 | AM18: =D18*L18*N18/1000 | AO18: =D18*Q18/1000 | AP18: =AO18/$AO$36 | AQ18: =AO18/$AO$58 | AR18: =AO18/$AO$59
B19: น้ำมัน Gasohol 91/95 รถยนต์องค์กร | C19: L | D19: ='1.2 Mobile'!J7 | E19: ='EF TGO AR5'!D30 | F19: ='EF TGO AR5'!E30 | G19: ='EF TGO AR5'!F30 | H19: ='EF TGO AR5'!G30 | Q19: =(E19*$AV$8)+(F19*$AV$9)+(G19*$AV$10)+(H19*$AV$11)+(I19*$AV$12)+(J19*$AV$13)+(K19*M19)+(L19*N19) | U19: / | Z19: TGO CFO EF (เมษายน 2565): Motor gasoline-oxidation catalyst (Mobile Combustion on road) | AA19: =D19*E19/1000 | AB19: =D19*F19/1000 | AC19: =D19*G19/1000 | AD19: =D19*H19/1000 | AE19: =D19*I19/1000 | AF19: =D19*J19/1000 | AG19: =D19*F19*$AV$9/1000 | AH19: =D19*G19*$AV$10/1000 | AI19: =D19*H19*$AV$11/1000 | AJ19: =D19*I19*$AV$12/1000 | AK19: =D19*J19*$AV$13/1000 | AL19: =D19*K19*M19/1000 | AM19: =D19*L19*N19/1000 | AO19: =D19*Q19/1000 | AP19: =AO19/$AO$36 | AQ19: =AO19/$AO$58 | AR19: =AO19/$AO$59
B20: น้ำมัน Gasohol E20 รถยนต์องค์กร | C20: L | D20: ='1.2 Mobile'!J8 | E20: ='EF TGO AR5'!D30 | F20: ='EF TGO AR5'!E30 | G20: ='EF TGO AR5'!F30 | H20: ='EF TGO AR5'!G30 | Q20: =(E20*$AV$8)+(F20*$AV$9)+(G20*$AV$10)+(H20*$AV$11)+(I20*$AV$12)+(J20*$AV$13)+(K20*M20)+(L20*N20) | U20: / | Z20: TGO CFO EF (เมษายน 2565): Motor gasoline-oxidation catalyst (Mobile Combustion on road) | AA20: =D20*E20/1000 | AB20: =D20*F20/1000 | AC20: =D20*G20/1000 | AD20: =D20*H20/1000 | AE20: =D20*I20/1000 | AF20: =D20*J20/1000 | AG20: =D20*F20*$AV$9/1000 | AH20: =D20*G20*$AV$10/1000 | AI20: =D20*H20*$AV$11/1000 | AJ20: =D20*I20*$AV$12/1000 | AK20: =D20*J20*$AV$13/1000 | AL20: =D20*K20*M20/1000 | AM20: =D20*L20*N20/1000 | AO20: =D20*Q20/1000 | AP20: =AO20/$AO$36 | AQ20: =AO20/$AO$58 | AR20: =AO20/$AO$59
B21: น้ำมัน Diesel B7 FL/รถใช้ขนส่งภายในองค์กร (off-road) | C21: L | D21: ='1.2 Mobile'!G9 | E21: ='EF TGO AR5'!D40 | F21: ='EF TGO AR5'!E40 | G21: ='EF TGO AR5'!F40 | H21: ='EF TGO AR5'!G40 | Q21: =(E21*$AV$8)+(F21*$AV$9)+(G21*$AV$10)+(H21*$AV$11)+(I21*$AV$12)+(J21*$AV$13)+(K21*M21)+(L21*N21) | U21: / | Z21: TGO CFO EF (เมษายน 2565): Diesel Industry (Mobile Combustion off road) | AA21: =D21*E21/1000 | AB21: =D21*F21/1000 | AC21: =D21*G21/1000 | AD21: =D21*H21/1000 | AE21: =D21*I21/1000 | AF21: =D21*J21/1000 | AG21: =D21*F21*$AV$9/1000 | AH21: =D21*G21*$AV$10/1000 | AI21: =D21*H21*$AV$11/1000 | AJ21: =D21*I21*$AV$12/1000 | AK21: =D21*J21*$AV$13/1000 | AL21: =D21*K21*M21/1000 | AM21: =D21*L21*N21/1000 | AO21: =D21*Q21/1000 | AP21: =AO21/$AO$36 | AQ21: =AO21/$AO$58 | AR21: =AO21/$AO$59
B22: Biodiesel (Mobile combustion-on road) | C22: kg | D22: ='1.2 Mobile'!I5+'1.2 Mobile'!I6 | G22: ='EF (1)'!F30*'EF (1)'!D30 | H22: ='EF (1)'!F30*'EF (1)'!E30 | Q22: =(E22*$AV$8)+(F22*$AV$9)+(G22*$AV$10)+(H22*$AV$11)+(I22*$AV$12)+(J22*$AV$13)+(K22*M22)+(L22*N22) | W22: / | Z22: IPCC, 2006 | AA22: =D22*E22/1000 | AB22: =D22*F22/1000 | AC22: =D22*G22/1000 | AD22: =D22*H22/1000 | AE22: =D22*I22/1000 | AF22: =D22*J22/1000 | AG22: =D22*F22*$AV$9/1000 | AH22: =D22*G22*$AV$10/1000 | AI22: =D22*H22*$AV$11/1000 | AJ22: =D22*I22*$AV$12/1000 | AK22: =D22*J22*$AV$13/1000 | AL22: =D22*K22*M22/1000 | AM22: =D22*L22*N22/1000 | AO22: =D22*Q22/1000 | AP22: =AO22/$AO$36 | AQ22: =AO22/$AO$58 | AR22: =AO22/$AO$59
B23: Biodiesel (Mobile combustion-off road) | C23: kg | D23: ='1.2 Mobile'!I9 | G23: ='EF (1)'!F32*'EF (1)'!D32 | H23: ='EF (1)'!F32*'EF (1)'!E32 | Q23: =(E23*$AV$8)+(F23*$AV$9)+(G23*$AV$10)+(H23*$AV$11)+(I23*$AV$12)+(J23*$AV$13)+(K23*M23)+(L23*N23) | W23: / | Z23: IPCC, 2006 | AA23: =D23*E23/1000 | AB23: =D23*F23/1000 | AC23: =D23*G23/1000 | AD23: =D23*H23/1000 | AE23: =D23*I23/1000 | AF23: =D23*J23/1000 | AG23: =D23*F23*$AV$9/1000 | AH23: =D23*G23*$AV$10/1000 | AI23: =D23*H23*$AV$11/1000 | AJ23: =D23*I23*$AV$12/1000 | AK23: =D23*J23*$AV$13/1000 | AL23: =D23*K23*M23/1000 | AM23: =D23*L23*N23/1000 | AO23: =D23*Q23/1000 | AP23: =AO23/$AO$36 | AQ23: =AO23/$AO$58 | AR23: =AO23/$AO$59
B24: Biogasoline (Ethanol) (Mobile combustion) | C24: kg | D24: ='1.2 Mobile'!L7+'1.2 Mobile'!L8 | G24: ='EF (1)'!F31*'EF (1)'!D31 | H24: ='EF (1)'!F31*'EF (1)'!E31 | Q24: =(E24*$AV$8)+(F24*$AV$9)+(G24*$AV$10)+(H24*$AV$11)+(I24*$AV$12)+(J24*$AV$13)+(K24*M24)+(L24*N24) | W24: / | Z24: IPCC, 2006 | AA24: =D24*E24/1000 | AB24: =D24*F24/1000 | AC24: =D24*G24/1000 | AD24: =D24*H24/1000 | AE24: =D24*I24/1000 | AF24: =D24*J24/1000 | AG24: =D24*F24*$AV$9/1000 | AH24: =D24*G24*$AV$10/1000 | AI24: =D24*H24*$AV$11/1000 | AJ24: =D24*I24*$AV$12/1000 | AK24: =D24*J24*$AV$13/1000 | AL24: =D24*K24*M24/1000 | AM24: =D24*L24*N24/1000 | AO24: =D24*Q24/1000 | AP24: =AO24/$AO$36 | AQ24: =AO24/$AO$58 | AR24: =AO24/$AO$59
B25: Fugitive | Q25: =(E25*$AV$8)+(F25*$AV$9)+(G25*$AV$10)+(H25*$AV$11)+(I25*$AV$12)+(J25*$AV$13)+(K25*M25)+(L25*N25) | AA25: =D25*E25/1000 | AB25: =D25*F25/1000 | AC25: =D25*G25/1000 | AD25: =D25*H25/1000 | AE25: =D25*I25/1000 | AF25: =D25*J25/1000 | AG25: =D25*F25*$AV$9/1000 | AH25: =D25*G25*$AV$10/1000 | AI25: =D25*H25*$AV$11/1000 | AJ25: =D25*I25*$AV$12/1000 | AK25: =D25*J25*$AV$13/1000 | AL25: =D25*K25*M25/1000 | AM25: =D25*L25*N25/1000 | AO25: =D25*Q25/1000 | AP25: =AO25/$AO$36 | AQ25: =AO25/$AO$58 | AR25: =AO25/$AO$59
B26: ='1.4.1 สารทำความเย็น'!A6 | C26: ='1.4.1 สารทำความเย็น'!D6 | D26: ='1.4.1 สารทำความเย็น'!E6 | K26: 1 | M26: ='EF TGO AR5'!H56 | Q26: =(E26*$AV$8)+(F26*$AV$9)+(G26*$AV$10)+(H26*$AV$11)+(I26*$AV$12)+(J26*$AV$13)+(K26*M26)+(L26*N26) | W26: / | Z26: IPCC : GWP (AR5) | AA26: =D26*E26/1000 | AB26: =D26*F26/1000 | AC26: =D26*G26/1000 | AD26: =D26*H26/1000 | AE26: =D26*I26/1000 | AF26: =D26*J26/1000 | AG26: =D26*F26*$AV$9/1000 | AH26: =D26*G26*$AV$10/1000 | AI26: =D26*H26*$AV$11/1000 | AJ26: =D26*I26*$AV$12/1000 | AK26: =D26*J26*$AV$13/1000 | AL26: =D26*K26*M26/1000 | AM26: =D26*L26*N26/1000 | AO26: =D26*Q26/1000 | AP26: =AO26/$AO$36 | AQ26: =AO26/$AO$58 | AR26: =AO26/$AO$59
B27: ='1.4.1 สารทำความเย็น'!A7 | C27: ='1.4.1 สารทำความเย็น'!D7 | D27: ='1.4.1 สารทำความเย็น'!E7 | K27: 1 | M27: ='EF (1)'!E16 | Q27: =(E27*$AV$8)+(F27*$AV$9)+(G27*$AV$10)+(H27*$AV$11)+(I27*$AV$12)+(J27*$AV$13)+(K27*M27)+(L27*N27) | W27: / | Z27: IPCC : GWP (AR5) | AA27: =D27*E27/1000 | AB27: =D27*F27/1000 | AC27: =D27*G27/1000 | AD27: =D27*H27/1000 | AE27: =D27*I27/1000 | AF27: =D27*J27/1000 | AG27: =D27*F27*$AV$9/1000 | AH27: =D27*G27*$AV$10/1000 | AI27: =D27*H27*$AV$11/1000 | AJ27: =D27*I27*$AV$12/1000 | AK27: =D27*J27*$AV$13/1000 | AL27: =D27*K27*M27/1000 | AM27: =D27*L27*N27/1000 | AO27: =D27*Q27/1000 | AP27: =AO27/$AO$36 | AQ27: =AO27/$AO$58 | AR27: =AO27/$AO$59
B28: ='1.4.1 สารทำความเย็น'!A8 | C28: ='1.4.1 สารทำความเย็น'!D8 | D28: ='1.4.1 สารทำความเย็น'!E8 | K28: 1 | M28: ='EF TGO AR5'!H59 | Q28: =(E28*$AV$8)+(F28*$AV$9)+(G28*$AV$10)+(H28*$AV$11)+(I28*$AV$12)+(J28*$AV$13)+(K28*M28)+(L28*N28) | W28: / | Z28: IPCC : GWP (AR5) | AA28: =D28*E28/1000 | AB28: =D28*F28/1000 | AC28: =D28*G28/1000 | AD28: =D28*H28/1000 | AE28: =D28*I28/1000 | AF28: =D28*J28/1000 | AG28: =D28*F28*$AV$9/1000 | AH28: =D28*G28*$AV$10/1000 | AI28: =D28*H28*$AV$11/1000 | AJ28: =D28*I28*$AV$12/1000 | AK28: =D28*J28*$AV$13/1000 | AL28: =D28*K28*M28/1000 | AM28: =D28*L28*N28/1000 | AO28: =D28*Q28/1000 | AP28: =AO28/$AO$36 | AQ28: =AO28/$AO$58 | AR28: =AO28/$AO$59
B29: ='1.4.1 สารทำความเย็น'!A9 | C29: ='1.4.1 สารทำความเย็น'!D9 | D29: ='1.4.1 สารทำความเย็น'!E9 | K29: 1 | M29: ='EF (1)'!E19 | Q29: =(E29*$AV$8)+(F29*$AV$9)+(G29*$AV$10)+(H29*$AV$11)+(I29*$AV$12)+(J29*$AV$13)+(K29*M29)+(L29*N29) | W29: / | Z29: IPCC : GWP (AR5) | AA29: =D29*E29/1000 | AB29: =D29*F29/1000 | AC29: =D29*G29/1000 | AD29: =D29*H29/1000 | AE29: =D29*I29/1000 | AF29: =D29*J29/1000 | AG29: =D29*F29*$AV$9/1000 | AH29: =D29*G29*$AV$10/1000 | AI29: =D29*H29*$AV$11/1000 | AJ29: =D29*I29*$AV$12/1000 | AK29: =D29*J29*$AV$13/1000 | AL29: =D29*K29*M29/1000 | AM29: =D29*L29*N29/1000 | AO29: =D29*Q29/1000 | AP29: =AO29/$AO$36 | AQ29: =AO29/$AO$58 | AR29: =AO29/$AO$59
B30: ='1.4.2 สารดับเพลิง'!A4 | C30: ='1.4.2 สารดับเพลิง'!D4 | D30: ='1.4.2 สารดับเพลิง'!E4 | E30: 1 | Q30: =(E30*$AV$8)+(F30*$AV$9)+(G30*$AV$10)+(H30*$AV$11)+(I30*$AV$12)+(J30*$AV$13)+(K30*M30)+(L30*N30) | W30: / | Z30: IPCC : GWP (AR5) | AA30: =D30*E30/1000 | AB30: =D30*F30/1000 | AC30: =D30*G30/1000 | AD30: =D30*H30/1000 | AE30: =D30*I30/1000 | AF30: =D30*J30/1000 | AG30: =D30*F30*$AV$9/1000 | AH30: =D30*G30*$AV$10/1000 | AI30: =D30*H30*$AV$11/1000 | AJ30: =D30*I30*$AV$12/1000 | AK30: =D30*J30*$AV$13/1000 | AL30: =D30*K30*M30/1000 | AM30: =D30*L30*N30/1000 | AO30: =D30*Q30/1000 | AP30: =AO30/$AO$36 | AQ30: =AO30/$AO$58 | AR30: =AO30/$AO$59
B31: Septic tank | C31: kgCH4 | D31: ='1.4.3 Septic'!I16+'1.4.3 Septic'!I32+'1.4.3 Septic'!I48+'1.4.3 Septic'!I64 | G31: 1 | Q31: =(E31*$AV$8)+(F31*$AV$9)+(G31*$AV$10)+(H31*$AV$11)+(I31*$AV$12)+(J31*$AV$13)+(K31*M31)+(L31*N31) | W31: / | Z31: IPCC : GWP (AR5) | AA31: =D31*E31/1000 | AB31: =D31*F31/1000 | AC31: =D31*G31/1000 | AD31: =D31*H31/1000 | AE31: =D31*I31/1000 | AF31: =D31*J31/1000 | AG31: =D31*F31*$AV$9/1000 | AH31: =D31*G31*$AV$10/1000 | AI31: =D31*H31*$AV$11/1000 | AJ31: =D31*I31*$AV$12/1000 | AK31: =D31*J31*$AV$13/1000 | AL31: =D31*K31*M31/1000 | AM31: =D31*L31*N31/1000 | AO31: =D31*Q31/1000 | AP31: =AO31/$AO$36 | AQ31: =AO31/$AO$58 | AR31: =AO31/$AO$59
B32: ='1.4.4 ปุ๋ย'!A3 | C32: ='1.4.4 ปุ๋ย'!C3 | D32: ='1.4.4 ปุ๋ย'!D3 | H32: ='1.4.4 ปุ๋ย'!Q3 | Q32: =(E32*$AV$8)+(F32*$AV$9)+(G32*$AV$10)+(H32*$AV$11)+(I32*$AV$12)+(J32*$AV$13)+(K32*M32)+(L32*N32) | W32: / | Z32: IPCC : GWP (AR5) | AA32: =D32*E32/1000 | AB32: =D32*F32/1000 | AC32: =D32*G32/1000 | AD32: =D32*H32/1000 | AE32: =D32*I32/1000 | AF32: =D32*J32/1000 | AG32: =D32*F32*$AV$9/1000 | AH32: =D32*G32*$AV$10/1000 | AI32: =D32*H32*$AV$11/1000 | AJ32: =D32*I32*$AV$12/1000 | AK32: =D32*J32*$AV$13/1000 | AL32: =D32*K32*M32/1000 | AM32: =D32*L32*N32/1000 | AO32: =D32*Q32/1000 | AP32: =AO32/$AO$36 | AQ32: =AO32/$AO$58 | AR32: =AO32/$AO$59
Q33: =(E33*$AV$8)+(F33*$AV$9)+(G33*$AV$10)+(H33*$AV$11)+(I33*$AV$12)+(J33*$AV$13)+(K33*M33)+(L33*N33) | AA33: =D33*E33/1000 | AB33: =D33*F33/1000 | AC33: =D33*G33/1000 | AD33: =D33*H33/1000 | AE33: =D33*I33/1000 | AF33: =D33*J33/1000 | AG33: =D33*F33*$AV$9/1000 | AH33: =D33*G33*$AV$10/1000 | AI33: =D33*H33*$AV$11/1000 | AJ33: =D33*I33*$AV$12/1000 | AK33: =D33*J33*$AV$13/1000 | AL33: =D33*K33*M33/1000 | AM33: =D33*L33*N33/1000 | AO33: =D33*Q33/1000 | AP33: =AO33/$AO$36 | AQ33: =AO33/$AO$58 | AR33: =AO33/$AO$59
Q34: =(E34*$AV$8)+(F34*$AV$9)+(G34*$AV$10)+(H34*$AV$11)+(I34*$AV$12)+(J34*$AV$13)+(K34*M34)+(L34*N34) | AA34: =D34*E34/1000 | AB34: =D34*F34/1000 | AC34: =D34*G34/1000 | AD34: =D34*H34/1000 | AE34: =D34*I34/1000 | AF34: =D34*J34/1000 | AG34: =D34*F34*$AV$9/1000 | AH34: =D34*G34*$AV$10/1000 | AI34: =D34*H34*$AV$11/1000 | AJ34: =D34*I34*$AV$12/1000 | AK34: =D34*J34*$AV$13/1000 | AL34: =D34*K34*M34/1000 | AM34: =D34*L34*N34/1000 | AO34: =D34*Q34/1000 | AP34: =AO34/$AO$36 | AQ34: =AO34/$AO$58 | AR34: =AO34/$AO$59
Q35: =(E35*$AV$8)+(F35*$AV$9)+(G35*$AV$10)+(H35*$AV$11)+(I35*$AV$12)+(J35*$AV$13)+(K35*M35)+(L35*N35) | AA35: =D35*E35/1000 | AB35: =D35*F35/1000 | AC35: =D35*G35/1000 | AD35: =D35*H35/1000 | AE35: =D35*I35/1000 | AF35: =D35*J35/1000 | AG35: =D35*F35*$AV$9/1000 | AH35: =D35*G35*$AV$10/1000 | AI35: =D35*H35*$AV$11/1000 | AJ35: =D35*I35*$AV$12/1000 | AK35: =D35*J35*$AV$13/1000 | AL35: =D35*K35*M35/1000 | AM35: =D35*L35*N35/1000 | AO35: =D35*Q35/1000 | AP35: =AO35/$AO$36 | AQ35: =AO35/$AO$58 | AR35: =AO35/$AO$59
AA36: =SUM(AA10:AA35) | AB36: =SUM(AB10:AB35) | AC36: =SUM(AC10:AC35) | AD36: =SUM(AD10:AD35) | AE36: =SUM(AE10:AE35) | AF36: =SUM(AF10:AF35) | AG36: =SUM(AG10:AG35) | AH36: =SUM(AH10:AH35) | ... AP36: =SUM(AP10:AP35)
A37: รายงานแยก | B37: ='1.4.1 สารทำความเย็น'!A4 | C37: ='1.4.1 สารทำความเย็น'!D4 | D37: ='1.4.1 สารทำความเย็น'!E4 | O37: 1 | P37: ='EF TGO AR5'!H55 | Q37: =(E37*$AV$8)+(O37*P37) | W37: / | Z37: IPCC : GWP (AR5) | AA37: =D37*E37*$AV$8/1000 | AN37: =D37*O37*P37/1000 | AO37: =D37*Q37/1000 | AP37: =AO37/$AO$44
B38: ='1.4.2 สารดับเพลิง'!A5 | C38: ='1.4.2 สารดับเพลิง'!D5 | D38: ='1.4.2 สารดับเพลิง'!E5 | O38: 1 | P38: ='EF (1)'!E13 | Q38: =(E38*$AV$8)+(O38*P38) | W38: / | Z38: IPCC : GWP (AR5) | AA38: =D38*E38*$AV$8/1000 | AN38: =D38*O38*P38/1000 | AO38: =D38*Q38/1000 | AP38: =AO38/$AO$44
B39: CO2 -Biodiesel (Stationary combustion) | C39: kg | D39: =D14 | E39: ='EF (1)'!F28*'EF (1)'!C28 | Q39: =(E39*$AV$8)+(O39*P39) | W39: / | Z39: IPCC, 2006 | AA39: =D39*E39*$AV$8/1000 | AN39: =D39*O39*P39/1000 | AO39: =D39*Q39/1000 | AP39: =AO39/$AO$44
B40: CO2-Biogasoline (Ethanol) (Stationary combustion) | C40: kg | D40: =D15 | E40: ='EF (1)'!F29*'EF (1)'!C29 | Q40: =(E40*$AV$8)+(O40*P40) | W40: / | Z40: IPCC, 2006 | AA40: =D40*E40*$AV$8/1000 | AN40: =D40*O40*P40/1000 | AO40: =D40*Q40/1000 | AP40: =AO40/$AO$44
B41: CO2-Biodiesel (Mobile combustion-on road) | C41: kg | D41: =D22 | E41: ='EF (1)'!$C$34 | Q41: =(E41*$AV$8)+(O41*P41) | W41: / | Z41: IPCC, 2006 | AA41: =D41*E41*$AV$8/1000 | AN41: =D41*O41*P41/1000 | AO41: =D41*Q41/1000 | AP41: =AO41/$AO$44
B42: CO2-Biodiesel (Mobile combustion-off road) | C42: kg | D42: =D23 | E42: ='EF (1)'!$C$36 | Q42: =(E42*$AV$8)+(O41*P42) | W42: / | Z42: IPCC, 2006 | AA42: =D42*E42*$AV$8/1000 | AN42: =D42*O42*P42/1000 | AO42: =D42*Q42/1000 | AP42: =AO42/$AO$44
...

Sheet Fr-04.2
B1: บัญชีรายการก๊าซเรือนกระจก ปีฐาน (base year) | AO1: TCFO_R_01 Version 04 : 21/2/2020
B3: ชื่อฟอร์ม | C3: บัญชีรายการก๊าซเรือนกระจก | H3: องค์กร | I3: ='Fr-01'!$B$6 | AB3: ปีฐาน | AE3: ='Fr-01'!H38 | AO3: หน้าที่ | AR3: 5
B4: รหัสฟอร์ม | C4: Fr-04.2 | H4: ผู้จัดทำ | I4: ='Fr-01'!$G$4 | AO4: วันที่ | AR4: ='Fr-04.1'!AR4
A6: ขอบเขต | B6: รายการ | C6: ค่า LCI | E6: GHG ที่ต้องรายงานตามข้อกำหนด | O6: GHG ที่อยู่นอกข้อกำหนด | Q6: Total (kgCO2e/หน่วย) | R6: ที่มา | Y6: Subsitute | Z6: แหล่งอ้างอิง | AA6: ผลคูณ (Ton GHG) | AG6: ผลคูณ (TonCO2e) | AO6: Total GHG | AP6: สัดส่วน (%) | AQ6: สัดส่วน (%) (SCOPE 1+2) | AR6: สัดส่วน (%) (SCOPE 1+2+3) | AS6: ระบุความแตกต่างระหว่างการรายงานปริมาณก๊าซเรือนกระจกของปีฐานและปีปัจจุบัน | AU6: GWP100
R7: 1st | T7: 2nd | X7: Other | AU7: ที่มา | AV7: IPCC, AR5
E8: ค่า EF (kg GHG/หน่วย) | M8: GWP100 | O8: ค่า EF (kg GHG/หน่วย) | P8: GWP100 | R8: Self collct | S8: Supplier | T8: TH LCI DB | U8: TGO EF | V8: Thai Res. | W8: Int. DB | AO8: (TonCO2e) | AU8: CO2 | AV8: 1
C9: หน่วย | D9: ปริมาณ | E9: CO2 | F9: Fossil CH4 | G9: CH4 | H9: N2O | I9: SF6 | J9: NF3 | K9: HFCs | L9: PFCs | M9: HFCs | N9: PFCs | AA9: CO2 | AB9: Fossil CH4 | AC9: CH4 | AD9: N2O | AE9: SF6 | AF9: NF3 | AG9: Fossil CH4 | AH9: CH4 | AI9: N2O | AJ9: SF6 | AK9: NF3 | AL9: HFCs | AM9: PFCs | AN9: Other | AU9: Fossil CH4 | AV9: 30
A10: ขอบเขต 1 | B10: ='Fr-04.1'!B10 | Q10: =(E10*$AV$8)+(F10*$AV$9)+(G10*$AV$10)+(H10*$AV$11)+(I10*$AV$12)+(J10*$AV$13)+(K10*M10)+(L10*N10) | AA10: =D10*E10/1000 | AB10: =D10*F10/1000 | AC10: =D10*G10/1000 | AD10: =D10*H10/1000 | AE10: =D10*I10/1000 | AF10: =D10*J10/1000 | AG10: =D10*F10*$AV$9/1000 | AH10: =D10*G10*$AV$10/1000 | AI10: =D10*H10*$AV$11/1000 | AJ10: =D10*I10*$AV$12/1000 | AK10: =D10*J10*$AV$13/1000 | AL10: =D10*K10*M10/1000 | AM10: =D10*L10*N10/1000 | AO10: =D10*Q10/1000 | AP10: =AO10/$AO$35 | AQ10: =AO10/$AO$57 | AR10: =AO10/$AO$58 | AU10: CH4 | AV10: 28
B11: ='Fr-04.1'!B11 | C11: ='Fr-04.1'!C11 | D11: ='Fr-04.1'!D11 | E11: ='EF TGO AR5'!D11 | F11: ='EF TGO AR5'!E11 | G11: ='EF TGO AR5'!F11 | H11: ='EF TGO AR5'!G11 | Q11: =(E11*$AV$8)+(F11*$AV$9)+(G11*$AV$10)+(H11*$AV$11)+(I11*$AV$12)+(J11*$AV$13)+(K11*M11)+(L11*N11) | U11: / | Z11: ='Fr-04.1'!Z11 | AA11: =D11*E11/1000 | AB11: =D11*F11/1000 | AC11: =D11*G11/1000 | AD11: =D11*H11/1000 | AE11: =D11*I11/1000 | AF11: =D11*J11/1000 | AG11: =D11*F11*$AV$9/1000 | AH11: =D11*G11*$AV$10/1000 | AI11: =D11*H11*$AV$11/1000 | AJ11: =D11*I11*$AV$12/1000 | AK11: =D11*J11*$AV$13/1000 | AL11: =D11*K11*M11/1000 | AM11: =D11*L11*N11/1000 | AO11: =D11*Q11/1000 | AP11: =AO11/$AO$35 | AQ11: =AO11/$AO$57 | AR11: =AO11/$AO$58 | AU11: N2O | AV11: 265
B12: ='Fr-04.1'!B12 | C12: ='Fr-04.1'!C12 | D12: ='Fr-04.1'!D12 | E12: ='EF TGO AR5'!D17 | F12: ='EF TGO AR5'!E17 | G12: ='EF TGO AR5'!F17 | H12: ='EF TGO AR5'!G17 | Q12: =(E12*$AV$8)+(F12*$AV$9)+(G12*$AV$10)+(H12*$AV$11)+(I12*$AV$12)+(J12*$AV$13)+(K12*M12)+(L12*N12) | U12: / | Z12: ='Fr-04.1'!Z12 | AA12: =D12*E12/1000 | AB12: =D12*F12/1000 | AC12: =D12*G12/1000 | AD12: =D12*H12/1000 | AE12: =D12*I12/1000 | AF12: =D12*J12/1000 | AG12: =D12*F12*$AV$9/1000 | AH12: =D12*G12*$AV$10/1000 | AI12: =D12*H12*$AV$11/1000 | AJ12: =D12*I12*$AV$12/1000 | AK12: =D12*J12*$AV$13/1000 | AL12: =D12*K12*M12/1000 | AM12: =D12*L12*N12/1000 | AO12: =D12*Q12/1000 | AP12: =AO12/$AO$35 | AQ12: =AO12/$AO$57 | AR12: =AO12/$AO$58 | AU12: SF6 | AV12: 23500
B13: ='Fr-04.1'!B13 | C13: ='Fr-04.1'!C13 | D13: ='Fr-04.1'!D13 | E13: ='EF (1)'!B9 | Q13: =(E13*$AV$8)+(F13*$AV$9)+(G13*$AV$10)+(H13*$AV$11)+(I13*$AV$12)+(J13*$AV$13)+(K13*M13)+(L13*N13) | X13: / | Z13: ='Fr-04.1'!Z13 | AA13: =D13*E13/1000 | AB13: =D13*F13/1000 | AC13: =D13*G13/1000 | AD13: =D13*H13/1000 | AE13: =D13*I13/1000 | AF13: =D13*J13/1000 | AG13: =D13*F13*$AV$9/1000 | AH13: =D13*G13*$AV$10/1000 | AI13: =D13*H13*$AV$11/1000 | AJ13: =D13*I13*$AV$12/1000 | AK13: =D13*J13*$AV$13/1000 | AL13: =D13*K13*M13/1000 | AM13: =D13*L13*N13/1000 | AO13: =D13*Q13/1000 | AP13: =AO13/$AO$35 | AQ13: =AO13/$AO$57 | AR13: =AO13/$AO$58 | AU13: NF3 | AV13: 16100
B14: ='Fr-04.1'!B14 | C14: ='Fr-04.1'!C14 | D14: ='Fr-04.1'!D14 | G14: ='EF (1)'!F28*'EF (1)'!D28 | H14: ='EF (1)'!F28*'EF (1)'!E28 | Q14: =(E14*$AV$8)+(F14*$AV$9)+(G14*$AV$10)+(H14*$AV$11)+(I14*$AV$12)+(J14*$AV$13)+(K14*M14)+(L14*N14) | W14: / | Z14: ='Fr-04.1'!Z14 | AA14: =D14*E14/1000 | AB14: =D14*F14/1000 | AC14: =D14*G14/1000 | AD14: =D14*H14/1000 | AE14: =D14*I14/1000 | AF14: =D14*J14/1000 | AG14: =D14*F14*$AV$9/1000 | AH14: =D14*G14*$AV$10/1000 | AI14: =D14*H14*$AV$11/1000 | AJ14: =D14*I14*$AV$12/1000 | AK14: =D14*J14*$AV$13/1000 | AL14: =D14*K14*M14/1000 | AM14: =D14*L14*N14/1000 | AO14: =D14*Q14/1000 | AP14: =AO14/$AO$35 | AQ14: =AO14/$AO$57 | AR14: =AO14/$AO$58
B15: ='Fr-04.1'!B15 | C15: ='Fr-04.1'!C15 | D15: ='Fr-04.1'!D15 | G15: ='EF (1)'!F29*'EF (1)'!D29 | H15: ='EF (1)'!F29*'EF (1)'!E29 | Q15: =(E15*$AV$8)+(F15*$AV$9)+(G15*$AV$10)+(H15*$AV$11)+(I15*$AV$12)+(J15*$AV$13)+(K15*M15)+(L15*N15) | W15: / | Z15: ='Fr-04.1'!Z15 | AA15: =D15*E15/1000 | AB15: =D15*F15/1000 | AC15: =D15*G15/1000 | AD15: =D15*H15/1000 | AE15: =D15*I15/1000 | AF15: =D15*J15/1000 | AG15: =D15*F15*$AV$9/1000 | AH15: =D15*G15*$AV$10/1000 | AI15: =D15*H15*$AV$11/1000 | AJ15: =D15*I15*$AV$12/1000 | AK15: =D15*J15*$AV$13/1000 | AL15: =D15*K15*M15/1000 | AM15: =D15*L15*N15/1000 | AO15: =D15*Q15/1000 | AP15: =AO15/$AO$35 | AQ15: =AO15/$AO$57 | AR15: =AO15/$AO$58
B16: ='Fr-04.1'!B16 | Q16: =(E16*$AV$8)+(F16*$AV$9)+(G16*$AV$10)+(H16*$AV$11)+(I16*$AV$12)+(J16*$AV$13)+(K16*M16)+(L16*N16) | Z16: ='Fr-04.1'!Z16 | AA16: =D16*E16/1000 | AB16: =D16*F16/1000 | AC16: =D16*G16/1000 | AD16: =D16*H16/1000 | AE16: =D16*I16/1000 | AF16: =D16*J16/1000 | AG16: =D16*F16*$AV$9/1000 | AH16: =D16*G16*$AV$10/1000 | AI16: =D16*H16*$AV$11/1000 | AJ16: =D16*I16*$AV$12/1000 | AK16: =D16*J16*$AV$13/1000 | AL16: =D16*K16*M16/1000 | AM16: =D16*L16*N16/1000 | AO16: =D16*Q16/1000 | AP16: =AO16/$AO$35 | AQ16: =AO16/$AO$57 | AR16: =AO16/$AO$58
B17: ='Fr-04.1'!B17 | C17: ='Fr-04.1'!C17 | D17: ='Fr-04.1'!D17 | E17: ='EF TGO AR5'!D32 | F17: ='EF TGO AR5'!E32 | G17: ='EF TGO AR5'!F32 | H17: ='EF TGO AR5'!G32 | Q17: =(E17*$AV$8)+(F17*$AV$9)+(G17*$AV$10)+(H17*$AV$11)+(I17*$AV$12)+(J17*$AV$13)+(K17*M17)+(L17*N17) | U17: / | Z17: ='Fr-04.1'!Z17 | AA17: =D17*E17/1000 | AB17: =D17*F17/1000 | AC17: =D17*G17/1000 | AD17: =D17*H17/1000 | AE17: =D17*I17/1000 | AF17: =D17*J17/1000 | AG17: =D17*F17*$AV$9/1000 | AH17: =D17*G17*$AV$10/1000 | AI17: =D17*H17*$AV$11/1000 | AJ17: =D17*I17*$AV$12/1000 | AK17: =D17*J17*$AV$13/1000 | AL17: =D17*K17*M17/1000 | AM17: =D17*L17*N17/1000 | AO17: =D17*Q17/1000 | AP17: =AO17/$AO$35 | AQ17: =AO17/$AO$57 | AR17: =AO17/$AO$58
B18: ='Fr-04.1'!B18 | C18: ='Fr-04.1'!C18 | D18: ='Fr-04.1'!D18 | E18: ='EF TGO AR5'!D32 | F18: ='EF TGO AR5'!E32 | G18: ='EF TGO AR5'!F32 | H18: ='EF TGO AR5'!G32 | Q18: =(E18*$AV$8)+(F18*$AV$9)+(G18*$AV$10)+(H18*$AV$11)+(I18*$AV$12)+(J18*$AV$13)+(K18*M18)+(L18*N18) | U18: / | Z18: ='Fr-04.1'!Z18 | AA18: =D18*E18/1000 | AB18: =D18*F18/1000 | AC18: =D18*G18/1000 | AD18: =D18*H18/1000 | AE18: =D18*I18/1000 | AF18: =D18*J18/1000 | AG18: =D18*F18*$AV$9/1000 | AH18: =D18*G18*$AV$10/1000 | AI18: =D18*H18*$AV$11/1000 | AJ18: =D18*I18*$AV$12/1000 | AK18: =D18*J18*$AV$13/1000 | AL18: =D18*K18*M18/1000 | AM18: =D18*L18*N18/1000 | AO18: =D18*Q18/1000 | AP18: =AO18/$AO$35 | AQ18: =AO18/$AO$57 | AR18: =AO18/$AO$58
B19: ='Fr-04.1'!B19 | C19: ='Fr-04.1'!C19 | D19: ='Fr-04.1'!D19 | E19: ='EF TGO AR5'!D30 | F19: ='EF TGO AR5'!E30 | G19: ='EF TGO AR5'!F30 | H19: ='EF TGO AR5'!G30 | Q19: =(E19*$AV$8)+(F19*$AV$9)+(G19*$AV$10)+(H19*$AV$11)+(I19*$AV$12)+(J19*$AV$13)+(K19*M19)+(L19*N19) | U19: / | Z19: ='Fr-04.1'!Z19 | AA19: =D19*E19/1000 | AB19: =D19*F19/1000 | AC19: =D19*G19/1000 | AD19: =D19*H19/1000 | AE19: =D19*I19/1000 | AF19: =D19*J19/1000 | AG19: =D19*F19*$AV$9/1000 | AH19: =D19*G19*$AV$10/1000 | AI19: =D19*H19*$AV$11/1000 | AJ19: =D19*I19*$AV$12/1000 | AK19: =D19*J19*$AV$13/1000 | AL19: =D19*K19*M19/1000 | AM19: =D19*L19*N19/1000 | AO19: =D19*Q19/1000 | AP19: =AO19/$AO$35 | AQ19: =AO19/$AO$57 | AR19: =AO19/$AO$58
B20: ='Fr-04.1'!B20 | C20: ='Fr-04.1'!C20 | D20: ='Fr-04.1'!D20 | E20: ='EF TGO AR5'!D30 | F20: ='EF TGO AR5'!E30 | G20: ='EF TGO AR5'!F30 | H20: ='EF TGO AR5'!G30 | Q20: =(E20*$AV$8)+(F20*$AV$9)+(G20*$AV$10)+(H20*$AV$11)+(I20*$AV$12)+(J20*$AV$13)+(K20*M20)+(L20*N20) | W20: / | Z20: ='Fr-04.1'!Z20 | AA20: =D20*E20/1000 | AB20: =D20*F20/1000 | AC20: =D20*G20/1000 | AD20: =D20*H20/1000 | AE20: =D20*I20/1000 | AF20: =D20*J20/1000 | AG20: =D20*F20*$AV$9/1000 | AH20: =D20*G20*$AV$10/1000 | AI20: =D20*H20*$AV$11/1000 | AJ20: =D20*I20*$AV$12/1000 | AK20: =D20*J20*$AV$13/1000 | AL20: =D20*K20*M20/1000 | AM20: =D20*L20*N20/1000 | AO20: =D20*Q20/1000 | AP20: =AO20/$AO$35 | AQ20: =AO20/$AO$57 | AR20: =AO20/$AO$58
B21: ='Fr-04.1'!B21 | C21: ='Fr-04.1'!C21 | D21: ='Fr-04.1'!D21 | E21: ='EF TGO AR5'!D40 | F21: ='EF TGO AR5'!E40 | G21: ='EF TGO AR5'!F40 | H21: ='EF TGO AR5'!G40 | Q21: =(E21*$AV$8)+(F21*$AV$9)+(G21*$AV$10)+(H21*$AV$11)+(I21*$AV$12)+(J21*$AV$13)+(K21*M21)+(L21*N21) | W21: / | Z21: ='Fr-04.1'!Z21 | AA21: =D21*E21/1000 | AB21: =D21*F21/1000 | AC21: =D21*G21/1000 | AD21: =D21*H21/1000 | AE21: =D21*I21/1000 | AF21: =D21*J21/1000 | AG21: =D21*F21*$AV$9/1000 | AH21: =D21*G21*$AV$10/1000 | AI21: =D21*H21*$AV$11/1000 | AJ21: =D21*I21*$AV$12/1000 | AK21: =D21*J21*$AV$13/1000 | AL21: =D21*K21*M21/1000 | AM21: =D21*L21*N21/1000 | AO21: =D21*Q21/1000 | AP21: =AO21/$AO$35 | AQ21: =AO21/$AO$57 | AR21: =AO21/$AO$58
B22: ='Fr-04.1'!B22 | C22: ='Fr-04.1'!C22 | D22: ='Fr-04.1'!D22 | G22: ='EF (1)'!F30*'EF (1)'!D30 | H22: ='EF (1)'!F30*'EF (1)'!E30 | Q22: =(E22*$AV$8)+(F22*$AV$9)+(G22*$AV$10)+(H22*$AV$11)+(I22*$AV$12)+(J22*$AV$13)+(K22*M22)+(L22*N22) | W22: / | Z22: ='Fr-04.1'!Z22 | AA22: =D22*E22/1000 | AB22: =D22*F22/1000 | AC22: =D22*G22/1000 | AD22: =D22*H22/1000 | AE22: =D22*I22/1000 | AF22: =D22*J22/1000 | AG22: =D22*F22*$AV$9/1000 | AH22: =D22*G22*$AV$10/1000 | AI22: =D22*H22*$AV$11/1000 | AJ22: =D22*I22*$AV$12/1000 | AK22: =D22*J22*$AV$13/1000 | AL22: =D22*K22*M22/1000 | AM22: =D22*L22*N22/1000 | AO22: =D22*Q22/1000 | AP22: =AO22/$AO$35 | AQ22: =AO22/$AO$57 | AR22: =AO22/$AO$58
B23: ='Fr-04.1'!B23 | C23: ='Fr-04.1'!C23 | D23: ='Fr-04.1'!D23 | G23: ='EF (1)'!F32*'EF (1)'!D32 | H23: ='EF (1)'!F32*'EF (1)'!E32 | Q23: =(E23*$AV$8)+(F23*$AV$9)+(G23*$AV$10)+(H23*$AV$11)+(I23*$AV$12)+(J23*$AV$13)+(K23*M23)+(L23*N23) | W23: / | Z23: ='Fr-04.1'!Z23 | AA23: =D23*E23/1000 | AB23: =D23*F23/1000 | AC23: =D23*G23/1000 | AD23: =D23*H23/1000 | AE23: =D23*I23/1000 | AF23: =D23*J23/1000 | AG23: =D23*F23*$AV$9/1000 | AH23: =D23*G23*$AV$10/1000 | AI23: =D23*H23*$AV$11/1000 | AJ23: =D23*I23*$AV$12/1000 | AK23: =D23*J23*$AV$13/1000 | AL23: =D23*K23*M23/1000 | AM23: =D23*L23*N23/1000 | AO23: =D23*Q23/1000 | AP23: =AO23/$AO$35 | AQ23: =AO23/$AO$57 | AR23: =AO23/$AO$58
B24: ='Fr-04.1'!B24 | C24: ='Fr-04.1'!C24 | D24: ='Fr-04.1'!D24 | G24: ='EF (1)'!F31*'EF (1)'!D31 | H24: ='EF (1)'!F31*'EF (1)'!E31 | Q24: =(E24*$AV$8)+(F24*$AV$9)+(G24*$AV$10)+(H24*$AV$11)+(I24*$AV$12)+(J24*$AV$13)+(K24*M24)+(L24*N24) | W24: / | Z24: ='Fr-04.1'!Z24 | AA24: =D24*E24/1000 | AB24: =D24*F24/1000 | AC24: =D24*G24/1000 | AD24: =D24*H24/1000 | AE24: =D24*I24/1000 | AF24: =D24*J24/1000 | AG24: =D24*F24*$AV$9/1000 | AH24: =D24*G24*$AV$10/1000 | AI24: =D24*H24*$AV$11/1000 | AJ24: =D24*I24*$AV$12/1000 | AK24: =D24*J24*$AV$13/1000 | AL24: =D24*K24*M24/1000 | AM24: =D24*L24*N24/1000 | AO24: =D24*Q24/1000 | AP24: =AO24/$AO$35 | AQ24: =AO24/$AO$57 | AR24: =AO24/$AO$58
B25: ='Fr-04.1'!B25 | Q25: =(E25*$AV$8)+(F25*$AV$9)+(G25*$AV$10)+(H25*$AV$11)+(I25*$AV$12)+(J25*$AV$13)+(K25*M25)+(L25*N25) | Z25: ='Fr-04.1'!Z25 | AA25: =D25*E25/1000 | AB25: =D25*F25/1000 | AC25: =D25*G25/1000 | AD25: =D25*H25/1000 | AE25: =D25*I25/1000 | AF25: =D25*J25/1000 | AG25: =D25*F25*$AV$9/1000 | AH25: =D25*G25*$AV$10/1000 | AI25: =D25*H25*$AV$11/1000 | AJ25: =D25*I25*$AV$12/1000 | AK25: =D25*J25*$AV$13/1000 | AL25: =D25*K25*M25/1000 | AM25: =D25*L25*N25/1000 | AO25: =D25*Q25/1000 | AP25: =AO25/$AO$35 | AQ25: =AO25/$AO$57 | AR25: =AO25/$AO$58
B26: ='Fr-04.1'!B26 | C26: ='Fr-04.1'!C26 | D26: ='Fr-04.1'!D26 | K26: 1 | M26: ='EF TGO AR5'!H56 | Q26: =(E26*$AV$8)+(F26*$AV$9)+(G26*$AV$10)+(H26*$AV$11)+(I26*$AV$12)+(J26*$AV$13)+(K26*M26)+(L26*N26) | W26: / | Z26: ='Fr-04.1'!Z26 | AA26: =D26*E26/1000 | AB26: =D26*F26/1000 | AC26: =D26*G26/1000 | AD26: =D26*H26/1000 | AE26: =D26*I26/1000 | AF26: =D26*J26/1000 | AG26: =D26*F26*$AV$9/1000 | AH26: =D26*G26*$AV$10/1000 | AI26: =D26*H26*$AV$11/1000 | AJ26: =D26*I26*$AV$12/1000 | AK26: =D26*J26*$AV$13/1000 | AL26: =D26*K26*M26/1000 | AM26: =D26*L26*N26/1000 | AO26: =D26*Q26/1000 | AP26: =AO26/$AO$35 | AQ26: =AO26/$AO$57 | AR26: =AO26/$AO$58
B27: ='Fr-04.1'!B27 | C27: ='Fr-04.1'!C27 | D27: ='Fr-04.1'!D27 | K27: 1 | M27: ='EF (1)'!E16 | Q27: =(E27*$AV$8)+(F27*$AV$9)+(G27*$AV$10)+(H27*$AV$11)+(I27*$AV$12)+(J27*$AV$13)+(K27*M27)+(L27*N27) | W27: / | Z27: ='Fr-04.1'!Z27 | AA27: =D27*E27/1000 | AB27: =D27*F27/1000 | AC27: =D27*G27/1000 | AD27: =D27*H27/1000 | AE27: =D27*I27/1000 | AF27: =D27*J27/1000 | AG27: =D27*F27*$AV$9/1000 | AH27: =D27*G27*$AV$10/1000 | AI27: =D27*H27*$AV$11/1000 | AJ27: =D27*I27*$AV$12/1000 | AK27: =D27*J27*$AV$13/1000 | AL27: =D27*K27*M27/1000 | AM27: =D27*L27*N27/1000 | AO27: =D27*Q27/1000 | AP27: =AO27/$AO$35 | AQ27: =AO27/$AO$57 | AR27: =AO27/$AO$58
B28: ='Fr-04.1'!B28 | C28: ='Fr-04.1'!C28 | D28: ='Fr-04.1'!D28 | K28: 1 | M28: ='EF TGO AR5'!H59 | Q28: =(E28*$AV$8)+(F28*$AV$9)+(G28*$AV$10)+(H28*$AV$11)+(I28*$AV$12)+(J28*$AV$13)+(K28*M28)+(L28*N28) | W28: / | Z28: ='Fr-04.1'!Z28 | AA28: =D28*E28/1000 | AB28: =D28*F28/1000 | AC28: =D28*G28/1000 | AD28: =D28*H28/1000 | AE28: =D28*I28/1000 | AF28: =D28*J28/1000 | AG28: =D28*F28*$AV$9/1000 | AH28: =D28*G28*$AV$10/1000 | AI28: =D28*H28*$AV$11/1000 | AJ28: =D28*I28*$AV$12/1000 | AK28: =D28*J28*$AV$13/1000 | AL28: =D28*K28*M28/1000 | AM28: =D28*L28*N28/1000 | AO28: =D28*Q28/1000 | AP28: =AO28/$AO$35 | AQ28: =AO28/$AO$57 | AR28: =AO28/$AO$58
B29: ='Fr-04.1'!B29 | C29: ='Fr-04.1'!C29 | D29: ='Fr-04.1'!D29 | K29: 1 | M29: ='EF (1)'!E19 | Q29: =(E29*$AV$8)+(F29*$AV$9)+(G29*$AV$10)+(H29*$AV$11)+(I29*$AV$12)+(J29*$AV$13)+(K29*M29)+(L29*N29) | W29: / | Z29: ='Fr-04.1'!Z29 | AA29: =D29*E29/1000 | AB29: =D29*F29/1000 | AC29: =D29*G29/1000 | AD29: =D29*H29/1000 | AE29: =D29*I29/1000 | AF29: =D29*J29/1000 | AG29: =D29*F29*$AV$9/1000 | AH29: =D29*G29*$AV$10/1000 | AI29: =D29*H29*$AV$11/1000 | AJ29: =D29*I29*$AV$12/1000 | AK29: =D29*J29*$AV$13/1000 | AL29: =D29*K29*M29/1000 | AM29: =D29*L29*N29/1000 | AO29: =D29*Q29/1000 | AP29: =AO29/$AO$35 | AQ29: =AO29/$AO$57 | AR29: =AO29/$AO$58
B30: ='Fr-04.1'!B30 | C30: ='Fr-04.1'!C30 | D30: ='Fr-04.1'!D30 | E30: 1 | Q30: =(E30*$AV$8)+(F30*$AV$9)+(G30*$AV$10)+(H30*$AV$11)+(I30*$AV$12)+(J30*$AV$13)+(K30*M30)+(L30*N30) | W30: / | Z30: ='Fr-04.1'!Z30 | AA30: =D30*E30/1000 | AB30: =D30*F30/1000 | AC30: =D30*G30/1000 | AD30: =D30*H30/1000 | AE30: =D30*I30/1000 | AF30: =D30*J30/1000 | AG30: =D30*F30*$AV$9/1000 | AH30: =D30*G30*$AV$10/1000 | AI30: =D30*H30*$AV$11/1000 | AJ30: =D30*I30*$AV$12/1000 | AK30: =D30*J30*$AV$13/1000 | AL30: =D30*K30*M30/1000 | AM30: =D30*L30*N30/1000 | AO30: =D30*Q30/1000 | AP30: =AO30/$AO$35 | AQ30: =AO30/$AO$57 | AR30: =AO30/$AO$58
B31: ='Fr-04.1'!B31 | C31: ='Fr-04.1'!C31 | D31: ='Fr-04.1'!D31 | G31: 1 | Q31: =(E31*$AV$8)+(F31*$AV$9)+(G31*$AV$10)+(H31*$AV$11)+(I31*$AV$12)+(J31*$AV$13)+(K31*M31)+(L31*N31) | W31: / | Z31: ='Fr-04.1'!Z31 | AA31: =D31*E31/1000 | AB31: =D31*F31/1000 | AC31: =D31*G31/1000 | AD31: =D31*H31/1000 | AE31: =D31*I31/1000 | AF31: =D31*J31/1000 | AG31: =D31*F31*$AV$9/1000 | AH31: =D31*G31*$AV$10/1000 | AI31: =D31*H31*$AV$11/1000 | AJ31: =D31*I31*$AV$12/1000 | AK31: =D31*J31*$AV$13/1000 | AL31: =D31*K31*M31/1000 | AM31: =D31*L31*N31/1000 | AO31: =D31*Q31/1000 | AP31: =AO31/$AO$35 | AQ31: =AO31/$AO$57 | AR31: =AO31/$AO$58
B32: ='Fr-04.1'!B32 | C32: ='Fr-04.1'!C32 | D32: ='Fr-04.1'!D32 | H32: ='1.4.4 ปุ๋ย'!Q3 | Q32: =(E32*$AV$8)+(F32*$AV$9)+(G32*$AV$10)+(H32*$AV$11)+(I32*$AV$12)+(J32*$AV$13)+(K32*M32)+(L32*N32) | W32: / | Z32: ='Fr-04.1'!Z32 | AA32: =D32*E32/1000 | AB32: =D32*F32/1000 | AC32: =D32*G32/1000 | AD32: =D32*H32/1000 | AE32: =D32*I32/1000 | AF32: =D32*J32/1000 | AG32: =D32*F32*$AV$9/1000 | AH32: =D32*G32*$AV$10/1000 | AI32: =D32*H32*$AV$11/1000 | AJ32: =D32*I32*$AV$12/1000 | AK32: =D32*J32*$AV$13/1000 | AL32: =D32*K32*M32/1000 | AM32: =D32*L32*N32/1000 | AO32: =D32*Q32/1000 | AP32: =AO32/$AO$35 | AQ32: =AO32/$AO$57 | AR32: =AO32/$AO$58
Q33: =(E33*$AV$8)+(F33*$AV$9)+(G33*$AV$10)+(H33*$AV$11)+(I33*$AV$12)+(J33*$AV$13)+(K33*M33)+(L33*N33) | AA33: =D33*E33/1000 | AB33: =D33*F33/1000 | AC33: =D33*G33/1000 | AD33: =D33*H33/1000 | AE33: =D33*I33/1000 | AF33: =D33*J33/1000 | AG33: =D33*F33*$AV$9/1000 | AH33: =D33*G33*$AV$10/1000 | AI33: =D33*H33*$AV$11/1000 | AJ33: =D33*I33*$AV$12/1000 | AK33: =D33*J33*$AV$13/1000 | AL33: =D33*K33*M33/1000 | AM33: =D33*L33*N33/1000 | AO33: =D33*Q33/1000 | AP33: =AO33/$AO$35 | AQ33: =AO33/$AO$57 | AR33: =AO33/$AO$58
Q34: =(E34*$AV$8)+(F34*$AV$9)+(G34*$AV$10)+(H34*$AV$11)+(I34*$AV$12)+(J34*$AV$13)+(K34*M34)+(L34*N34) | AA34: =D34*E34/1000 | AB34: =D34*F34/1000 | AC34: =D34*G34/1000 | AD34: =D34*H34/1000 | AE34: =D34*I34/1000 | AF34: =D34*J34/1000 | AG34: =D34*F34*$AV$9/1000 | AH34: =D34*G34*$AV$10/1000 | AI34: =D34*H34*$AV$11/1000 | AJ34: =D34*I34*$AV$12/1000 | AK34: =D34*J34*$AV$13/1000 | AL34: =D34*K34*M34/1000 | AM34: =D34*L34*N34/1000 | AO34: =D34*Q34/1000 | AP34: =AO34/$AO$35 | AQ34: =AO34/$AO$57 | AR34: =AO34/$AO$58
AA35: =SUM(AA10:AA34) | AB35: =SUM(AB10:AB34) | AC35: =SUM(AC10:AC34) | AD35: =SUM(AD10:AD34) | AE35: =SUM(AE10:AE34) | AF35: =SUM(AF10:AF34) | AG35: =SUM(AG10:AG34) | AH35: =SUM(AH10:AH34) | ... AP35: =SUM(AP10:AP34)
A36: การปล่อย GHG โดยตรงที่ทำการรายงานแยก | B36: ='Fr-04.1'!B37 | C36: ='Fr-04.1'!C37 | D36: ='Fr-04.1'!D37 | O36: 1 | P36: ='EF TGO AR5'!H55 | Q36: =(E36*$AV$8)+(O36*P36) | W36: / | Z36: ='Fr-04.1'!Z37 | AA36: =D36*E36*$AV$8/1000 | AN36: =D36*O36*P36/1000 | AO36: =D36*Q36/1000 | AP36: =AO36/$AO$43
B37: ='Fr-04.1'!B38 | C37: ='Fr-04.1'!C38 | D37: ='Fr-04.1'!D38 | O37: 1 | P37: ='EF (1)'!E13 | Q37: =(E37*$AV$8)+(O37*P37) | W37: / | Z37: ='Fr-04.1'!Z38 | AA37: =D37*E37*$AV$8/1000 | AN37: =D37*O37*P37/1000 | AO37: =D37*Q37/1000 | AP37: =AO37/$AO$43
B38: ='Fr-04.1'!B39 | C38: ='Fr-04.1'!C39 | D38: ='Fr-04.1'!D39 | E38: ='EF (1)'!F28*'EF (1)'!C28 | Q38: =(E38*$AV$8)+(O38*P38) | W38: / | Z38: ='Fr-04.1'!Z39 | AA38: =D38*E38*$AV$8/1000 | AN38: =D38*O38*P38/1000 | AO38: =D38*Q38/1000 | AP38: =AO38/$AO$43
B39: ='Fr-04.1'!B40 | C39: ='Fr-04.1'!C40 | D39: ='Fr-04.1'!D40 | E39: ='EF (1)'!F29*'EF (1)'!C29 | Q39: =(E39*$AV$8)+(O39*P39) | W39: / | Z39: ='Fr-04.1'!Z40 | AA39: =D39*E39*$AV$8/1000 | AN39: =D39*O39*P39/1000 | AO39: =D39*Q39/1000 | AP39: =AO39/$AO$43
B40: ='Fr-04.1'!B41 | C40: ='Fr-04.1'!C41 | D40: ='Fr-04.1'!D41 | E40: ='EF (1)'!C34 | Q40: =(E40*$AV$8)+(O40*P40) | W40: / | Z40: ='Fr-04.1'!Z41 | AA40: =D40*E40*$AV$8/1000 | AN40: =D40*O40*P40/1000 | AO40: =D40*Q40/1000 | AP40: =AO40/$AO$43
B41: ='Fr-04.1'!B42 | C41: ='Fr-04.1'!C42 | D41: ='Fr-04.1'!D42 | E41: ='EF (1)'!C36 | Q41: =(E41*$AV$8)+(O41*P41) | W41: / | Z41: ='Fr-04.1'!Z42 | AA41: =D41*E41*$AV$8/1000 | AN41: =D41*O41*P41/1000 | AO41: =D41*Q41/1000 | AP41: =AO41/$AO$43
B42: ='Fr-04.1'!B43 | C42: ='Fr-04.1'!C43 | D42: ='Fr-04.1'!D43 | E42: ='EF (1)'!C35 | Q42: =(E42*$AV$8)+(O42*P42) | W42: / | Z42: ='Fr-04.1'!Z43 | AA42: =D42*E42*$AV$8/1000 | AN42: =D42*O42*P42/1000 | AO42: =D42*Q42/1000 | AP42: =AO42/$AO$43
...

Sheet Fr-05
B1: สรุปการปล่อยก๊าซเรือนกระจกขององค์กร | I1: TCFO_R_01 Version 04 : 21/2/2020
B3: ชื่อฟอร์ม | C3: บัญชีรายการก๊าซเรือนกระจก | E3: องค์กร | F3: ='Fr-01'!$B$6 | I3: หน้าที่ | J3: 6
B4: รหัสฟอร์ม | C4: Fr-05 | E4: ผู้จัดทำ | F4: ='Fr-01'!$G$4 | I4: วันที่จัดทำ | J4: ='Fr-01'!J4
A5: ปีปัจจุบัน | B5: ='Fr-01'!H36
B6: ขอบเขต | C6: การปล่อยก๊าซเรือนกระจกขององค์กร | D6: สัดส่วนเมื่อเทียบขอบเขต 1 และ 2 | E6: สัดส่วนเมื่อเทียบขอบเขต 1, 2 และ 3
B10: ประเภท 1 | C10: =ROUNDUP('Fr-04.1'!AO36,0) | D10: =C10/C$14% | E10: =C10/SUM(C10:C12)%
B11: ประเภท 2 | C11: =ROUNDUP('Fr-04.1'!AO49,0) | D11: =C11/C$14% | E11: =C11/SUM(C10:C12)%
B12: ประเภท 3 | C12: =ROUNDUP('Fr-04.1'!AO57,0) | E12: =C12/SUM(C10:C12)%
B13: อื่น ๆ | C13: =ROUNDUP('Fr-04.1'!AO44,0)
B14: รวม Scope 1 & 2 | C14: =SUM(C10:C11) | D14: =SUM(D10:D11)
B15: รวม Scope 1 & 2 & 3 | C15: =SUM(C10:C12) | E15: =SUM(E10:E12)
B17: Carbon intensity (Scope 1+2) | D17: =C14/'Fr-01'!H37 | E17: TonCO2eq/ | F17: ='Fr-01'!J37
B18: Carbon intensity (Scope 1+2+3) | D18: =C15/'Fr-01'!H37 | E18: TonCO2eq/ | F18: ='Fr-01'!J37
A20: ปีฐาน | B20: ='Fr-01'!H38
B22: ขอบเขต | C22: การปล่อยก๊าซเรือนกระจกขององค์กร | D22: สัดส่วนเมื่อเทียบขอบเขต 1 และ 2 | E22: สัดส่วนเมื่อเทียบขอบเขต 1, 2 และ 3 | G22: เปรียบเทียบ
B26: ประเภท 1 | C26: =ROUNDUP('Fr-04.2'!AO35,0) | D26: =C26/C$14% | E26: =C26/SUM(C26:C28)%
B27: ประเภท 2 | C27: =ROUNDUP('Fr-04.2'!AO48,0) | D27: =C27/C$14% | E27: =C27/SUM(C26:C28)%
B28: ประเภท 3 | C28: =ROUNDUP('Fr-04.2'!AO56,0) | E28: =C28/SUM(C26:C28)%
B29: อื่น ๆ | C29: =ROUNDUP('Fr-04.2'!AO43,0)
B30: รวม Scope 1 & 2 | C30: =SUM(C26:C27) | D30: =SUM(D26:D27)
B31: รวม Scope 1 & 2 & 3 | C31: =SUM(C26:C28) | E31: =SUM(E26:E28)
B33: Carbon intensity (Scope 1+2) | D33: =C30/'Fr-01'!H39 | E33: TonCO2eq/ | F33: =F17
B34: Carbon intensity (Scope 1+2+3) | D34: =C31/'Fr-01'!H39 | E34: TonCO2eq/ | F34: =F18
A37: จัดทำโดย | B37: ='Fr-04.2'!B59 | G37: เสร็จสิ้นวันที่ | H37: ='Fr-03.1'!K35

Sheet EF TGO AR4
B2: ชื่อ | C2: Units | D2: EMISSION FACTORS | H2: แหล่งอ้างอิงข้อมูล | J2: GWP100
