Workbook

Sheet Fr-01
B1: รายละเอียดขององค์กร | I1: TCFO_R_01 Version 04 : 21/2/2020
B3: ชื่อฟอร์ม | C3: บัญชีรายการก๊าซเรือนกระจก | E3: องค์กร | G3: =B6 -> บริษัท มัลติแบกซ์ จำกัด (มหาชน) | I3: หน้าที่ | J3: 1
B4: รหัสฟอร์ม | C4: Fr-01 | E4: ผู้จัดทำ | G4: บริษัท อีโค เซ็นทริก คอร์ปอเรชั่น จำกัด | I4: วันที่จัดทำ | J4: 243820
B6: บริษัท มัลติแบกซ์ จำกัด (มหาชน)
A8: รูปขององค์กร | F8: ขอบเขตขององค์กร
F9: ประเภท 1 | H9: ='Fr-04.1'!B10 -> Stationary combustion
H10: ='Fr-04.1'!B11 -> น้ำมัน Diesel B7 (Fire Pump)
H11: ='Fr-04.1'!B12 -> น้ำมัน Gasohol 91/95 (เครื่องตัดหญ้า)
H12: ='Fr-04.1'!B13 -> Acetylene Gas (ซ่อมบำรุง)
H13: ='Fr-04.1'!B14 -> Biodiesel (Stationary combustion)
H14: ='Fr-04.1'!B15 -> Biogasoline (Ethanol) (Stationary combustion)
H15: ='Fr-04.1'!B16 -> 0
H16: ='Fr-04.1'!B17 -> 0
H17: ='Fr-04.1'!B19 -> 0
H18: ='Fr-04.1'!B21 -> 0
H19: ='Fr-04.1'!B22 -> 0
H20: ='Fr-04.1'!B24 -> 0
H21: ='Fr-04.1'!B25 -> 0
H22: ='Fr-04.1'!B26 -> 0
H23: ='Fr-04.1'!B27 -> 0
H24: ='Fr-04.1'!B28 -> 0
H25: ='Fr-04.1'!B29 -> 0
H26: ='Fr-04.1'!B30 -> 0
H27: ='Fr-04.1'!B31 -> 0
H28: ='Fr-04.1'!B32 -> 0
F29: ประเภท 2 | H29: ='Fr-04.1'!B45 -> 0
F32: ประเภท 3 | H32: ='Fr-04.1'!B50 -> 0
H33: ='Fr-04.1'!B51 -> 0
H34: ='Fr-04.1'!B52 -> 0
H35: ='Fr-04.1'!B53 -> 0
F36: ระยะเวลาเก็บข้อมูล | H36: 1 มกราคม - 31 ธันวาคม 2566
F37: ผลผลิต | H37: 9586 | J37: ตัน
F38: ปีฐาน | H38: 1 มกราคม - 31 ธันวาคม 2566
F39: ผลผลิตปีฐาน | H39: 9586 | J39: =J37 -> ตัน
F40: ข้อมูลองค์กร
F41: 1 | G41: ผลิตสินค้าเม็ดพลาสติก
F42: 2 | G42: ผลิตสินค้าถุงพลาสติก
F43: 3
F44: 4
F45: 5
...

Sheet Fr-02
B1: แผนภาพองค์กร | L1: TCFO_R_01 Version 04 : 21/2/2020
B3: ชื่อฟอร์ม | C3: บัญชีรายการก๊าซเรือนกระจก | F3: องค์กร | G3: ='Fr-01'!$B$6 -> บริษัท มัลติแบกซ์ จำกัด (มหาชน) | L3: หน้าที่ | M3: 2
B4: รหัสฟอร์ม | C4: Fr-02 | F4: ผู้จัดทำ | G4: ='Fr-01'!$G$4 -> บริษัท อีโค เซ็นทริก คอร์ปอเรชั่น จำกัด | L4: วันที่ | M4: ='Fr-01'!J4 -> 243820

Sheet Fr-03.1
B1: แผนภาพแสดงโครงสร้างขององค์กรและหน้าที่ความรับผิดชอบ | L1: TCFO_R_01 Version 04 : 21/2/2020
B3: ชื่อฟอร์ม | C3: บัญชีรายการก๊าซเรือนกระจก | F3: องค์กร | G3: ='Fr-01'!$B$6 -> บริษัท มัลติแบกซ์ จำกัด (มหาชน) | L3: หน้าที่ | M3: 3
B4: รหัสฟอร์ม | C4: Fr-03.1 | F4: ผู้จัดทำ | G4: ='Fr-01'!$G$4 -> บริษัท อีโค เซ็นทริก คอร์ปอเรชั่น จำกัด | L4: วันที่ | M4: ='Fr-01'!J4 -> 243820
A35: จัดทำโดย | B35: ='Fr-01'!G4 -> บริษัท อีโค เซ็นทริก คอร์ปอเรชั่น จำกัด | J35: เสร็จสิ้นวันที่ | K35: 243829

Sheet Fr-03.2
B1: ประเมินความมีนัยสำคัญของการปล่อยก๊าซเรือนกระจกทางอ้อม (SCOPE 3) | O1: TCFO_R_01 Version 04 : 21/2/2020
B3: ชื่อฟอร์ม | C3: ประเมินความมีนัยสำคัญ Scope3 | E3: องค์กร | F3: ='Fr-01'!G3 -> บริษัท มัลติแบกซ์ จำกัด (มหาชน) | O3: หน้าที่ | P3: 3
B4: รหัสฟอร์ม | C4: Fr-03.2 | E4: ผู้จัดทำ | F4: ='Fr-01'!G4 -> บริษัท อีโค เซ็นทริก คอร์ปอเรชั่น จำกัด | O4: วันที่ | P4: ='Fr-01'!J4 -> 243820
A6: คำอธิบาย | B6: องค์กรจะต้องคัดเลือกแหล่งปล่อยก๊าซเรือนกระจกทางอ้อม (Scope 3) โดยกำหนดเกณฑ์ในการประเมินความมีนัยสำคัญของการปล่อยก๊าซเรือนกระจกทางอ้อม (Scope 3)
A8: ประเด็นที่ต้องพิจารณา | C8: คำอธิบาย
A9: Source of GHG | C9: องค์กรมีแหล่งปล่อยก๊าซเรือนกระจกนี้หรือไม่
A10: ขนาด (Magnitude or Size) | C10: เป็นกิจกรรมการปล่อยหรือดูดกลับก๊าซเรือนกระจกทางอ้อมซึ่งถูกสันนิษฐานว่ามีปริมาณการปล่อยหรือดูดกลับก๊าซเรือนกระจกในปริมาณมากอย่างมีนัยสำคัญ
A11: ระดับของแรงจูงใจ (Level of influence (Reduction of potential)) | C11: เป็นกิจกรรมการปล่อยหรือดูดกลับก๊าซเรือนกระจกที่องค์กรมีความสามารถในการตรวจติดตามและลดปริมาณการปล่อยหรือดูดกลับก๊าซเรือนกระจกจากกิจกรรมนั้น(ตัวอย่างเช่นเป็นกิจกรรมที่เกี่ยวข้องกับการประเมินประสิทธิภาพพลังงาน การออกแบบเชิงนิเวศเศรษฐกิจ, เกี่ยวข้องกับข้อตกลงที่มีกับลูกค้า, เกี่ยวข้องกับข้อกำหนดขอบเขตงานจากผู้ว่าจ้าง)
A12: ความเสี่ยง หรือ โอกาส Risk or opportunity | C12: เป็นกิจกรรมการปล่อยหรือดูดกลับก๊าซเรือนกระจกทางอ้อมซึ่งมีส่วนทำให้องค์กรได้รับความเสี่ยง (ตัวอย่างของความเสี่ยงที่มีความเชื่อมโยงกับการเปลี่ยนแปลงสภาพภูมิอากาศ เช่น ความเสี่ยงทางด้านการเงิน, ความเสี่ยงทางด้านกฎระเบียบข้อบังคับ, ความเสี่ยงตลอดห่วงโซ่อุปทาน, ความเสี่ยงเกี่ยวกับสินค้าและลูกค้า, ความเสี่ยงเกี่ยวกับการดำเนินคดี และ ความเสี่ยงด้านชื่อเสียง) หรือได้รับโอกาสต่างๆ ทางธุรกิจ (เช่น การเข้าสู่ช่องทางตลาดใหม่ การเข้าสู่ระบบธุรกิจในรูปแบบใหม่)
A13: Sector Guidance | C13: เป็นกิจกรรมการปล่อยก๊าซเรือนกระจกที่ถูกถือว่ามีนัยสำคัญสำหรับอุตสาหกรรมที่กำลังพิจารณา ตามที่กำหนดไว้ในคู่มือหรือแนวทางที่เฉพาะเจาะจงสำหรับอุตสาหกรรมนั้น
A14: Outsourcing | C14: เป็นกิจกรรมการปล่อยและดูดกลับก๊าซเรือนกระจกทางอ้อมที่เกิดจากการจัดจ้างบุคคลหรือหน่วยงานภายนอกเข้ามาดำเนินกิจกรรมที่ถือว่า เป็นกิจกรรมหลักในการดำเนินธุรกิจขององค์กร
A15: Employee engagement | C15: เป็นกิจกรรมการปล่อยก๊าซเรือนกระจกทางอ้อมที่สามารถส่งเสริมให้เกิดการกระตุ้นให้พนักงานมีส่วนร่วมในการลดการปล่อยก๊าซเรือนกระจก ผ่านการลดการใช้พลังงาน หรือการทำงานร่วมกันเป็นทีมภายใต้หลักคิดที่เกี่ยวข้องกับการเปลี่ยนแปลงสภาพภูมิอากาศ (เช่น การสร้างแรงจูงใจในการอนุรักษ์พลังงาน, การเดินทาง โดยใช้รถร่วมกัน, การประเมินราคาคาร์บอนภายในองค์กร เป็นต้น)
A16: ที่มา : หัวข้อที่ 12 ข้อกำหนดในการคำนวณและรายงานคาร์บอนฟุตพริ้นท์ขององค์กร พิมพ์ครั้งที่ 7 (ฉบับปรับปรุงครั้งที่ 5, มกราคม 2564)
C19: น้ำหนักประเด็นที่พิจารณา | F19: 0.6 | G19: 0.2 | H19: 0.1 | I19: 0.1
A20: No. TGO | B20: Scope in ISO 14064-1 | C20: Category | D20: Source of GHG | E20: Source of EF | F20: Magnitude | G20: Level of influence (Reduction of potential) | H20: Risk | I20: Oppoturnity | J20: ผลคะแนน | K20: ผลการประเมิน | L20: ผลการคัดเลือก | M20: GHG (tCO2eq.) | N20: %
A21: 3.1 | B21: 4.1 | C21: Purchased Goods & Services
C22: =#REF! -> #REF! | D22: 1 | E22: 1 | F22: 3 | G22: 3 | H22: 3 | I22: 5 | J22: =D22+E22+(F22*$F$19)+(G22*$G$19)+(H22*$H$19)+(I22*$I$19) -> 5.2 | K22: มีนัยสำคัญ | L22: เลือกประเมิน | M22: =#REF! -> #REF! | N22: =#REF! -> #REF!
C23: =#REF! -> #REF! | D23: 1 | E23: 1 | F23: 3 | G23: 3 | H23: 3 | I23: 5 | J23: =D23+E23+(F23*$F$19)+(G23*$G$19)+(H23*$H$19)+(I23*$I$19) -> 5.2 | K23: มีนัยสำคัญ | L23: เลือกประเมิน | M23: =#REF! -> #REF! | N23: =#REF! -> #REF!
C24: =#REF! -> #REF! | D24: 1 | E24: 1 | F24: 3 | G24: 3 | H24: 3 | I24: 5 | J24: =D24+E24+(F24*$F$19)+(G24*$G$19)+(H24*$H$19)+(I24*$I$19) -> 5.2 | K24: มีนัยสำคัญ | L24: เลือกประเมิน | M24: =#REF! -> #REF! | N24: =#REF! -> #REF!
C25: =#REF! -> #REF! | D25: 1 | E25: 1 | F25: 1 | G25: 1 | H25: 1 | I25: 1 | J25: =D25+E25+(F25*$F$19)+(G25*$G$19)+(H25*$H$19)+(I25*$I$19) -> 3 | K25: ไม่มีนัยสำคัญ | M25: =#REF! -> #REF! | N25: =#REF! -> #REF!
C26: =#REF! -> #REF! | D26: 1 | E26: 1 | F26: 1 | G26: 1 | H26: 1 | I26: 1 | J26: =D26+E26+(F26*$F$19)+(G26*$G$19)+(H26*$H$19)+(I26*$I$19) -> 3 | K26: ไม่มีนัยสำคัญ | M26: =#REF! -> #REF! | N26: =#REF! -> #REF!
C27: =#REF! -> #REF! | D27: 1 | E27: 1 | F27: 1 | G27: 1 | H27: 1 | I27: 1 | J27: =D27+E27+(F27*$F$19)+(G27*$G$19)+(H27*$H$19)+(I27*$I$19) -> 3 | K27: ไม่มีนัยสำคัญ | M27: =#REF! -> #REF! | N27: =#REF! -> #REF!
C28: =#REF! -> #REF! | D28: 1 | E28: 1 | F28: 1 | G28: 1 | H28: 1 | I28: 1 | J28: =D28+E28+(F28*$F$19)+(G28*$G$19)+(H28*$H$19)+(I28*$I$19) -> 3 | K28: ไม่มีนัยสำคัญ | M28: =#REF! -> #REF! | N28: =#REF! -> #REF!
C29: =#REF! -> #REF! | D29: 1 | E29: 1 | F29: 1 | G29: 1 | H29: 1 | I29: 1 | J29: =D29+E29+(F29*$F$19)+(G29*$G$19)+(H29*$H$19)+(I29*$I$19) -> 3 | K29: ไม่มีนัยสำคัญ | M29: =#REF! -> #REF! | N29: =#REF! -> #REF!
C30: =#REF! -> #REF! | D30: 1 | E30: 1 | F30: 1 | G30: 1 | H30: 1 | I30: 1 | J30: =D30+E30+(F30*$F$19)+(G30*$G$19)+(H30*$H$19)+(I30*$I$19) -> 3 | K30: ไม่มีนัยสำคัญ | M30: =#REF! -> #REF! | N30: =#REF! -> #REF!
C31: =#REF! -> #REF! | D31: 1 | E31: 1 | F31: 1 | G31: 1 | H31: 1 | I31: 1 | J31: =D31+E31+(F31*$F$19)+(G31*$G$19)+(H31*$H$19)+(I31*$I$19) -> 3 | K31: ไม่มีนัยสำคัญ | M31: =#REF! -> #REF! | N31: =#REF! -> #REF!
C32: =#REF! -> #REF! | D32: 1 | E32: 1 | F32: 1 | G32: 1 | H32: 1 | I32: 1 | J32: =D32+E32+(F32*$F$19)+(G32*$G$19)+(H32*$H$19)+(I32*$I$19) -> 3 | K32: ไม่มีนัยสำคัญ | M32: =#REF!+#REF! -> #REF! | N32: =#REF!+#REF! -> #REF!
A33: 3.2 | B33: 4.2 | C33: Capital goods | D33: 1 | E33: 0 | J33: =D33+E33+(F33*$F$19)+(G33*$G$19)+(H33*$H$19)+(I33*$I$19) -> 1 | K33: ไม่มีนัยสำคัญ/มีนัยสำคัญ
A34: 3.3 | B34: 2.2 | C34: Fuel- and energy related activities
C35: =#REF! -> #REF! | D35: 1 | E35: 1 | F35: 1 | G35: 1 | H35: 1 | I35: 1 | J35: =D35+E35+(F35*$F$19)+(G35*$G$19)+(H35*$H$19)+(I35*$I$19) -> 3 | K35: ไม่มีนัยสำคัญ | M35: =#REF! -> #REF! | N35: =#REF! -> #REF!
C36: =#REF! -> #REF! | D36: 1 | E36: 1 | F36: 1 | G36: 1 | H36: 1 | I36: 1 | J36: =D36+E36+(F36*$F$19)+(G36*$G$19)+(H36*$H$19)+(I36*$I$19) -> 3 | K36: ไม่มีนัยสำคัญ | M36: =#REF! -> #REF! | N36: =#REF! -> #REF!
C37: =#REF! -> #REF! | D37: 1 | E37: 1 | F37: 1 | G37: 1 | H37: 1 | I37: 1 | J37: =D37+E37+(F37*$F$19)+(G37*$G$19)+(H37*$H$19)+(I37*$I$19) -> 3 | K37: ไม่มีนัยสำคัญ | M37: =#REF! -> #REF! | N37: =#REF! -> #REF!
C38: =#REF! -> #REF! | D38: 1 | E38: 1 | F38: 1 | G38: 1 | H38: 1 | I38: 1 | J38: =D38+E38+(F38*$F$19)+(G38*$G$19)+(H38*$H$19)+(I38*$I$19) -> 3 | K38: ไม่มีนัยสำคัญ | M38: =#REF! -> #REF! | N38: =#REF! -> #REF!
A39: 3.4 | B39: 3.1 | C39: Upstream transportation and distribution
C40: =#REF! -> #REF! | D40: 1 | E40: 1 | F40: 1 | G40: 1 | H40: 1 | I40: 1 | J40: =D40+E40+(F40*$F$19)+(G40*$G$19)+(H40*$H$19)+(I40*$I$19) -> 3 | K40: ไม่มีนัยสำคัญ | M40: =#REF! -> #REF! | N40: =#REF! -> #REF!
C41: =#REF! -> #REF! | D41: 1 | E41: 1 | F41: 1 | G41: 1 | H41: 1 | I41: 1 | J41: =D41+E41+(F41*$F$19)+(G41*$G$19)+(H41*$H$19)+(I41*$I$19) -> 3 | K41: ไม่มีนัยสำคัญ | M41: =#REF! -> #REF! | N41: =#REF! -> #REF!
C42: =#REF! -> #REF! | D42: 1 | E42: 1 | F42: 1 | G42: 1 | H42: 1 | I42: 1 | J42: =D42+E42+(F42*$F$19)+(G42*$G$19)+(H42*$H$19)+(I42*$I$19) -> 3 | K42: ไม่มีนัยสำคัญ | M42: =#REF! -> #REF! | N42: =#REF! -> #REF!
C43: =#REF! -> #REF! | D43: 1 | E43: 1 | F43: 1 | G43: 1 | H43: 1 | I43: 1 | J43: =D43+E43+(F43*$F$19)+(G43*$G$19)+(H43*$H$19)+(I43*$I$19) -> 3 | K43: ไม่มีนัยสำคัญ | M43: =#REF! -> #REF! | N43: =#REF! -> #REF!
C44: =#REF! -> #REF! | D44: 1 | E44: 1 | F44: 1 | G44: 1 | H44: 1 | I44: 1 | J44: =D44+E44+(F44*$F$19)+(G44*$G$19)+(H44*$H$19)+(I44*$I$19) -> 3 | K44: ไม่มีนัยสำคัญ | M44: =#REF! -> #REF! | N44: =#REF! -> #REF!
C45: =#REF! -> #REF! | D45: 1 | E45: 1 | F45: 1 | G45: 1 | H45: 1 | I45: 1 | J45: =D45+E45+(F45*$F$19)+(G45*$G$19)+(H45*$H$19)+(I45*$I$19) -> 3 | K45: ไม่มีนัยสำคัญ | M45: =#REF! -> #REF! | N45: =#REF! -> #REF!
...

Sheet Fr-04.1
B1: บัญชีรายการก๊าซเรือนกระจก | AO1: TCFO_R_01 Version 04 : 21/2/2020
B3: ชื่อฟอร์ม | C3: บัญชีรายการก๊าซเรือนกระจก | H3: องค์กร | I3: ='Fr-01'!$B$6 -> บริษัท มัลติแบกซ์ จำกัด (มหาชน) | AB3: ปีที่เก็บข้อมูล | AE3: ='Fr-01'!H36 -> 1 มกราคม - 31 ธันวาคม 2566 | AO3: หน้าที่ | AR3: 4
B4: รหัสฟอร์ม | C4: Fr-04.1 | H4: ผู้จัดทำ | I4: ='Fr-01'!$G$4 -> บริษัท อีโค เซ็นทริก คอร์ปอเรชั่น จำกัด | AO4: วันที่ | AR4: 45494
A6: ขอบเขต | B6: รายการ | C6: ค่า LCI | E6: GHG ที่ต้องรายงานตามข้อกำหนด | O6: GHG ที่อยู่นอกข้อกำหนด | Q6: Total (kgCO2e/หน่วย) | R6: ที่มา | Y6: Subsitute | Z6: แหล่งอ้างอิง | AA6: ผลคูณ (Ton GHG) | AG6: ผลคูณ (TonCO2e) | AO6: Total GHG | AP6: สัดส่วน (%) | AQ6: สัดส่วน (%) (SCOPE 1+2) | AR6: สัดส่วน (%) (SCOPE 1+2+3) | AS6: คำอธิบายเพิ่มเติม | AU6: GWP100
R7: 1st | T7: 2nd | X7: Other | AU7: ที่มา | AV7: IPCC, AR5
E8: ค่า EF (kg GHG/หน่วย) | M8: GWP100 | O8: ค่า EF (kg GHG/หน่วย) | P8: GWP100 | R8: Self collct | S8: Supplier | T8: TH LCI DB | U8: TGO EF | V8: Thai Res. | W8: Int. DB | AO8: (TonCO2e) | AU8: CO2 | AV8: 1
C9: หน่วย | D9: ปริมาณ | E9: CO2 | F9: Fossil CH4 | G9: CH4 | H9: N2O | I9: SF6 | J9: NF3 | K9: HFCs | L9: PFCs | M9: HFCs | N9: PFCs | AA9: CO2 | AB9: Fossil CH4 | AC9: CH4 | AD9: N2O | AE9: SF6 | AF9: NF3 | AG9: Fossil CH4 | AH9: CH4 | AI9: N2O | AJ9: SF6 | AK9: NF3 | AL9: HFCs | AM9: PFCs | AN9: Other | AU9: Fossil CH4 | AV9: 30
A10: ขอบเขต 1 | B10: Stationary combustion | Q10: =(E10*$AV$8)+(F10*$AV$9)+(G10*$AV$10)+(H10*$AV$11)+(I10*$AV$12)+(J10*$AV$13)+(K10*M10)+(L10*N10) -> 0 | AA10: =D10*E10/1000 -> 0 | AB10: =D10*F10/1000 -> 0 | AC10: =D10*G10/1000 -> 0 | AD10: =D10*H10/1000 -> 0 | AE10: =D10*I10/1000 -> 0 | AF10: =D10*J10/1000 -> 0 | AG10: =D10*F10*$AV$9/1000 -> 0 | AH10: =D10*G10*$AV$10/1000 -> 0 | AI10: =D10*H10*$AV$11/1000 -> 0 | AJ10: =D10*I10*$AV$12/1000 -> 0 | AK10: =D10*J10*$AV$13/1000 -> 0 | AL10: =D10*K10*M10/1000 -> 0 | AM10: =D10*L10*N10/1000 -> 0 | AO10: =D10*Q10/1000 -> 0 | AP10: =AO10/$AO$36 -> 0 | AQ10: =AO10/$AO$58 -> 0 | AR10: =AO10/$AO$59 -> 0 | AU10: CH4 | AV10: 28
B11: ='1.1 Stationary '!A9 -> น้ำมัน Diesel B7 (Fire Pump) | C11: ='1.1 Stationary '!C9 -> L | D11: ='1.1 Stationary '!G4 -> 502.2 | E11: ='EF TGO AR5'!D11 -> 2.698722 | F11: ='EF TGO AR5'!E11 -> 0.00010926 | G11: ='EF TGO AR5'!F11 -> 0 | H11: ='EF TGO AR5'!G11 -> 2.1852e-05 | Q11: =(E11*$AV$8)+(F11*$AV$9)+(G11*$AV$10)+(H11*$AV$11)+(I11*$AV$12)+(J11*$AV$13)+(K11*M11)+(L11*N11) -> 2.7077906 | U11: / | Z11: TGO CFO EF (เมษายน 2565):Gas/Diesel oil | AA11: =D11*E11/1000 -> 1.3552982 | AB11: =D11*F11/1000 -> 5.4870372e-05 | AC11: =D11*G11/1000 -> 0 | AD11: =D11*H11/1000 -> 1.0974074e-05 | AE11: =D11*I11/1000 -> 0 | AF11: =D11*J11/1000 -> 0 | AG11: =D11*F11*AJ13/1000 -> 0 | AH11: =D11*G11*$AV$10/1000 -> 0 | AI11: =D11*H11*$AV$11/1000 -> 0.0029081297 | AJ11: =D11*I11*$AV$12/1000 -> 0 | AK11: =D11*J11*$AV$13/1000 -> 0 | AL11: =D11*K11*M11/1000 -> 0 | AM11: =D11*L11*N11/1000 -> 0 | AO11: =D11*Q11/1000 -> 1.3598524 | AP11: =AO11/$AO$36 -> 0.8338074 | AQ11: =AO11/$AO$58 -> 0.8338074 | AR11: =AO11/$AO$59 -> 0.8338074 | AU11: N2O | AV11: 265
B12: ='1.1 Stationary '!A10 -> น้ำมัน Gasohol 91/95 (เครื่องตัดหญ้า) | C12: ='1.1 Stationary '!C10 -> L | D12: ='1.1 Stationary '!J5 -> 46.3914 | E12: ='EF TGO AR5'!D17 -> 2.181564 | F12: ='EF TGO AR5'!E17 -> 9.444e-05 | G12: ='EF TGO AR5'!F17 -> 0 | H12: ='EF TGO AR5'!G17 -> 1.8888e-05 | Q12: =(E12*$AV$8)+(F12*$AV$9)+(G12*$AV$10)+(H12*$AV$11)+(I12*$AV$12)+(J12*$AV$13)+(K12*M12)+(L12*N12) -> 2.1894025 | U12: / | Z12: TGO CFO EF (เมษายน 2565): Motor Gasoline | AA12: =D12*E12/1000 -> 0.10120581 | AB12: =D12*F12/1000 -> 4.3812038e-06 | AC12: =D12*G12/1000 -> 0 | AD12: =D12*H12/1000 -> 8.7624076e-07 | AE12: =D12*I12/1000 -> 0 | AF12: =D12*J12/1000 -> 0 | AG12: =D12*F12*$AV$9/1000 -> 0.00013143611 | AH12: =D12*G12*$AV$10/1000 -> 0 | AI12: =D12*H12*$AV$11/1000 -> 0.0002322038 | AJ12: =D12*I12*$AV$12/1000 -> 0 | AK12: =D12*J12*$AV$13/1000 -> 0 | AL12: =D12*K12*M12/1000 -> 0 | AM12: =D12*L12*N12/1000 -> 0 | AO12: =D12*Q12/1000 -> 0.10156945 | AP12: =AO12/$AO$36 -> 0.062278344 | AQ12: =AO12/$AO$58 -> 0.062278344 | AR12: =AO12/$AO$59 -> 0.062278344 | AU12: SF6 | AV12: 23500 | AX12: =0.0025*265 -> 0.6625
B13: ='1.1 Stationary '!A11 -> Acetylene Gas (ซ่อมบำรุง) | C13: ='1.1 Stationary '!C11 -> kg | D13: ='1.1 Stationary '!D11 -> 50 | E13: ='EF (1)'!B9 -> 3.3846154 | Q13: =(E13*$AV$8)+(F13*$AV$9)+(G13*$AV$10)+(H13*$AV$11)+(I13*$AV$12)+(J13*$AV$13)+(K13*M13)+(L13*N13) -> 3.3846154 | X13: / | Z13: EF (1) สมการเคมี | AA13: =D13*E13/1000 -> 0.16923077 | AB13: =D13*F13/1000 -> 0 | AC13: =D13*G13/1000 -> 0 | AD13: =D13*H13/1000 -> 0 | AE13: =D13*I13/1000 -> 0 | AF13: =D13*J13/1000 -> 0 | AG13: =D13*F13*$AV$9/1000 -> 0 | AH13: =D13*G13*$AV$10/1000 -> 0 | AI13: =D13*H13*$AV$11/1000 -> 0 | AJ13: =D13*I13*$AV$12/1000 -> 0 | AK13: =D13*J13*$AV$13/1000 -> 0 | AL13: =D13*K13*M13/1000 -> 0 | AM13: =D13*L13*N13/1000 -> 0 | AO13: =D13*Q13/1000 -> 0.16923077 | AP13: =AO13/$AO$36 -> 0.10376557 | AQ13: =AO13/$AO$58 -> 0.10376557 | AR13: =AO13/$AO$59 -> 0.10376557 | AU13: NF3 | AV13: 16100
B14: Biodiesel (Stationary combustion) | C14: kg | D14: ='1.1 Stationary '!I4 -> 32.886 | G14: ='EF (1)'!F28*'EF (1)'!D28 -> 8.1e-05 | H14: ='EF (1)'!F28*'EF (1)'!E28 -> 1.62e-05 | Q14: =(E14*$AV$8)+(F14*$AV$9)+(G14*$AV$10)+(H14*$AV$11)+(I14*$AV$12)+(J14*$AV$13)+(K14*M14)+(L14*N14) -> 0.006561 | W14: / | Z14: IPCC, 2006 | AA14: =D14*E14/1000 -> 0 | AB14: =D14*F14/1000 -> 0 | AC14: =D14*G14/1000 -> 2.663766e-06 | AD14: =D14*H14/1000 -> 5.327532e-07 | AE14: =D14*I14/1000 -> 0 | AF14: =D14*J14/1000 -> 0 | AG14: =D14*F14*$AV$9/1000 -> 0 | AH14: =D14*G14*$AV$10/1000 -> 7.4585448e-05 | AI14: =D14*H14*$AV$11/1000 -> 0.0001411796 | AJ14: =D14*I14*$AV$12/1000 -> 0 | AK14: =D14*J14*$AV$13/1000 -> 0 | AL14: =D14*K14*M14/1000 -> 0 | AM14: =D14*L14*N14/1000 -> 0 | AO14: =D14*Q14/1000 -> 0.00021576505 | AP14: =AO14/$AO$36 -> 0.00013229854 | AQ14: =AO14/$AO$58 -> 0.00013229854 | AR14: =AO14/$AO$59 -> 0.00013229854
B15: Biogasoline (Ethanol) (Stationary combustion) | C15: kg | D15: ='1.1 Stationary '!L5 -> 4.072134 | G15: ='EF (1)'!F29*'EF (1)'!D29 -> 8.1e-05 | H15: ='EF (1)'!F29*'EF (1)'!E29 -> 1.62e-05 | Q15: =(E15*$AV$8)+(F15*$AV$9)+(G15*$AV$10)+(H15*$AV$11)+(I15*$AV$12)+(J15*$AV$13)+(K15*M15)+(L15*N15) -> 0.006561 | W15: / | Z15: IPCC, 2006 | AA15: =D15*E15/1000 -> 0 | AB15: =D15*F15/1000 -> 0 | AC15: =D15*G15/1000 -> 3.2984285e-07 | AD15: =D15*H15/1000 -> 6.5968571e-08 | AE15: =D15*I15/1000 -> 0 | AF15: =D15*J15/1000 -> 0 | AG15: =D15*F15*$AV$9/1000 -> 0 | AH15: =D15*G15*$AV$10/1000 -> 9.2355999e-06 | AI15: =D15*H15*$AV$11/1000 -> 1.7481671e-05 | AJ15: =D15*I15*$AV$12/1000 -> 0 | AK15: =D15*J15*$AV$13/1000 -> 0 | AL15: =D15*K15*M15/1000 -> 0 | AM15: =D15*L15*N15/1000 -> 0 | AO15: =D15*Q15/1000 -> 2.6717271e-05 | AP15: =AO15/$AO$36 -> 1.6381968e-05 | AQ15: =AO15/$AO$58 -> 1.6381968e-05 | AR15: =AO15/$AO$59 -> 1.6381968e-05
Q16: =(E16*$AV$8)+(F16*$AV$9)+(G16*$AV$10)+(H16*$AV$11)+(I16*$AV$12)+(J16*$AV$13)+(K16*M16)+(L16*N16) -> 0 | AA16: =D16*E16/1000 -> 0 | AB16: =D16*F16/1000 -> 0 | AC16: =D16*G16/1000 -> 0 | AD16: =D16*H16/1000 -> 0 | AE16: =D16*I16/1000 -> 0 | AF16: =D16*J16/1000 -> 0 | AG16: =D16*F16*$AV$9/1000 -> 0 | AH16: =D16*G16*$AV$10/1000 -> 0 | AI16: =D16*H16*$AV$11/1000 -> 0 | AJ16: =D16*I16*$AV$12/1000 -> 0 | AK16: =D16*J16*$AV$13/1000 -> 0 | AL16: =D16*K16*M16/1000 -> 0 | AM16: =D16*L16*N16/1000 -> 0 | AO16: =D16*Q16/1000 -> 0 | AP16: =AO16/$AO$36 -> 0 | AQ16: =AO16/$AO$58 -> 0 | AR16: =AO16/$AO$59 -> 0
Q17: =(E17*$AV$8)+(F17*$AV$9)+(G17*$AV$10)+(H17*$AV$11)+(I17*$AV$12)+(J17*$AV$13)+(K17*M17)+(L17*N17) -> 0 | AA17: =D17*E17/1000 -> 0 | AB17: =D17*F17/1000 -> 0 | AC17: =D17*G17/1000 -> 0 | AD17: =D17*H17/1000 -> 0 | AE17: =D17*I17/1000 -> 0 | AF17: =D17*J17/1000 -> 0 | AG17: =D17*F17*$AV$9/1000 -> 0 | AH17: =D17*G17*$AV$10/1000 -> 0 | AI17: =D17*H17*$AV$11/1000 -> 0 | AJ17: =D17*I17*$AV$12/1000 -> 0 | AK17: =D17*J17*$AV$13/1000 -> 0 | AL17: =D17*K17*M17/1000 -> 0 | AM17: =D17*L17*N17/1000 -> 0 | AO17: =D17*Q17/1000 -> 0 | AP17: =AO17/$AO$36 -> 0 | AQ17: =AO17/$AO$58 -> 0 | AR17: =AO17/$AO$59 -> 0
Q18: =(E18*$AV$8)+(F18*$AV$9)+(G18*$AV$10)+(H18*$AV$11)+(I18*$AV$12)+(J18*$AV$13)+(K18*M18)+(L18*N18) -> 0 | AA18: =D18*E18/1000 -> 0 | AB18: =D18*F18/1000 -> 0 | AC18: =D18*G18/1000 -> 0 | AD18: =D18*H18/1000 -> 0 | AE18: =D18*I18/1000 -> 0 | AF18: =D18*J18/1000 -> 0 | AG18: =D18*F18*$AV$9/1000 -> 0 | AH18: =D18*G18*$AV$10/1000 -> 0 | AI18: =D18*H18*$AV$11/1000 -> 0 | AJ18: =D18*I18*$AV$12/1000 -> 0 | AK18: =D18*J18*$AV$13/1000 -> 0 | AL18: =D18*K18*M18/1000 -> 0 | AM18: =D18*L18*N18/1000 -> 0 | AO18: =D18*Q18/1000 -> 0 | AP18: =AO18/$AO$36 -> 0 | AQ18: =AO18/$AO$58 -> 0 | AR18: =AO18/$AO$59 -> 0
Q19: =(E19*$AV$8)+(F19*$AV$9)+(G19*$AV$10)+(H19*$AV$11)+(I19*$AV$12)+(J19*$AV$13)+(K19*M19)+(L19*N19) -> 0 | AA19: =D19*E19/1000 -> 0 | AB19: =D19*F19/1000 -> 0 | AC19: =D19*G19/1000 -> 0 | AD19: =D19*H19/1000 -> 0 | AE19: =D19*I19/1000 -> 0 | AF19: =D19*J19/1000 -> 0 | AG19: =D19*F19*$AV$9/1000 -> 0 | AH19: =D19*G19*$AV$10/1000 -> 0 | AI19: =D19*H19*$AV$11/1000 -> 0 | AJ19: =D19*I19*$AV$12/1000 -> 0 | AK19: =D19*J19*$AV$13/1000 -> 0 | AL19: =D19*K19*M19/1000 -> 0 | AM19: =D19*L19*N19/1000 -> 0 | AO19: =D19*Q19/1000 -> 0 | AP19: =AO19/$AO$36 -> 0 | AQ19: =AO19/$AO$58 -> 0 | AR19: =AO19/$AO$59 -> 0
Q20: =(E20*$AV$8)+(F20*$AV$9)+(G20*$AV$10)+(H20*$AV$11)+(I20*$AV$12)+(J20*$AV$13)+(K20*M20)+(L20*N20) -> 0 | AA20: =D20*E20/1000 -> 0 | AB20: =D20*F20/1000 -> 0 | AC20: =D20*G20/1000 -> 0 | AD20: =D20*H20/1000 -> 0 | AE20: =D20*I20/1000 -> 0 | AF20: =D20*J20/1000 -> 0 | AG20: =D20*F20*$AV$9/1000 -> 0 | AH20: =D20*G20*$AV$10/1000 -> 0 | AI20: =D20*H20*$AV$11/1000 -> 0 | AJ20: =D20*I20*$AV$12/1000 -> 0 | AK20: =D20*J20*$AV$13/1000 -> 0 | AL20: =D20*K20*M20/1000 -> 0 | AM20: =D20*L20*N20/1000 -> 0 | AO20: =D20*Q20/1000 -> 0 | AP20: =AO20/$AO$36 -> 0 | AQ20: =AO20/$AO$58 -> 0 | AR20: =AO20/$AO$59 -> 0
Q21: =(E21*$AV$8)+(F21*$AV$9)+(G21*$AV$10)+(H21*$AV$11)+(I21*$AV$12)+(J21*$AV$13)+(K21*M21)+(L21*N21) -> 0 | AA21: =D21*E21/1000 -> 0 | AB21: =D21*F21/1000 -> 0 | AC21: =D21*G21/1000 -> 0 | AD21: =D21*H21/1000 -> 0 | AE21: =D21*I21/1000 -> 0 | AF21: =D21*J21/1000 -> 0 | AG21: =D21*F21*$AV$9/1000 -> 0 | AH21: =D21*G21*$AV$10/1000 -> 0 | AI21: =D21*H21*$AV$11/1000 -> 0 | AJ21: =D21*I21*$AV$12/1000 -> 0 | AK21: =D21*J21*$AV$13/1000 -> 0 | AL21: =D21*K21*M21/1000 -> 0 | AM21: =D21*L21*N21/1000 -> 0 | AO21: =D21*Q21/1000 -> 0 | AP21: =AO21/$AO$36 -> 0 | AQ21: =AO21/$AO$58 -> 0 | AR21: =AO21/$AO$59 -> 0
Q22: =(E22*$AV$8)+(F22*$AV$9)+(G22*$AV$10)+(H22*$AV$11)+(I22*$AV$12)+(J22*$AV$13)+(K22*M22)+(L22*N22) -> 0 | AA22: =D22*E22/1000 -> 0 | AB22: =D22*F22/1000 -> 0 | AC22: =D22*G22/1000 -> 0 | AD22: =D22*H22/1000 -> 0 | AE22: =D22*I22/1000 -> 0 | AF22: =D22*J22/1000 -> 0 | AG22: =D22*F22*$AV$9/1000 -> 0 | AH22: =D22*G22*$AV$10/1000 -> 0 | AI22: =D22*H22*$AV$11/1000 -> 0 | AJ22: =D22*I22*$AV$12/1000 -> 0 | AK22: =D22*J22*$AV$13/1000 -> 0 | AL22: =D22*K22*M22/1000 -> 0 | AM22: =D22*L22*N22/1000 -> 0 | AO22: =D22*Q22/1000 -> 0 | AP22: =AO22/$AO$36 -> 0 | AQ22: =AO22/$AO$58 -> 0 | AR22: =AO22/$AO$59 -> 0
Q23: =(E23*$AV$8)+(F23*$AV$9)+(G23*$AV$10)+(H23*$AV$11)+(I23*$AV$12)+(J23*$AV$13)+(K23*M23)+(L23*N23) -> 0 | AA23: =D23*E23/1000 -> 0 | AB23: =D23*F23/1000 -> 0 | AC23: =D23*G23/1000 -> 0 | AD23: =D23*H23/1000 -> 0 | AE23: =D23*I23/1000 -> 0 | AF23: =D23*J23/1000 -> 0 | AG23: =D23*F23*$AV$9/1000 -> 0 | AH23: =D23*G23*$AV$10/1000 -> 0 | AI23: =D23*H23*$AV$11/1000 -> 0 | AJ23: =D23*I23*$AV$12/1000 -> 0 | AK23: =D23*J23*$AV$13/1000 -> 0 | AL23: =D23*K23*M23/1000 -> 0 | AM23: =D23*L23*N23/1000 -> 0 | AO23: =D23*Q23/1000 -> 0 | AP23: =AO23/$AO$36 -> 0 | AQ23: =AO23/$AO$58 -> 0 | AR23: =AO23/$AO$59 -> 0
Q24: =(E24*$AV$8)+(F24*$AV$9)+(G24*$AV$10)+(H24*$AV$11)+(I24*$AV$12)+(J24*$AV$13)+(K24*M24)+(L24*N24) -> 0 | AA24: =D24*E24/1000 -> 0 | AB24: =D24*F24/1000 -> 0 | AC24: =D24*G24/1000 -> 0 | AD24: =D24*H24/1000 -> 0 | AE24: =D24*I24/1000 -> 0 | AF24: =D24*J24/1000 -> 0 | AG24: =D24*F24*$AV$9/1000 -> 0 | AH24: =D24*G24*$AV$10/1000 -> 0 | AI24: =D24*H24*$AV$11/1000 -> 0 | AJ24: =D24*I24*$AV$12/1000 -> 0 | AK24: =D24*J24*$AV$13/1000 -> 0 | AL24: =D24*K24*M24/1000 -> 0 | AM24: =D24*L24*N24/1000 -> 0 | AO24: =D24*Q24/1000 -> 0 | AP24: =AO24/$AO$36 -> 0 | AQ24: =AO24/$AO$58 -> 0 | AR24: =AO24/$AO$59 -> 0
Q25: =(E25*$AV$8)+(F25*$AV$9)+(G25*$AV$10)+(H25*$AV$11)+(I25*$AV$12)+(J25*$AV$13)+(K25*M25)+(L25*N25) -> 0 | AA25: =D25*E25/1000 -> 0 | AB25: =D25*F25/1000 -> 0 | AC25: =D25*G25/1000 -> 0 | AD25: =D25*H25/1000 -> 0 | AE25: =D25*I25/1000 -> 0 | AF25: =D25*J25/1000 -> 0 | AG25: =D25*F25*$AV$9/1000 -> 0 | AH25: =D25*G25*$AV$10/1000 -> 0 | AI25: =D25*H25*$AV$11/1000 -> 0 | AJ25: =D25*I25*$AV$12/1000 -> 0 | AK25: =D25*J25*$AV$13/1000 -> 0 | AL25: =D25*K25*M25/1000 -> 0 | AM25: =D25*L25*N25/1000 -> 0 | AO25: =D25*Q25/1000 -> 0 | AP25: =AO25/$AO$36 -> 0 | AQ25: =AO25/$AO$58 -> 0 | AR25: =AO25/$AO$59 -> 0
Q26: =(E26*$AV$8)+(F26*$AV$9)+(G26*$AV$10)+(H26*$AV$11)+(I26*$AV$12)+(J26*$AV$13)+(K26*M26)+(L26*N26) -> 0 | AA26: =D26*E26/1000 -> 0 | AB26: =D26*F26/1000 -> 0 | AC26: =D26*G26/1000 -> 0 | AD26: =D26*H26/1000 -> 0 | AE26: =D26*I26/1000 -> 0 | AF26: =D26*J26/1000 -> 0 | AG26: =D26*F26*$AV$9/1000 -> 0 | AH26: =D26*G26*$AV$10/1000 -> 0 | AI26: =D26*H26*$AV$11/1000 -> 0 | AJ26: =D26*I26*$AV$12/1000 -> 0 | AK26: =D26*J26*$AV$13/1000 -> 0 | AL26: =D26*K26*M26/1000 -> 0 | AM26: =D26*L26*N26/1000 -> 0 | AO26: =D26*Q26/1000 -> 0 | AP26: =AO26/$AO$36 -> 0 | AQ26: =AO26/$AO$58 -> 0 | AR26: =AO26/$AO$59 -> 0
Q27: =(E27*$AV$8)+(F27*$AV$9)+(G27*$AV$10)+(H27*$AV$11)+(I27*$AV$12)+(J27*$AV$13)+(K27*M27)+(L27*N27) -> 0 | AA27: =D27*E27/1000 -> 0 | AB27: =D27*F27/1000 -> 0 | AC27: =D27*G27/1000 -> 0 | AD27: =D27*H27/1000 -> 0 | AE27: =D27*I27/1000 -> 0 | AF27: =D27*J27/1000 -> 0 | AG27: =D27*F27*$AV$9/1000 -> 0 | AH27: =D27*G27*$AV$10/1000 -> 0 | AI27: =D27*H27*$AV$11/1000 -> 0 | AJ27: =D27*I27*$AV$12/1000 -> 0 | AK27: =D27*J27*$AV$13/1000 -> 0 | AL27: =D27*K27*M27/1000 -> 0 | AM27: =D27*L27*N27/1000 -> 0 | AO27: =D27*Q27/1000 -> 0 | AP27: =AO27/$AO$36 -> 0 | AQ27: =AO27/$AO$58 -> 0 | AR27: =AO27/$AO$59 -> 0
... Q35: =(E35*$AV$8)+(F35*$AV$9)+(G35*$AV$10)+(H35*$AV$11)+(I35*$AV$12)+(J35*$AV$13)+(K35*M35)+(L35*N35) -> 0 | AA35: =D35*E35/1000 -> 0 | AB35: =D35*F35/1000 -> 0 | AC35: =D35*G35/1000 -> 0 | AD35: =D35*H35/1000 -> 0 | AE35: =D35*I35/1000 -> 0 | AF35: =D35*J35/1000 -> 0 | AG35: =D35*F35*$AV$9/1000 -> 0 | AH35: =D35*G35*$AV$10/1000 -> 0 | AI35: =D35*H35*$AV$11/1000 -> 0 | AJ35: =D35*I35*$AV$12/1000 -> 0 | AK35: =D35*J35*$AV$13/1000 -> 0 | AL35: =D35*K35*M35/1000 -> 0 | AM35: =D35*L35*N35/1000 -> 0 | AO35: =D35*Q35/1000 -> 0 | AP35: =AO35/$AO$36 -> 0 | AQ35: =AO35/$AO$58 -> 0 | AR35: =AO35/$AO$59 -> 0
AA36: =SUM(AA10:AA35) -> 1.6257348 | AB36: =SUM(AB10:AB35) -> 5.9251576e-05 | AC36: =SUM(AC10:AC35) -> 2.9936089e-06 | AD36: =SUM(AD10:AD35) -> 1.2449037e-05 | AE36: =SUM(AE10:AE35) -> 0 | AF36: =SUM(AF10:AF35) -> 0 | AG36: =SUM(AG10:AG35) -> 0.00013143611 | AH36: =SUM(AH10:AH35) -> 8.3821048e-05 | ... AP36: =SUM(AP10:AP35) -> 1
A37: รายงานแยก | AA37: =D37*E37*$AV$8/1000 -> 0 | AN37: =D37*O37*P37/1000 -> 0 | AO37: =D37*Q37/1000 -> 0 | AP37: =AO37/$AO$44 -> #DIV/0!
AA38: =D38*E38*$AV$8/1000 -> 0 | AN38: =D38*O38*P38/1000 -> 0 | AO38: =D38*Q38/1000 -> 0 | AP38: =AO38/$AO$44 -> #DIV/0!
AA39: =D39*E39*$AV$8/1000 -> 0 | AN39: =D39*O39*P39/1000 -> 0 | AO39: =D39*Q39/1000 -> 0 | AP39: =AO39/$AO$44 -> #DIV/0!
AA40: =D40*E40*$AV$8/1000 -> 0 | AN40: =D40*O40*P40/1000 -> 0 | AO40: =D40*Q40/1000 -> 0 | AP40: =AO40/$AO$44 -> #DIV/0!
AA41: =D41*E41*$AV$8/1000 -> 0 | AN41: =D41*O41*P41/1000 -> 0 | AO41: =D41*Q41/1000 -> 0 | AP41: =AO41/$AO$44 -> #DIV/0!
AA42: =D42*E42*$AV$8/1000 -> 0 | AN42: =D42*O42*P42/1000 -> 0 | AO42: =D42*Q42/1000 -> 0 | AP42: =AO42/$AO$44 -> #DIV/0!
AA43: =D43*E43*$AV$8/1000 -> 0 | AN43: =D43*O43*P43/1000 -> 0 | AO43: =D43*Q43/1000 -> 0 | AP43: =AO43/$AO$44 -> #DIV/0!
AO44: =SUM(AO37:AO43) -> 0 | AP44: =SUM(AP37:AP43) -> #DIV/0!
A45: ขอบเขต 2 | AO45: =D45*Q45/1000 -> 0 | AP45: =AO45/$AO$49 -> #DIV/0! | AQ45: =AO45/$AO$58 -> 0 | AR45: =AO45/$AO$59 -> 0
AO46: =D46*Q46/1000 -> 0 | AP46: =AO46/$AO$49 -> #DIV/0! | AQ46: =AO46/$AO$58 -> 0 | AR46: =AO46/$AO$59 -> 0
AO47: =D47*Q47/1000 -> 0 | AP47: =AO47/$AO$49 -> #DIV/0! | AQ47: =AO47/$AO$58 -> 0 | AR47: =AO47/$AO$59 -> 0
AP48: =AO48/$AO$49 -> #DIV/0! | AQ48: =AO48/$AO$58 -> 0 | AR48: =AO48/$AO$59 -> 0
AO49: =SUM(AO45:AO48) -> 0 | AP49: =SUM(AP45:AP48) -> #DIV/0!
...

Sheet Fr-04.2
B1: บัญชีรายการก๊าซเรือนกระจก ปีฐาน (base year) | AO1: TCFO_R_01 Version 04 : 21/2/2020
B3: ชื่อฟอร์ม | C3: บัญชีรายการก๊าซเรือนกระจก | H3: องค์กร | I3: ='Fr-01'!$B$6 -> บริษัท มัลติแบกซ์ จำกัด (มหาชน) | AB3: ปีฐาน | AE3: ='Fr-01'!H38 -> 1 มกราคม - 31 ธันวาคม 2566 | AO3: หน้าที่ | AR3: 5
B4: รหัสฟอร์ม | C4: Fr-04.2 | H4: ผู้จัดทำ | I4: ='Fr-01'!$G$4 -> บริษัท อีโค เซ็นทริก คอร์ปอเรชั่น จำกัด | AO4: วันที่ | AR4: ='Fr-04.1'!AR4 -> 45494
A6: ขอบเขต | B6: รายการ | C6: ค่า LCI | E6: GHG ที่ต้องรายงานตามข้อกำหนด | O6: GHG ที่อยู่นอกข้อกำหนด | Q6: Total (kgCO2e/หน่วย) | R6: ที่มา | Y6: Subsitute | Z6: แหล่งอ้างอิง | AA6: ผลคูณ (Ton GHG) | AG6: ผลคูณ (TonCO2e) | AO6: Total GHG | AP6: สัดส่วน (%) | AQ6: สัดส่วน (%) (SCOPE 1+2) | AR6: สัดส่วน (%) (SCOPE 1+2+3) | AS6: ระบุความแตกต่างระหว่างการรายงานปริมาณก๊าซเรือนกระจกของปีฐานและปีปัจจุบัน | AU6: GWP100
R7: 1st | T7: 2nd | X7: Other | AU7: ที่มา | AV7: IPCC, AR5
E8: ค่า EF (kg GHG/หน่วย) | M8: GWP100 | O8: ค่า EF (kg GHG/หน่วย) | P8: GWP100 | R8: Self collct | S8: Supplier | T8: TH LCI DB | U8: TGO EF | V8: Thai Res. | W8: Int. DB | AO8: (TonCO2e) | AU8: CO2 | AV8: 1
C9: หน่วย | D9: ปริมาณ | E9: CO2 | F9: Fossil CH4 | G9: CH4 | H9: N2O | I9: SF6 | J9: NF3 | K9: HFCs | L9: PFCs | M9: HFCs | N9: PFCs | AA9: CO2 | AB9: Fossil CH4 | AC9: CH4 | AD9: N2O | AE9: SF6 | AF9: NF3 | AG9: Fossil CH4 | AH9: CH4 | AI9: N2O | AJ9: SF6 | AK9: NF3 | AL9: HFCs | AM9: PFCs | AN9: Other | AU9: Fossil CH4 | AV9: 30
A10: ขอบเขต 1 | B10: ='Fr-04.1'!B10 -> Stationary combustion | Q10: =(E10*$AV$8)+(F10*$AV$9)+(G10*$AV$10)+(H10*$AV$11)+(I10*$AV$12)+(J10*$AV$13)+(K10*M10)+(L10*N10) -> 0 | AA10: =D10*E10/1000 -> 0 | AB10: =D10*F10/1000 -> 0 | AC10: =D10*G10/1000 -> 0 | AD10: =D10*H10/1000 -> 0 | AE10: =D10*I10/1000 -> 0 | AF10: =D10*J10/1000 -> 0 | AG10: =D10*F10*$AV$9/1000 -> 0 | AH10: =D10*G10*$AV$10/1000 -> 0 | AI10: =D10*H10*$AV$11/1000 -> 0 | AJ10: =D10*I10*$AV$12/1000 -> 0 | AK10: =D10*J10*$AV$13/1000 -> 0 | AL10: =D10*K10*M10/1000 -> 0 | AM10: =D10*L10*N10/1000 -> 0 | AO10: =D10*Q10/1000 -> 0 | AP10: =AO10/$AO$35 -> #REF! | AQ10: =AO10/$AO$57 -> #REF! | AR10: =AO10/$AO$58 -> #REF! | AU10: CH4 | AV10: 28
B11: ='Fr-04.1'!B11 -> น้ำมัน Diesel B7 (Fire Pump) | C11: ='Fr-04.1'!C11 -> L | D11: ='Fr-04.1'!D11 -> 502.2 | E11: ='EF TGO AR5'!D11 -> 2.698722 | F11: ='EF TGO AR5'!E11 -> 0.00010926 | G11: ='EF TGO AR5'!F11 -> 0 | H11: ='EF TGO AR5'!G11 -> 2.1852e-05 | Q11: =(E11*$AV$8)+(F11*$AV$9)+(G11*$AV$10)+(H11*$AV$11)+(I11*$AV$12)+(J11*$AV$13)+(K11*M11)+(L11*N11) -> 2.7077906 | U11: / | Z11: ='Fr-04.1'!Z11 -> TGO CFO EF (เมษายน 2565):Gas/Diesel oil | AA11: =D11*E11/1000 -> 1.3552982 | AB11: =D11*F11/1000 -> 5.4870372e-05 | AC11: =D11*G11/1000 -> 0 | AD11: =D11*H11/1000 -> 1.0974074e-05 | AE11: =D11*I11/1000 -> 0 | AF11: =D11*J11/1000 -> 0 | AG11: =D11*F11*$AV$9/1000 -> 0.0016461112 | AH11: =D11*G11*$AV$10/1000 -> 0 | AI11: =D11*H11*$AV$11/1000 -> 0.0029081297 | AJ11: =D11*I11*$AV$12/1000 -> 0 | AK11: =D11*J11*$AV$13/1000 -> 0 | AL11: =D11*K11*M11/1000 -> 0 | AM11: =D11*L11*N11/1000 -> 0 | AO11: =D11*Q11/1000 -> 1.3598524 | AP11: =AO11/$AO$35 -> #REF! | AQ11: =AO11/$AO$57 -> #REF! | AR11: =AO11/$AO$58 -> #REF! | AU11: N2O | AV11: 265
B12: ='Fr-04.1'!B12 -> น้ำมัน Gasohol 91/95 (เครื่องตัดหญ้า) | C12: ='Fr-04.1'!C12 -> L | D12: ='Fr-04.1'!D12 -> 46.3914 | E12: ='EF TGO AR5'!D17 -> 2.181564 | F12: ='EF TGO AR5'!E17 -> 9.444e-05 | G12: ='EF TGO AR5'!F17 -> 0 | H12: ='EF TGO AR5'!G17 -> 1.8888e-05 | Q12: =(E12*$AV$8)+(F12*$AV$9)+(G12*$AV$10)+(H12*$AV$11)+(I12*$AV$12)+(J12*$AV$13)+(K12*M12)+(L12*N12) -> 2.1894025 | U12: / | Z12: ='Fr-04.1'!Z12 -> TGO CFO EF (เมษายน 2565): Motor Gasoline | AA12: =D12*E12/1000 -> 0.10120581 | AB12: =D12*F12/1000 -> 4.3812038e-06 | AC12: =D12*G12/1000 -> 0 | AD12: =D12*H12/1000 -> 8.7624076e-07 | AE12: =D12*I12/1000 -> 0 | AF12: =D12*J12/1000 -> 0 | AG12: =D12*F12*$AV$9/1000 -> 0.00013143611 | AH12: =D12*G12*$AV$10/1000 -> 0 | AI12: =D12*H12*$AV$11/1000 -> 0.0002322038 | AJ12: =D12*I12*$AV$12/1000 -> 0 | AK12: =D12*J12*$AV$13/1000 -> 0 | AL12: =D12*K12*M12/1000 -> 0 | AM12: =D12*L12*N12/1000 -> 0 | AO12: =D12*Q12/1000 -> 0.10156945 | AP12: =AO12/$AO$35 -> #REF! | AQ12: =AO12/$AO$57 -> #REF! | AR12: =AO12/$AO$58 -> #REF! | AU12: SF6 | AV12: 23500
B13: ='Fr-04.1'!B13 -> Acetylene Gas (ซ่อมบำรุง) | C13: ='Fr-04.1'!C13 -> kg | D13: ='Fr-04.1'!D13 -> 50 | E13: ='EF (1)'!B9 -> 3.3846154 | Q13: =(E13*$AV$8)+(F13*$AV$9)+(G13*$AV$10)+(H13*$AV$11)+(I13*$AV$12)+(J13*$AV$13)+(K13*M13)+(L13*N13) -> 3.3846154 | X13: / | Z13: ='Fr-04.1'!Z13 -> EF (1) สมการเคมี | AA13: =D13*E13/1000 -> 0.16923077 | AB13: =D13*F13/1000 -> 0 | AC13: =D13*G13/1000 -> 0 | AD13: =D13*H13/1000 -> 0 | AE13: =D13*I13/1000 -> 0 | AF13: =D13*J13/1000 -> 0 | AG13: =D13*F13*$AV$9/1000 -> 0 | AH13: =D13*G13*$AV$10/1000 -> 0 | AI13: =D13*H13*$AV$11/1000 -> 0 | AJ13: =D13*I13*$AV$12/1000 -> 0 | AK13: =D13*J13*$AV$13/1000 -> 0 | AL13: =D13*K13*M13/1000 -> 0 | AM13: =D13*L13*N13/1000 -> 0 | AO13: =D13*Q13/1000 -> 0.16923077 | AP13: =AO13/$AO$35 -> #REF! | AQ13: =AO13/$AO$57 -> #REF! | AR13: =AO13/$AO$58 -> #REF! | AU13: NF3 | AV13: 16100
B14: ='Fr-04.1'!B14 -> Biodiesel (Stationary combustion) | C14: ='Fr-04.1'!C14 -> kg | D14: ='Fr-04.1'!D14 -> 32.886 | G14: ='EF (1)'!F28*'EF (1)'!D28 -> 8.1e-05 | H14: ='EF (1)'!F28*'EF (1)'!E28 -> 1.62e-05 | Q14: =(E14*$AV$8)+(F14*$AV$9)+(G14*$AV$10)+(H14*$AV$11)+(I14*$AV$12)+(J14*$AV$13)+(K14*M14)+(L14*N14) -> 0.006561 | W14: / | Z14: ='Fr-04.1'!Z14 -> IPCC, 2006 | AA14: =D14*E14/1000 -> 0 | AB14: =D14*F14/1000 -> 0 | AC14: =D14*G14/1000 -> 2.663766e-06 | AD14: =D14*H14/1000 -> 5.327532e-07 | AE14: =D14*I14/1000 -> 0 | AF14: =D14*J14/1000 -> 0 | AG14: =D14*F14*$AV$9/1000 -> 0 | AH14: =D14*G14*$AV$10/1000 -> 7.4585448e-05 | AI14: =D14*H14*$AV$11/1000 -> 0.0001411796 | AJ14: =D14*I14*$AV$12/1000 -> 0 | AK14: =D14*J14*$AV$13/1000 -> 0 | AL14: =D14*K14*M14/1000 -> 0 | AM14: =D14*L14*N14/1000 -> 0 | AO14: =D14*Q14/1000 -> 0.00021576505 | AP14: =AO14/$AO$35 -> #REF! | AQ14: =AO14/$AO$57 -> #REF! | AR14: =AO14/$AO$58 -> #REF!
B15: ='Fr-04.1'!B15 -> Biogasoline (Ethanol) (Stationary combustion) | C15: ='Fr-04.1'!C15 -> kg | D15: ='Fr-04.1'!D15 -> 4.072134 | G15: ='EF (1)'!F29*'EF (1)'!D29 -> 8.1e-05 | H15: ='EF (1)'!F29*'EF (1)'!E29 -> 1.62e-05 | Q15: =(E15*$AV$8)+(F15*$AV$9)+(G15*$AV$10)+(H15*$AV$11)+(I15*$AV$12)+(J15*$AV$13)+(K15*M15)+(L15*N15) -> 0.006561 | W15: / | Z15: ='Fr-04.1'!Z15 -> IPCC, 2006 | AA15: =D15*E15/1000 -> 0 | AB15: =D15*F15/1000 -> 0 | AC15: =D15*G15/1000 -> 3.2984285e-07 | AD15: =D15*H15/1000 -> 6.5968571e-08 | AE15: =D15*I15/1000 -> 0 | AF15: =D15*J15/1000 -> 0 | AG15: =D15*F15*$AV$9/1000 -> 0 | AH15: =D15*G15*$AV$10/1000 -> 9.2355999e-06 | AI15: =D15*H15*$AV$11/1000 -> 1.7481671e-05 | AJ15: =D15*I15*$AV$12/1000 -> 0 | AK15: =D15*J15*$AV$13/1000 -> 0 | AL15: =D15*K15*M15/1000 -> 0 | AM15: =D15*L15*N15/1000 -> 0 | AO15: =D15*Q15/1000 -> 2.6717271e-05 | AP15: =AO15/$AO$35 -> #REF! | AQ15: =AO15/$AO$57 -> #REF! | AR15: =AO15/$AO$58 -> #REF!
B16: ='Fr-04.1'!B16 -> 0 | Q16: =(E16*$AV$8)+(F16*$AV$9)+(G16*$AV$10)+(H16*$AV$11)+(I16*$AV$12)+(J16*$AV$13)+(K16*M16)+(L16*N16) -> 0 | Z16: ='Fr-04.1'!Z16 -> 0 | AA16: =D16*E16/1000 -> 0 | AB16: =D16*F16/1000 -> 0 | AC16: =D16*G16/1000 -> 0 | AD16: =D16*H16/1000 -> 0 | AE16: =D16*I16/1000 -> 0 | AF16: =D16*J16/1000 -> 0 | AG16: =D16*F16*$AV$9/1000 -> 0 | AH16: =D16*G16*$AV$10/1000 -> 0 | AI16: =D16*H16*$AV$11/1000 -> 0 | AJ16: =D16*I16*$AV$12/1000 -> 0 | AK16: =D16*J16*$AV$13/1000 -> 0 | AL16: =D16*K16*M16/1000 -> 0 | AM16: =D16*L16*N16/1000 -> 0 | AO16: =D16*Q16/1000 -> 0 | AP16: =AO16/$AO$35 -> #REF! | AQ16: =AO16/$AO$57 -> #REF! | AR16: =AO16/$AO$58 -> #REF!
B17: ='Fr-04.1'!B17 -> 0 | C17: ='Fr-04.1'!C17 -> 0 | D17: ='Fr-04.1'!D17 -> 0 | E17: ='EF TGO AR5'!D32 -> 2.698722 | F17: ='EF TGO AR5'!E32 -> 0.000142038 | G17: ='EF TGO AR5'!F32 -> 0 | H17: ='EF TGO AR5'!G32 -> 0.000142038 | Q17: =(E17*$AV$8)+(F17*$AV$9)+(G17*$AV$10)+(H17*$AV$11)+(I17*$AV$12)+(J17*$AV$13)+(K17*M17)+(L17*N17) -> 2.7406232 | U17: / | Z17: ='Fr-04.1'!Z17 -> 0 | AA17: =D17*E17/1000 -> 0 | AB17: =D17*F17/1000 -> 0 | AC17: =D17*G17/1000 -> 0 | AD17: =D17*H17/1000 -> 0 | AE17: =D17*I17/1000 -> 0 | AF17: =D17*J17/1000 -> 0 | AG17: =D17*F17*$AV$9/1000 -> 0 | AH17: =D17*G17*$AV$10/1000 -> 0 | AI17: =D17*H17*$AV$11/1000 -> 0 | AJ17: =D17*I17*$AV$12/1000 -> 0 | AK17: =D17*J17*$AV$13/1000 -> 0 | AL17: =D17*K17*M17/1000 -> 0 | AM17: =D17*L17*N17/1000 -> 0 | AO17: =D17*Q17/1000 -> 0 | AP17: =AO17/$AO$35 -> #REF! | AQ17: =AO17/$AO$57 -> #REF! | AR17: =AO17/$AO$58 -> #REF!
B18: ='Fr-04.1'!B18 -> 0 | C18: ='Fr-04.1'!C18 -> 0 | D18: ='Fr-04.1'!D18 -> 0 | E18: ='EF TGO AR5'!D32 -> 2.698722 | F18: ='EF TGO AR5'!E32 -> 0.000142038 | G18: ='EF TGO AR5'!F32 -> 0 | H18: ='EF TGO AR5'!G32 -> 0.000142038 | Q18: =(E18*$AV$8)+(F18*$AV$9)+(G18*$AV$10)+(H18*$AV$11)+(I18*$AV$12)+(J18*$AV$13)+(K18*M18)+(L18*N18) -> 2.7406232 | U18: / | Z18: ='Fr-04.1'!Z18 -> 0 | AA18: =D18*E18/1000 -> 0 | AB18: =D18*F18/1000 -> 0 | AC18: =D18*G18/1000 -> 0 | AD18: =D18*H18/1000 -> 0 | AE18: =D18*I18/1000 -> 0 | AF18: =D18*J18/1000 -> 0 | AG18: =D18*F18*$AV$9/1000 -> 0 | AH18: =D18*G18*$AV$10/1000 -> 0 | AI18: =D18*H18*$AV$11/1000 -> 0 | AJ18: =D18*I18*$AV$12/1000 -> 0 | AK18: =D18*J18*$AV$13/1000 -> 0 | AL18: =D18*K18*M18/1000 -> 0 | AM18: =D18*L18*N18/1000 -> 0 | AO18: =D18*Q18/1000 -> 0 | AP18: =AO18/$AO$35 -> #REF! | AQ18: =AO18/$AO$57 -> #REF! | AR18: =AO18/$AO$58 -> #REF!
B19: ='Fr-04.1'!B19 -> 0 | C19: ='Fr-04.1'!C19 -> 0 | D19: ='Fr-04.1'!D19 -> 0 | E19: ='EF TGO AR5'!D30 -> 2.181564 | F19: ='EF TGO AR5'!E30 -> 0.000787 | G19: ='EF TGO AR5'!F30 -> 0 | H19: ='EF TGO AR5'!G30 -> 0.00025184 | Q19: =(E19*$AV$8)+(F19*$AV$9)+(G19*$AV$10)+(H19*$AV$11)+(I19*$AV$12)+(J19*$AV$13)+(K19*M19)+(L19*N19) -> 2.2719116 | U19: / | Z19: ='Fr-04.1'!Z19 -> 0 | AA19: =D19*E19/1000 -> 0 | AB19: =D19*F19/1000 -> 0 | AC19: =D19*G19/1000 -> 0 | AD19: =D19*H19/1000 -> 0 | AE19: =D19*I19/1000 -> 0 | AF19: =D19*J19/1000 -> 0 | AG19: =D19*F19*$AV$9/1000 -> 0 | AH19: =D19*G19*$AV$10/1000 -> 0 | AI19: =D19*H19*$AV$11/1000 -> 0 | AJ19: =D19*I19*$AV$12/1000 -> 0 | AK19: =D19*J19*$AV$13/1000 -> 0 | AL19: =D19*K19*M19/1000 -> 0 | AM19: =D19*L19*N19/1000 -> 0 | AO19: =D19*Q19/1000 -> 0 | AP19: =AO19/$AO$35 -> #REF! | AQ19: =AO19/$AO$57 -> #REF! | AR19: =AO19/$AO$58 -> #REF!
B20: ='Fr-04.1'!B20 -> 0 | C20: ='Fr-04.1'!C20 -> 0 | D20: ='Fr-04.1'!D20 -> 0 | E20: ='EF TGO AR5'!D30 -> 2.181564 | F20: ='EF TGO AR5'!E30 -> 0.000787 | G20: ='EF TGO AR5'!F30 -> 0 | H20: ='EF TGO AR5'!G30 -> 0.00025184 | Q20: =(E20*$AV$8)+(F20*$AV$9)+(G20*$AV$10)+(H20*$AV$11)+(I20*$AV$12)+(J20*$AV$13)+(K20*M20)+(L20*N20) -> 2.2719116 | W20: / | Z20: ='Fr-04.1'!Z20 -> 0 | AA20: =D20*E20/1000 -> 0 | AB20: =D20*F20/1000 -> 0 | AC20: =D20*G20/1000 -> 0 | AD20: =D20*H20/1000 -> 0 | AE20: =D20*I20/1000 -> 0 | AF20: =D20*J20/1000 -> 0 | AG20: =D20*F20*$AV$9/1000 -> 0 | AH20: =D20*G20*$AV$10/1000 -> 0 | AI20: =D20*H20*$AV$11/1000 -> 0 | AJ20: =D20*I20*$AV$12/1000 -> 0 | AK20: =D20*J20*$AV$13/1000 -> 0 | AL20: =D20*K20*M20/1000 -> 0 | AM20: =D20*L20*N20/1000 -> 0 | AO20: =D20*Q20/1000 -> 0 | AP20: =AO20/$AO$35 -> #REF! | AQ20: =AO20/$AO$57 -> #REF! | AR20: =AO20/$AO$58 -> #REF!
B21: ='Fr-04.1'!B21 -> 0 | C21: ='Fr-04.1'!C21 -> 0 | D21: ='Fr-04.1'!D21 -> 0 | E21: ='EF TGO AR5'!D40 -> 2.698722 | F21: ='EF TGO AR5'!E40 -> 0.000151143 | G21: ='EF TGO AR5'!F40 -> 0 | H21: ='EF TGO AR5'!G40 -> 0.001041612 | Q21: =(E21*$AV$8)+(F21*$AV$9)+(G21*$AV$10)+(H21*$AV$11)+(I21*$AV$12)+(J21*$AV$13)+(K21*M21)+(L21*N21) -> 2.9792835 | W21: / | Z21: ='Fr-04.1'!Z21 -> 0 | AA21: =D21*E21/1000 -> 0 | AB21: =D21*F21/1000 -> 0 | AC21: =D21*G21/1000 -> 0 | AD21: =D21*H21/1000 -> 0 | AE21: =D21*I21/1000 -> 0 | AF21: =D21*J21/1000 -> 0 | AG21: =D21*F21*$AV$9/1000 -> 0 | AH21: =D21*G21*$AV$10/1000 -> 0 | AI21: =D21*H21*$AV$11/1000 -> 0 | AJ21: =D21*I21*$AV$12/1000 -> 0 | AK21: =D21*J21*$AV$13/1000 -> 0 | AL21: =D21*K21*M21/1000 -> 0 | AM21: =D21*L21*N21/1000 -> 0 | AO21: =D21*Q21/1000 -> 0 | AP21: =AO21/$AO$35 -> #REF! | AQ21: =AO21/$AO$57 -> #REF! | AR21: =AO21/$AO$58 -> #REF!
B22: ='Fr-04.1'!B22 -> 0 | C22: ='Fr-04.1'!C22 -> 0 | D22: ='Fr-04.1'!D22 -> 0 | G22: ='EF (1)'!F30*'EF (1)'!D30 -> 0.00011205 | H22: ='EF (1)'!F30*'EF (1)'!E30 -> 0.0007722 | Q22: =(E22*$AV$8)+(F22*$AV$9)+(G22*$AV$10)+(H22*$AV$11)+(I22*$AV$12)+(J22*$AV$13)+(K22*M22)+(L22*N22) -> 0.2077704 | W22: / | Z22: ='Fr-04.1'!Z22 -> 0 | AA22: =D22*E22/1000 -> 0 | AB22: =D22*F22/1000 -> 0 | AC22: =D22*G22/1000 -> 0 | AD22: =D22*H22/1000 -> 0 | AE22: =D22*I22/1000 -> 0 | AF22: =D22*J22/1000 -> 0 | AG22: =D22*F22*$AV$9/1000 -> 0 | AH22: =D22*G22*$AV$10/1000 -> 0 | AI22: =D22*H22*$AV$11/1000 -> 0 | AJ22: =D22*I22*$AV$12/1000 -> 0 | AK22: =D22*J22*$AV$13/1000 -> 0 | AL22: =D22*K22*M22/1000 -> 0 | AM22: =D22*L22*N22/1000 -> 0 | AO22: =D22*Q22/1000 -> 0 | AP22: =AO22/$AO$35 -> #REF! | AQ22: =AO22/$AO$57 -> #REF! | AR22: =AO22/$AO$58 -> #REF!
B23: ='Fr-04.1'!B23 -> 0 | C23: ='Fr-04.1'!C23 -> 0 | D23: ='Fr-04.1'!D23 -> 0 | G23: ='EF (1)'!F32*'EF (1)'!D32 -> 0.00011205 | H23: ='EF (1)'!F32*'EF (1)'!E32 -> 0.0007722 | Q23: =(E23*$AV$8)+(F23*$AV$9)+(G23*$AV$10)+(H23*$AV$11)+(I23*$AV$12)+(J23*$AV$13)+(K23*M23)+(L23*N23) -> 0.2077704 | W23: / | Z23: ='Fr-04.1'!Z23 -> 0 | AA23: =D23*E23/1000 -> 0 | AB23: =D23*F23/1000 -> 0 | AC23: =D23*G23/1000 -> 0 | AD23: =D23*H23/1000 -> 0 | AE23: =D23*I23/1000 -> 0 | AF23: =D23*J23/1000 -> 0 | AG23: =D23*F23*$AV$9/1000 -> 0 | AH23: =D23*G23*$AV$10/1000 -> 0 | AI23: =D23*H23*$AV$11/1000 -> 0 | AJ23: =D23*I23*$AV$12/1000 -> 0 | AK23: =D23*J23*$AV$13/1000 -> 0 | AL23: =D23*K23*M23/1000 -> 0 | AM23: =D23*L23*N23/1000 -> 0 | AO23: =D23*Q23/1000 -> 0 | AP23: =AO23/$AO$35 -> #REF! | AQ23: =AO23/$AO$57 -> #REF! | AR23: =AO23/$AO$58 -> #REF!
B24: ='Fr-04.1'!B24 -> 0 | C24: ='Fr-04.1'!C24 -> 0 | D24: ='Fr-04.1'!D24 -> 0 | G24: ='EF (1)'!F31*'EF (1)'!D31 -> 0.00702 | H24: ='EF (1)'!F31*'EF (1)'!E31 -> 0.001107 | Q24: =(E24*$AV$8)+(F24*$AV$9)+(G24*$AV$10)+(H24*$AV$11)+(I24*$AV$12)+(J24*$AV$13)+(K24*M24)+(L24*N24) -> 0.489915 | W24: / | Z24: ='Fr-04.1'!Z24 -> 0 | AA24: =D24*E24/1000 -> 0 | AB24: =D24*F24/1000 -> 0 | AC24: =D24*G24/1000 -> 0 | AD24: =D24*H24/1000 -> 0 | AE24: =D24*I24/1000 -> 0 | AF24: =D24*J24/1000 -> 0 | AG24: =D24*F24*$AV$9/1000 -> 0 | AH24: =D24*G24*$AV$10/1000 -> 0 | AI24: =D24*H24*$AV$11/1000 -> 0 | AJ24: =D24*I24*$AV$12/1000 -> 0 | AK24: =D24*J24*$AV$13/1000 -> 0 | AL24: =D24*K24*M24/1000 -> 0 | AM24: =D24*L24*N24/1000 -> 0 | AO24: =D24*Q24/1000 -> 0 | AP24: =AO24/$AO$35 -> #REF! | AQ24: =AO24/$AO$57 -> #REF! | AR24: =AO24/$AO$58 -> #REF!
B25: ='Fr-04.1'!B25 -> 0 | Q25: =(E25*$AV$8)+(F25*$AV$9)+(G25*$AV$10)+(H25*$AV$11)+(I25*$AV$12)+(J25*$AV$13)+(K25*M25)+(L25*N25) -> 0 | Z25: ='Fr-04.1'!Z25 -> 0 | AA25: =D25*E25/1000 -> 0 | AB25: =D25*F25/1000 -> 0 | AC25: =D25*G25/1000 -> 0 | AD25: =D25*H25/1000 -> 0 | AE25: =D25*I25/1000 -> 0 | AF25: =D25*J25/1000 -> 0 | AG25: =D25*F25*$AV$9/1000 -> 0 | AH25: =D25*G25*$AV$10/1000 -> 0 | AI25: =D25*H25*$AV$11/1000 -> 0 | AJ25: =D25*I25*$AV$12/1000 -> 0 | AK25: =D25*J25*$AV$13/1000 -> 0 | AL25: =D25*K25*M25/1000 -> 0 | AM25: =D25*L25*N25/1000 -> 0 | AO25: =D25*Q25/1000 -> 0 | AP25: =AO25/$AO$35 -> #REF! | AQ25: =AO25/$AO$57 -> #REF! | AR25: =AO25/$AO$58 -> #REF!
B26: ='Fr-04.1'!B26 -> 0 | C26: ='Fr-04.1'!C26 -> 0 | D26: ='Fr-04.1'!D26 -> 0 | K26: 1 | M26: ='EF TGO AR5'!H56 -> 677 | Q26: =(E26*$AV$8)+(F26*$AV$9)+(G26*$AV$10)+(H26*$AV$11)+(I26*$AV$12)+(J26*$AV$13)+(K26*M26)+(L26*N26) -> 677 | W26: / | Z26: ='Fr-04.1'!Z26 -> 0 | AA26: =D26*E26/1000 -> 0 | AB26: =D26*F26/1000 -> 0 | AC26: =D26*G26/1000 -> 0 | AD26: =D26*H26/1000 -> 0 | AE26: =D26*I26/1000 -> 0 | AF26: =D26*J26/1000 -> 0 | AG26: =D26*F26*$AV$9/1000 -> 0 | AH26: =D26*G26*$AV$10/1000 -> 0 | AI26: =D26*H26*$AV$11/1000 -> 0 | AJ26: =D26*I26*$AV$12/1000 -> 0 | AK26: =D26*J26*$AV$13/1000 -> 0 | AL26: =D26*K26*M26/1000 -> 0 | AM26: =D26*L26*N26/1000 -> 0 | AO26: =D26*Q26/1000 -> 0 | AP26: =AO26/$AO$35 -> #REF! | AQ26: =AO26/$AO$57 -> #REF! | AR26: =AO26/$AO$58 -> #REF!
B27: ='Fr-04.1'!B27 -> 0 | C27: ='Fr-04.1'!C27 -> 0 | D27: ='Fr-04.1'!D27 -> 0 | K27: 1 | M27: ='EF (1)'!E16 -> 1923.5 | Q27: =(E27*$AV$8)+(F27*$AV$9)+(G27*$AV$10)+(H27*$AV$11)+(I27*$AV$12)+(J27*$AV$13)+(K27*M27)+(L27*N27) -> 1923.5 | W27: / | Z27: ='Fr-04.1'!Z27 -> 0 | AA27: =D27*E27/1000 -> 0 | AB27: =D27*F27/1000 -> 0 | AC27: =D27*G27/1000 -> 0 | AD27: =D27*H27/1000 -> 0 | AE27: =D27*I27/1000 -> 0 | AF27: =D27*J27/1000 -> 0 | AG27: =D27*F27*$AV$9/1000 -> 0 | AH27: =D27*G27*$AV$10/1000 -> 0 | AI27: =D27*H27*$AV$11/1000 -> 0 | AJ27: =D27*I27*$AV$12/1000 -> 0 | AK27: =D27*J27*$AV$13/1000 -> 0 | AL27: =D27*K27*M27/1000 -> 0 | AM27: =D27*L27*N27/1000 -> 0 | AO27: =D27*Q27/1000 -> 0 | AP27: =AO27/$AO$35 -> #REF! | AQ27: =AO27/$AO$57 -> #REF! | AR27: =AO27/$AO$58 -> #REF!
B28: ='Fr-04.1'!B28 -> 0 | C28: ='Fr-04.1'!C28 -> 0 | D28: ='Fr-04.1'!D28 -> 0 | K28: 1 | M28: ='EF TGO AR5'!H59 -> 1300 | Q28: =(E28*$AV$8)+(F28*$AV$9)+(G28*$AV$10)+(H28*$AV$11)+(I28*$AV$12)+(J28*$AV$13)+(K28*M28)+(L28*N28) -> 1300 | W28: / | Z28: ='Fr-04.1'!Z28 -> 0 | AA28: =D28*E28/1000 -> 0 | AB28: =D28*F28/1000 -> 0 | AC28: =D28*G28/1000 -> 0 | AD28: =D28*H28/1000 -> 0 | AE28: =D28*I28/1000 -> 0 | AF28: =D28*J28/1000 -> 0 | AG28: =D28*F28*$AV$9/1000 -> 0 | AH28: =D28*G28*$AV$10/1000 -> 0 | AI28: =D28*H28*$AV$11/1000 -> 0 | AJ28: =D28*I28*$AV$12/1000 -> 0 | AK28: =D28*J28*$AV$13/1000 -> 0 | AL28: =D28*K28*M28/1000 -> 0 | AM28: =D28*L28*N28/1000 -> 0 | AO28: =D28*Q28/1000 -> 0 | AP28: =AO28/$AO$35 -> #REF! | AQ28: =AO28/$AO$57 -> #REF! | AR28: =AO28/$AO$58 -> #REF!
B29: ='Fr-04.1'!B29 -> 0 | C29: ='Fr-04.1'!C29 -> 0 | D29: ='Fr-04.1'!D29 -> 0 | K29: 1 | M29: ='EF (1)'!E19 -> 1624.21 | Q29: =(E29*$AV$8)+(F29*$AV$9)+(G29*$AV$10)+(H29*$AV$11)+(I29*$AV$12)+(J29*$AV$13)+(K29*M29)+(L29*N29) -> 1624.21 | W29: / | Z29: ='Fr-04.1'!Z29 -> 0 | AA29: =D29*E29/1000 -> 0 | AB29: =D29*F29/1000 -> 0 | AC29: =D29*G29/1000 -> 0 | AD29: =D29*H29/1000 -> 0 | AE29: =D29*I29/1000 -> 0 | AF29: =D29*J29/1000 -> 0 | AG29: =D29*F29*$AV$9/1000 -> 0 | AH29: =D29*G29*$AV$10/1000 -> 0 | AI29: =D29*H29*$AV$11/1000 -> 0 | AJ29: =D29*I29*$AV$12/1000 -> 0 | AK29: =D29*J29*$AV$13/1000 -> 0 | AL29: =D29*K29*M29/1000 -> 0 | AM29: =D29*L29*N29/1000 -> 0 | AO29: =D29*Q29/1000 -> 0 | AP29: =AO29/$AO$35 -> #REF! | AQ29: =AO29/$AO$57 -> #REF! | AR29: =AO29/$AO$58 -> #REF!
B30: ='Fr-04.1'!B30 -> 0 | C30: ='Fr-04.1'!C30 -> 0 | D30: ='Fr-04.1'!D30 -> 0 | E30: 1 | Q30: =(E30*$AV$8)+(F30*$AV$9)+(G30*$AV$10)+(H30*$AV$11)+(I30*$AV$12)+(J30*$AV$13)+(K30*M30)+(L30*N30) -> 1 | W30: / | Z30: ='Fr-04.1'!Z30 -> 0 | AA30: =D30*E30/1000 -> 0 | AB30: =D30*F30/1000 -> 0 | AC30: =D30*G30/1000 -> 0 | AD30: =D30*H30/1000 -> 0 | AE30: =D30*I30/1000 -> 0 | AF30: =D30*J30/1000 -> 0 | AG30: =D30*F30*$AV$9/1000 -> 0 | AH30: =D30*G30*$AV$10/1000 -> 0 | AI30: =D30*H30*$AV$11/1000 -> 0 | AJ30: =D30*I30*$AV$12/1000 -> 0 | AK30: =D30*J30*$AV$13/1000 -> 0 | AL30: =D30*K30*M30/1000 -> 0 | AM30: =D30*L30*N30/1000 -> 0 | AO30: =D30*Q30/1000 -> 0 | AP30: =AO30/$AO$35 -> #REF! | AQ30: =AO30/$AO$57 -> #REF! | AR30: =AO30/$AO$58 -> #REF!
B31: ='Fr-04.1'!B31 -> 0 | C31: ='Fr-04.1'!C31 -> 0 | D31: ='Fr-04.1'!D31 -> 0 | G31: 1 | Q31: =(E31*$AV$8)+(F31*$AV$9)+(G31*$AV$10)+(H31*$AV$11)+(I31*$AV$12)+(J31*$AV$13)+(K31*M31)+(L31*N31) -> 28 | W31: / | Z31: ='Fr-04.1'!Z31 -> 0 | AA31: =D31*E31/1000 -> 0 | AB31: =D31*F31/1000 -> 0 | AC31: =D31*G31/1000 -> 0 | AD31: =D31*H31/1000 -> 0 | AE31: =D31*I31/1000 -> 0 | AF31: =D31*J31/1000 -> 0 | AG31: =D31*F31*$AV$9/1000 -> 0 | AH31: =D31*G31*$AV$10/1000 -> 0 | AI31: =D31*H31*$AV$11/1000 -> 0 | AJ31: =D31*I31*$AV$12/1000 -> 0 | AK31: =D31*J31*$AV$13/1000 -> 0 | AL31: =D31*K31*M31/1000 -> 0 | AM31: =D31*L31*N31/1000 -> 0 | AO31: =D31*Q31/1000 -> 0 | AP31: =AO31/$AO$35 -> #REF! | AQ31: =AO31/$AO$57 -> #REF! | AR31: =AO31/$AO$58 -> #REF!
B32: ='Fr-04.1'!B32 -> 0 | C32: ='Fr-04.1'!C32 -> 0 | D32: ='Fr-04.1'!D32 -> 0 | H32: =#REF! -> #REF! | Q32: =(E32*$AV$8)+(F32*$AV$9)+(G32*$AV$10)+(H32*$AV$11)+(I32*$AV$12)+(J32*$AV$13)+(K32*M32)+(L32*N32) -> #REF! | W32: / | Z32: ='Fr-04.1'!Z32 -> 0 | AA32: =D32*E32/1000 -> 0 | AB32: =D32*F32/1000 -> 0 | AC32: =D32*G32/1000 -> 0 | AD32: =D32*H32/1000 -> #REF! | AE32: =D32*I32/1000 -> 0 | AF32: =D32*J32/1000 -> 0 | AG32: =D32*F32*$AV$9/1000 -> 0 | AH32: =D32*G32*$AV$10/1000 -> 0 | AI32: =D32*H32*$AV$11/1000 -> #REF! | AJ32: =D32*I32*$AV$12/1000 -> 0 | AK32: =D32*J32*$AV$13/1000 -> 0 | AL32: =D32*K32*M32/1000 -> 0 | AM32: =D32*L32*N32/1000 -> 0 | AO32: =D32*Q32/1000 -> #REF! | AP32: =AO32/$AO$35 -> #REF! | AQ32: =AO32/$AO$57 -> #REF! | AR32: =AO32/$AO$58 -> #REF!
Q33: =(E33*$AV$8)+(F33*$AV$9)+(G33*$AV$10)+(H33*$AV$11)+(I33*$AV$12)+(J33*$AV$13)+(K33*M33)+(L33*N33) -> 0 | AA33: =D33*E33/1000 -> 0 | AB33: =D33*F33/1000 -> 0 | AC33: =D33*G33/1000 -> 0 | AD33: =D33*H33/1000 -> 0 | AE33: =D33*I33/1000 -> 0 | AF33: =D33*J33/1000 -> 0 | AG33: =D33*F33*$AV$9/1000 -> 0 | AH33: =D33*G33*$AV$10/1000 -> 0 | AI33: =D33*H33*$AV$11/1000 -> 0 | AJ33: =D33*I33*$AV$12/1000 -> 0 | AK33: =D33*J33*$AV$13/1000 -> 0 | AL33: =D33*K33*M33/1000 -> 0 | AM33: =D33*L33*N33/1000 -> 0 | AO33: =D33*Q33/1000 -> 0 | AP33: =AO33/$AO$35 -> #REF! | AQ33: =AO33/$AO$57 -> #REF! | AR33: =AO33/$AO$58 -> #REF!
Q34: =(E34*$AV$8)+(F34*$AV$9)+(G34*$AV$10)+(H34*$AV$11)+(I34*$AV$12)+(J34*$AV$13)+(K34*M34)+(L34*N34) -> 0 | AA34: =D34*E34/1000 -> 0 | AB34: =D34*F34/1000 -> 0 | AC34: =D34*G34/1000 -> 0 | AD34: =D34*H34/1000 -> 0 | AE34: =D34*I34/1000 -> 0 | AF34: =D34*J34/1000 -> 0 | AG34: =D34*F34*$AV$9/1000 -> 0 | AH34: =D34*G34*$AV$10/1000 -> 0 | AI34: =D34*H34*$AV$11/1000 -> 0 | AJ34: =D34*I34*$AV$12/1000 -> 0 | AK34: =D34*J34*$AV$13/1000 -> 0 | AL34: =D34*K34*M34/1000 -> 0 | AM34: =D34*L34*N34/1000 -> 0 | AO34: =D34*Q34/1000 -> 0 | AP34: =AO34/$AO$35 -> #REF! | AQ34: =AO34/$AO$57 -> #REF! | AR34: =AO34/$AO$58 -> #REF!
AA35: =SUM(AA10:AA34) -> 1.6257348 | AB35: =SUM(AB10:AB34) -> 5.9251576e-05 | AC35: =SUM(AC10:AC34) -> 2.9936089e-06 | AD35: =SUM(AD10:AD34) -> #REF! | AE35: =SUM(AE10:AE34) -> 0 | AF35: =SUM(AF10:AF34) -> 0 | AG35: =SUM(AG10:AG34) -> 0.0017775473 | AH35: =SUM(AH10:AH34) -> 8.3821048e-05 | ... AP35: =SUM(AP10:AP34) -> #REF!
A36: การปล่อย GHG โดยตรงที่ทำการรายงานแยก | B36: ='Fr-04.1'!B37 -> 0 | C36: ='Fr-04.1'!C37 -> 0 | D36: ='Fr-04.1'!D37 -> 0 | O36: 1 | P36: ='EF TGO AR5'!H55 -> 1760 | Q36: =(E36*$AV$8)+(O36*P36) -> 1760 | W36: / | Z36: ='Fr-04.1'!Z37 -> 0 | AA36: =D36*E36*$AV$8/1000 -> 0 | AN36: =D36*O36*P36/1000 -> 0 | AO36: =D36*Q36/1000 -> 0 | AP36: =AO36/$AO$43 -> #DIV/0!
B37: ='Fr-04.1'!B38 -> 0 | C37: ='Fr-04.1'!C38 -> 0 | D37: ='Fr-04.1'!D38 -> 0 | O37: 1 | P37: ='EF (1)'!E13 -> 79 | Q37: =(E37*$AV$8)+(O37*P37) -> 79 | W37: / | Z37: ='Fr-04.1'!Z38 -> 0 | AA37: =D37*E37*$AV$8/1000 -> 0 | AN37: =D37*O37*P37/1000 -> 0 | AO37: =D37*Q37/1000 -> 0 | AP37: =AO37/$AO$43 -> #DIV/0!
B38: ='Fr-04.1'!B39 -> 0 | C38: ='Fr-04.1'!C39 -> 0 | D38: ='Fr-04.1'!D39 -> 0 | E38: ='EF (1)'!F28*'EF (1)'!C28 -> 1.9116 | Q38: =(E38*$AV$8)+(O38*P38) -> 1.9116 | W38: / | Z38: ='Fr-04.1'!Z39 -> 0 | AA38: =D38*E38*$AV$8/1000 -> 0 | AN38: =D38*O38*P38/1000 -> 0 | AO38: =D38*Q38/1000 -> 0 | AP38: =AO38/$AO$43 -> #DIV/0!
B39: ='Fr-04.1'!B40 -> 0 | C39: ='Fr-04.1'!C40 -> 0 | D39: ='Fr-04.1'!D40 -> 0 | E39: ='EF (1)'!F29*'EF (1)'!C29 -> 1.9116 | Q39: =(E39*$AV$8)+(O39*P39) -> 1.9116 | W39: / | Z39: ='Fr-04.1'!Z40 -> 0 | AA39: =D39*E39*$AV$8/1000 -> 0 | AN39: =D39*O39*P39/1000 -> 0 | AO39: =D39*Q39/1000 -> 0 | AP39: =AO39/$AO$43 -> #DIV/0!
B40: ='Fr-04.1'!B41 -> 0 | C40: ='Fr-04.1'!C41 -> 0 | D40: ='Fr-04.1'!D41 -> 0 | E40: ='EF (1)'!C34 -> 2.8368489 | Q40: =(E40*$AV$8)+(O40*P40) -> 2.8368489 | W40: / | Z40: ='Fr-04.1'!Z41 -> 0 | AA40: =D40*E40*$AV$8/1000 -> 0 | AN40: =D40*O40*P40/1000 -> 0 | AO40: =D40*Q40/1000 -> 0 | AP40: =AO40/$AO$43 -> #DIV/0!
B41: ='Fr-04.1'!B42 -> 0 | C41: ='Fr-04.1'!C42 -> 0 | D41: ='Fr-04.1'!D42 -> 0 | E41: ='EF (1)'!C36 -> 2.8368489 | Q41: =(E41*$AV$8)+(O41*P41) -> 2.8368489 | W41: / | Z41: ='Fr-04.1'!Z42 -> 0 | AA41: =D41*E41*$AV$8/1000 -> 0 | AN41: =D41*O41*P41/1000 -> 0 | AO41: =D41*Q41/1000 -> 0 | AP41: =AO41/$AO$43 -> #DIV/0!
B42: ='Fr-04.1'!B43 -> 0 | C42: ='Fr-04.1'!C43 -> 0 | D42: ='Fr-04.1'!D43 -> 0 | E42: ='EF (1)'!C35 -> 1.9227722 | Q42: =(E42*$AV$8)+(O42*P42) -> 1.9227722 | W42: / | Z42: ='Fr-04.1'!Z43 -> 0 | AA42: =D42*E42*$AV$8/1000 -> 0 | AN42: =D42*O42*P42/1000 -> 0 | AO42: =D42*Q42/1000 -> 0 | AP42: =AO42/$AO$43 -> #DIV/0!
...

Sheet Fr-05
B1: สรุปการปล่อยก๊าซเรือนกระจกขององค์กร | I1: TCFO_R_01 Version 04 : 21/2/2020
B3: ชื่อฟอร์ม | C3: บัญชีรายการก๊าซเรือนกระจก | E3: องค์กร | F3: ='Fr-01'!$B$6 -> บริษัท มัลติแบกซ์ จำกัด (มหาชน) | I3: หน้าที่ | J3: 6
B4: รหัสฟอร์ม | C4: Fr-05 | E4: ผู้จัดทำ | F4: ='Fr-01'!$G$4 -> บริษัท อีโค เซ็นทริก คอร์ปอเรชั่น จำกัด | I4: วันที่จัดทำ | J4: ='Fr-01'!J4 -> 243820
A5: ปีปัจจุบัน | B5: ='Fr-01'!H36 -> 1 มกราคม - 31 ธันวาคม 2566
B6: ขอบเขต | C6: การปล่อยก๊าซเรือนกระจกขององค์กร | D6: สัดส่วนเมื่อเทียบขอบเขต 1 และ 2 | E6: สัดส่วนเมื่อเทียบขอบเขต 1, 2 และ 3
B10: ประเภท 1 | C10: =ROUNDUP('Fr-04.1'!AO36,0) -> 2 | D10: =C10/C$14% -> 100 | E10: =C10/SUM(C10:C12)% -> 100
B11: ประเภท 2 | C11: =ROUNDUP('Fr-04.1'!AO49,0) -> 0 | D11: =C11/C$14% -> 0 | E11: =C11/SUM(C10:C12)% -> 0
B12: ประเภท 3 | C12: =ROUNDUP('Fr-04.1'!AO57,0) -> 0 | E12: =C12/SUM(C10:C12)% -> 0
B13: อื่น ๆ | C13: =ROUNDUP('Fr-04.1'!AO44,0) -> 0
B14: รวม Scope 1 & 2 | C14: =SUM(C10:C11) -> 2 | D14: =SUM(D10:D11) -> 100
B15: รวม Scope 1 & 2 & 3 | C15: =SUM(C10:C12) -> 2 | E15: =SUM(E10:E12) -> 100
B17: Carbon intensity (Scope 1+2) | D17: =C14/'Fr-01'!H37 -> 0.0002086376 | E17: TonCO2eq/ | F17: ='Fr-01'!J37 -> ตัน
B18: Carbon intensity (Scope 1+2+3) | D18: =C15/'Fr-01'!H37 -> 0.0002086376 | E18: TonCO2eq/ | F18: ='Fr-01'!J37 -> ตัน
A20: ปีฐาน | B20: ='Fr-01'!H38 -> 1 มกราคม - 31 ธันวาคม 2566
B22: ขอบเขต | C22: การปล่อยก๊าซเรือนกระจกขององค์กร | D22: สัดส่วนเมื่อเทียบขอบเขต 1 และ 2 | E22: สัดส่วนเมื่อเทียบขอบเขต 1, 2 และ 3 | G22: เปรียบเทียบ
B26: ประเภท 1 | C26: =ROUNDUP('Fr-04.2'!AO35,0) -> #REF! | D26: =C26/C$14% -> #REF! | E26: =C26/SUM(C26:C28)% -> #REF!
B27: ประเภท 2 | C27: =ROUNDUP('Fr-04.2'!AO48,0) -> 0 | D27: =C27/C$14% -> 0 | E27: =C27/SUM(C26:C28)% -> #REF!
B28: ประเภท 3 | C28: =ROUNDUP('Fr-04.2'!AO56,0) -> 0 | E28: =C28/SUM(C26:C28)% -> #REF!
B29: อื่น ๆ | C29: =ROUNDUP('Fr-04.2'!AO43,0) -> 0
B30: รวม Scope 1 & 2 | C30: =SUM(C26:C27) -> #REF! | D30: =SUM(D26:D27) -> #REF!
B31: รวม Scope 1 & 2 & 3 | C31: =SUM(C26:C28) -> #REF! | E31: =SUM(E26:E28) -> #REF!
B33: Carbon intensity (Scope 1+2) | D33: =C30/'Fr-01'!H39 -> #REF! | E33: TonCO2eq/ | F33: =F17 -> ตัน
B34: Carbon intensity (Scope 1+2+3) | D34: =C31/'Fr-01'!H39 -> #REF! | E34: TonCO2eq/ | F34: =F18 -> ตัน
A37: จัดทำโดย | B37: ='Fr-04.2'!B59 -> บริษัท อีโค เซ็นทริก คอร์ปอเรชั่น จำกัด | G37: เสร็จสิ้นวันที่ | H37: ='Fr-03.1'!K35 -> 243829

Sheet EF TGO AR4
B2: ชื่อ | C2: Units | D2: EMISSION FACTORS | H2: แหล่งอ้างอิงข้อมูล | J2: GWP100
D3: CO2 | E3: CH4 | F3: N2O | G3: Total | J3: ที่มา | K3: IPCC, AR4 | L3: IPCC, AR5
D4: [kg CO2/unit] | E4: [kg CH4/unit] | F4: [kg N2O/unit] | G4: [kg CO2eq/unit] | J4: CO2 | K4: 1 | L4: 1
A5: Stationary Combustion | J5: CH4 | K5: 25 | L5: 28
B6: Natural gas | C6: scf | D6: =D48*$G$48*10^-6 -> 0.057222 | E6: =E48*$G$48*10^-6 -> 1.02e-06 | F6: =F48*$G$48*10^-6 -> 1.02e-07 | G6: =D6+(E6*$K$5)+(F6*$K$6) -> 0.057277896 | H6: IPCC Vol.2 table 2.2, DEDE | J6: N2O | K6: 298 | L6: 265
B7: Natural gas | C7: MJ | D7: =D48/1000000 -> 0.0561 | E7: =E48/1000000 -> 1e-06 | F7: =F48/1000000 -> 1e-07 | G7: =D7+(E7*$K$5)+(F7*$K$6) -> 0.0561548 | H7: IPCC Vol.2 table 2.2, DEDE | J7: SF6 | K7: 22800 | L7: 23500
B8: Lignite | C8: kg | D8: =D49*$G$49*10^-6 -> 1.05747 | E8: =E49*$G$49*10^-6 -> 1.047e-05 | F8: =F49*$G$49*10^-6 -> 1.5705e-05 | G8: =D8+(E8*$K$5)+(F8*$K$6) -> 1.0624118 | H8: IPCC Vol.2 table 2.2, DEDE | J8: NF3 | K8: 17200 | L8: 16100
B9: Fuel oil A | C9: litre | D9: =D50*$G$50*10^-6 -> 3.2096984 | E9: =E50*$G$50*10^-6 -> 0.00012440692 | F9: =F50*$G$50*10^-6 -> 2.4881383e-05 | G9: =D9+(E9*$K$5)+(F9*$K$6) -> 3.2202233 | H9: IPCC Vol.2 table 2.2, PTT | J9: PASS: 12345678
B10: Fuel oil C | C10: litre | D10: =D51*$G$51*10^-6 -> 3.2353401 | E10: =E51*$G$51*10^-6 -> 0.00012540078 | F10: =F51*$G$51*10^-6 -> 2.5080156e-05 | G10: =D10+(E10*$K$5)+(F10*$K$6) -> 3.245949 | H10: IPCC Vol.2 table 2.2, PTT
B11: Gas/Diesel oil | C11: litre | D11: =D52*$G$52*10^-6 -> 2.698722 | E11: =E52*$G$52*10^-6 -> 0.00010926 | F11: =F52*$G$52*10^-6 -> 2.1852e-05 | G11: =D11+(E11*$K$5)+(F11*$K$6) -> 2.7079654 | H11: IPCC Vol.2 table 2.2, DEDE
B12: Anthracite | C12: kg | D12: =D53*$G$53*10^-6 -> 3.08662 | E12: =E53*$G$53*10^-6 -> 3.14e-05 | F12: =F53*$G$53*10^-6 -> 4.71e-05 | G12: =D12+(E12*$K$5)+(F12*$K$6) -> 3.1014408 | H12: IPCC Vol.2 table 2.2, DEDE
B13: Sub-bituminous coal | C13: kg | D13: =D54*$G$54*10^-6 -> 2.534157 | E13: =E54*$G$54*10^-6 -> 2.637e-05 | F13: =F54*$G$54*10^-6 -> 3.9555e-05 | G13: =D13+(E13*$K$5)+(F13*$K$6) -> 2.5466036 | H13: IPCC Vol.2 table 2.2, DEDE
B14: Jet Kerosene | C14: litre | D14: =D55*$G$55*10^-6 -> 2.468895 | E14: =E55*$G$55*10^-6 -> 0.00010359 | F14: =F55*$G$55*10^-6 -> 2.0718e-05 | G14: =D14+(E14*$K$5)+(F14*$K$6) -> 2.4776587 | H14: IPCC Vol.2 table 2.2, DEDE
B15: LPG | C15: litre | D15: =D56*$G$56*10^-6 -> 1.679722 | E15: =E56*$G$56*10^-6 -> 2.662e-05 | F15: =F56*$G$56*10^-6 -> 2.662e-06 | G15: =D15+(E15*$K$5)+(F15*$K$6) -> 1.6811808 | H15: IPCC Vol.2 table 2.2, DEDE
B16: LPG | C16: kg | D16: =D15/0.54 -> 3.1105963 | E16: =E15/0.54 -> 4.9296296e-05 | F16: =F15/0.54 -> 4.9296296e-06 | G16: =D16+(E16*$K$5)+(F16*$K$6) -> 3.1132977 | H16: IPCC Vol.2 table 2.2, DEDE LPG 1 litre = 0.54 kg
B17: Motor gasoline | C17: litre | D17: =D57*$G$57*10^-6 -> 2.181564 | E17: =E57*$G$57*10^-6 -> 9.444e-05 | F17: =F57*$G$57*10^-6 -> 1.8888e-05 | G17: =D17+(E17*$K$5)+(F17*$K$6) -> 2.1895536 | H17: IPCC Vol.2 table 2.2, DEDE
A19: Mobile Combustion (On road)
B20: Motor Gasoline - uncontrolled | C20: litre | D20: =D63*$G$63*10^-6 -> 2.181564 | E20: =E63*$G$63*10^-6 -> 0.00103884 | F20: =F63*$G$63*10^-6 -> 0.000100736 | G20: =D20+(E20*$K$5)+(F20*$K$6) -> 2.2375543 | H20: IPCC Vol.2 table 3.2.1, 3.2.2, DEDE
B21: Motor Gasoline - oxydation catalyst | C21: litre | D21: =D64*$G$64*10^-6 -> 2.181564 | E21: =E64*$G$64*10^-6 -> 0.000787 | F21: =F64*$G$64*10^-6 -> 0.00025184 | G21: =D21+(E21*$K$5)+(F21*$K$6) -> 2.2762873 | H21: IPCC Vol.2 table 3.2.1, 3.2.2, DEDE
B22: Motor Gasoline - low mileage light duty vihicle vintage 1995 or later | C22: litre | D22: =D65*$G$65*10^-6 -> 2.181564 | E22: =E65*$G$65*10^-6 -> 0.000119624 | F22: =F65*$G$65*10^-6 -> 0.000179436 | G22: =D22+(E22*$K$5)+(F22*$K$6) -> 2.2380265 | H22: IPCC Vol.2 table 3.2.1, 3.2.2, DEDE
B23: Gas/ Diesel Oil | C23: litre | D23: =D66*$G$66*10^-6 -> 2.698722 | E23: =E66*$G$66*10^-6 -> 0.000142038 | F23: =F66*$G$66*10^-6 -> 0.000142038 | G23: =D23+(E23*$K$5)+(F23*$K$6) -> 2.7446003 | H23: IPCC Vol.2 table 3.2.1, 3.2.2, DEDE
B24: Compressed Natural Gas | C24: kg | D24: =D67*$G$67*10^-6 -> 2.12619 | E24: =E67*$G$67*10^-6 -> 0.0034868 | F24: =F67*$G$67*10^-6 -> 0.0001137 | G24: =D24+(E24*$K$5)+(F24*$K$6) -> 2.2472426 | H24: IPCC Vol.2 table 3.2.1, 3.2.2, PTT
B25: Liquified Petroleum Gas | C25: litre | D25: =D68*$G$68*10^-6 -> 1.679722 | E25: =E68*$G$68*10^-6 -> 0.00165044 | F25: =F68*$G$68*10^-6 -> 5.324e-06 | G25: =D25+(E25*$K$5)+(F25*$K$6) -> 1.7225696 | H25: IPCC Vol.2 table 3.2.1, 3.2.2, DEDE
B26: Liquified Petroleum Gas | C26: kg | D26: =D25/0.54 -> 3.1105963 | E26: =E25/0.54 -> 0.0030563704 | F26: =F25/0.54 -> 9.8592593e-06 | G26: =D26+(E26*$K$5)+(F26*$K$6) -> 3.1899436 | H26: IPCC Vol.2 table 3.2.1, 3.2.2, DEDE LPG 1 litre = 0.54 kg
A27: Mobile Combustion (Off road)
B28: Diesel
B29: - Agriculture | C29: litre | D29: =D75*$G$75/(10^6) -> 2.698722 | E29: =E75*$G$75/(10^6) -> 0.000151143 | F29: =F75*$G$75/(10^6) -> 0.001041612 | G29: =D29+(E29*$K$5)+(F29*$K$6) -> 3.012901 | H29: IPCC Vol.2 table 3.3.1, DEDE
B30: - Forestry | C30: litre | D30: =D76*$G$76/(10^6) -> 2.698722 | E30: =E76*$G$76/(10^6) -> 0.000151143 | F30: =F76*$G$76/(10^6) -> 0.001041612 | G30: =D30+(E30*$K$5)+(F30*$K$6) -> 3.012901 | H30: IPCC Vol.2 table 3.3.1, DEDE
B31: - Industry | C31: litre | D31: =D77*$G$77/(10^6) -> 2.698722 | E31: =E77*$G$77/(10^6) -> 0.000151143 | F31: =F77*$G$77/(10^6) -> 0.001041612 | G31: =D31+(E31*$K$5)+(F31*$K$6) -> 3.012901 | H31: IPCC Vol.2 table 3.3.1, DEDE
B32: - Household | C32: litre | D32: =D78*$G$78/(10^6) -> 2.698722 | E32: =E78*$G$78/(10^6) -> 0.000151143 | F32: =F78*$G$78/(10^6) -> 0.001041612 | G32: =D32+(E32*$K$5)+(F32*$K$6) -> 3.012901 | H32: IPCC Vol.2 table 3.3.1, DEDE
B33: Motor Gasoline - 4 stroke
B34: - Agriculture | C34: litre | D34: =D80*$G$80/(10^6) -> 2.181564 | E34: =E80*$G$80/(10^6) -> 0.0025184 | F34: =F80*$G$80/(10^6) -> 6.296e-05 | G34: =D34+(E34*$K$5)+(F34*$K$6) -> 2.2632861 | H34: IPCC Vol.2 table 3.3.1, DEDE
