Workbook

Sheet Fr-01
B1: รายละเอียดขององค์กร | I1: TCFO_R_01 Version 04 : 21/2/2020
B3: ชื่อฟอร์ม | C3: บัญชีรายการก๊าซเรือนกระจก | E3: องค์กร | G3: =B6 -> ชื่อองค์กรที่ขอขึ้นทะเบียน | I3: หน้าที่ | J3: 1
B4: รหัสฟอร์ม | C4: Fr-01 | E4: ผู้จัดทำ | I4: วันที่จัดทำ
B6: ชื่อองค์กรที่ขอขึ้นทะเบียน
A8: รูปขององค์กร | F8: ขอบเขตขององค์กร
F9: ประเภท 1
F18: ประเภท 2
F21: ประเภท 3
F22: ระยะเวลาเก็บข้อมูล | H22: ระบุปีที่เก็บข้อมูล เช่น ม.ค.63-ธ.ค.63
F23: ผลผลิต | H23: 0 | J23: ระบุหน่วย
F24: ปีฐาน | H24: ระบุปีฐาน เช่น ม.ค.61-ธ.ค.61
F25: ผลผลิตปีฐาน | H25: 0 | J25: =J23 -> ระบุหน่วย
F26: ข้อมูลองค์กร
F27: 1
F28: 2
F29: 3
F30: 4
F31: 5
F32: สถานที่ติดต่อ
F33: วันที่ขอขึ้นทะเบียน
A35: การแสดงเครื่องหมาย | F35: กราฟแท่งแสดงการปล่อย GHG แต่ละขอบเขต

Sheet Fr-02
B1: แผนภาพองค์กร | L1: TCFO_R_01 Version 04 : 21/2/2020
B3: ชื่อฟอร์ม | C3: บัญชีรายการก๊าซเรือนกระจก | F3: องค์กร | G3: ='Fr-01'!$B$6 -> ชื่อองค์กรที่ขอขึ้นทะเบียน | L3: หน้าที่ | M3: 2
B4: รหัสฟอร์ม | C4: Fr-02 | F4: ผู้จัดทำ | G4: ='Fr-01'!$G$4 -> 0 | L4: วันที่

Sheet Fr-03.1
B1: แผนภาพแสดงโครงสร้างขององค์กรและหน้าที่ความรับผิดชอบ | L1: TCFO_R_01 Version 04 : 21/2/2020
B3: ชื่อฟอร์ม | C3: บัญชีรายการก๊าซเรือนกระจก | F3: องค์กร | G3: ='Fr-01'!$B$6 -> ชื่อองค์กรที่ขอขึ้นทะเบียน | L3: หน้าที่ | M3: 3
B4: รหัสฟอร์ม | C4: Fr-03.1 | F4: ผู้จัดทำ | G4: ='Fr-01'!$G$4 -> 0 | L4: วันที่
A26: จัดทำโดย | J26: เสร็จสิ้นวันที่ | K26: 0

Sheet Fr-03.2
B1: ประเมินความมีนัยสำคัญของการปล่อยก๊าซเรือนกระจกทางอ้อม (SCOPE 3) | O1: TCFO_R_01 Version 04 : 21/2/2020
B3: ชื่อฟอร์ม | C3: ประเมินความมีนัยสำคัญ Scope3 | E3: องค์กร | F3: ='Fr-01'!G3 -> ชื่อองค์กรที่ขอขึ้นทะเบียน | O3: หน้าที่ | P3: 3
B4: รหัสฟอร์ม | C4: Fr-03.2 | E4: ผู้จัดทำ | F4: ='Fr-01'!G4 -> 0 | O4: วันที่
A6: คำอธิบาย | B6: องค์กรจะต้องคัดเลือกแหล่งปล่อยก๊าซเรือนกระจกทางอ้อม (Scope 3) โดยกำหนดเกณฑ์ในการประเมินความมีนัยสำคัญของการปล่อยก๊าซเรือนกระจกทางอ้อม (Scope 3)
A8: ประเด็นที่ต้องพิจารณา | C8: คำอธิบาย
A9: Source of GHG | C9: องค์กรมีแหล่งปล่อยก๊าซเรือนกระจกนี้หรือไม่
A10: ขนาด (Magnitude or Size) | C10: เป็นกิจกรรมการปล่อยหรือดูดกลับก๊าซเรือนกระจกทางอ้อมซึ่งถูกสันนิษฐานว่ามีปริมาณการปล่อยหรือดูดกลับก๊าซเรือนกระจกในปริมาณมากอย่างมีนัยสำคัญ
A11: ระดับของแรงจูงใจ (Level of influence (Reduction of potential)) | C11: เป็นกิจกรรมการปล่อยหรือดูดกลับก๊าซเรือนกระจกที่องค์กรมีความสามารถในการตรวจติดตามและลดปริมาณการปล่อยหรือดูดกลับก๊าซเรือนกระจกจากกิจกรรมนั้น(ตัวอย่างเช่นเป็นกิจกรรมที่เกี่ยวข้องกับการประเมินประสิทธิภาพพลังงาน การออกแบบเชิงนิเวศเศรษฐกิจ, เกี่ยวข้องกับข้อตกลงที่มีกับลูกค้า, เกี่ยวข้องกับข้อกำหนดขอบเขตงานจากผู้ว่าจ้าง)
A12: ความเสี่ยง หรือ โอกาส Risk or opportunity | C12: เป็นกิจกรรมการปล่อยหรือดูดกลับก๊าซเรือนกระจกทางอ้อมซึ่งมีส่วนทำให้องค์กรได้รับความเสี่ยง (ตัวอย่างของความเสี่ยงที่มีความเชื่อมโยงกับการเปลี่ยนแปลงสภาพภูมิอากาศ เช่น ความเสี่ยงทางด้านการเงิน, ความเสี่ยงทางด้านกฎระเบียบข้อบังคับ, ความเสี่ยงตลอดห่วงโซ่อุปทาน, ความเสี่ยงเกี่ยวกับสินค้าและลูกค้า, ความเสี่ยงเกี่ยวกับการดำเนินคดี และ ความเสี่ยงด้านชื่อเสียง) หรือได้รับโอกาสต่างๆ ทางธุรกิจ (เช่น การเข้าสู่ช่องทางตลาดใหม่ การเข้าสู่ระบบธุรกิจในรูปแบบใหม่)
A13: Sector Guidance | C13: เป็นกิจกรรมการปล่อยก๊าซเรือนกระจกที่ถูกถือว่ามีนัยสำคัญสำหรับอุตสาหกรรมที่กำลังพิจารณา ตามที่กำหนดไว้ในคู่มือหรือแนวทางที่เฉพาะเจาะจงสำหรับอุตสาหกรรมนั้น
A14: Outsourcing | C14: เป็นกิจกรรมการปล่อยและดูดกลับก๊าซเรือนกระจกทางอ้อมที่เกิดจากการจัดจ้างบุคคลหรือหน่วยงานภายนอกเข้ามาดำเนินกิจกรรมที่ถือว่า เป็นกิจกรรมหลักในการดำเนินธุรกิจขององค์กร
A15: Employee engagement | C15: เป็นกิจกรรมการปล่อยก๊าซเรือนกระจกทางอ้อมที่สามารถส่งเสริมให้เกิดการกระตุ้นให้พนักงานมีส่วนร่วมในการลดการปล่อยก๊าซเรือนกระจก ผ่านการลดการใช้พลังงาน หรือการทำงานร่วมกันเป็นทีมภายใต้หลักคิดที่เกี่ยวข้องกับการเปลี่ยนแปลงสภาพภูมิอากาศ (เช่น การสร้างแรงจูงใจในการอนุรักษ์พลังงาน, การเดินทาง โดยใช้รถร่วมกัน, การประเมินราคาคาร์บอนภายในองค์กร เป็นต้น)
A16: ที่มา : หัวข้อที่ 12 ข้อกำหนดในการคำนวณและรายงานคาร์บอนฟุตพริ้นท์ขององค์กร พิมพ์ครั้งที่ 7 (ฉบับปรับปรุงครั้งที่ 5, มกราคม 2564)
A18: No | B18: Category | C18: Source of GHG | D18: Magnitude | E18: Level of influence (Reduction of potential) | F18: opportunity or Risk | H18: Sector Guidance | K18: Outsourcing | N18: Employee engagement | O18: Remark
A19: 1 | B19: Purchased goods and services | C19: P
A20: 2 | B20: Capital goods | C20: P
A21: 3 | B21: Fuel- and energy related activities | C21: P
A22: 4 | B22: Upstream transportation and distribution | C22: P
A23: 5 | B23: Waste generated in operations | C23: P
A24: 6 | B24: Business travel | C24: P
A25: 7 | B25: Employee commuting | C25: P
A26: 8 | B26: Upstream leased assets | C26: P
A27: 9 | B27: Downstream transportation and distribution | C27: P
A28: 10 | B28: Processing of sold products | C28: P
A29: 11 | B29: Use of sold products | C29: P
A30: 12 | B30: End-of-life treatment of sold products | C30: P
... A33: 15 | B33: Investments | C33: P
A35: อธิบาย หลักเกณฑ์ในการประเมินความมีนัยสำคัญ

Sheet Fr-04.1
B1: บัญชีรายการก๊าซเรือนกระจก | AO1: TCFO_R_01 Version 04 : 21/2/2020
B3: ชื่อฟอร์ม | C3: บัญชีรายการก๊าซเรือนกระจก | H3: องค์กร | I3: ='Fr-01'!$B$6 -> ชื่อองค์กรที่ขอขึ้นทะเบียน | AB3: ปีที่เก็บข้อมูล | AE3: ='Fr-01'!H22 -> ระบุปีที่เก็บข้อมูล เช่น ม.ค.63-ธ.ค.63 | AO3: หน้าที่ | AR3: 4
B4: รหัสฟอร์ม | C4: Fr-04.1 | H4: ผู้จัดทำ | I4: ='Fr-01'!$G$4 -> 0 | AO4: วันที่
A6: ขอบเขต | B6: รายการ | C6: ค่า LCI | E6: GHG ที่ต้องรายงานตามข้อกำหนด | O6: GHG ที่อยู่นอกข้อกำหนด | Q6: Total (kgCO2e/หน่วย) | R6: ที่มา | Y6: Subsitute | Z6: แหล่งอ้างอิง | AA6: ผลคูณ (Ton GHG) | AG6: ผลคูณ (TonCO2e) | AO6: Total GHG | AP6: สัดส่วน (%) | AQ6: สัดส่วน (%) (SCOPE 1+2) | AR6: สัดส่วน (%) (SCOPE 1+2+3) | AS6: คำอธิบายเพิ่มเติม | AU6: GWP100
R7: 1st | T7: 2nd | X7: Other | AU7: ที่มา | AV7: IPCC, AR5
E8: ค่า EF (kg GHG/หน่วย) | M8: GWP100 | O8: ค่า EF (kg GHG/หน่วย) | P8: GWP100 | R8: Self collct | S8: Supplier | T8: TH LCI DB | U8: TGO EF | V8: Thai Res. | W8: Int. DB | AO8: (TonCO2e) | AU8: CO2 | AV8: 1
C9: หน่วย | D9: ปริมาณ | E9: CO2 | F9: Fossil CH4 | G9: CH4 | H9: N2O | I9: SF6 | J9: NF3 | K9: HFCs | L9: PFCs | M9: HFCs | N9: PFCs | AA9: CO2 | AB9: Fossil CH4 | AC9: CH4 | AD9: N2O | AE9: SF6 | AF9: NF3 | AG9: Fossil CH4 | AH9: CH4 | AI9: N2O | AJ9: SF6 | AK9: NF3 | AL9: HFCs | AM9: PFCs | AN9: Other | AU9: Fossil CH4 | AV9: 30
A10: ขอบเขต 1 | Q10: =(E10*$AV$8)+(F10*$AV$9)+(G10*$AV$10)+(H10*$AV$11)+(I10*$AV$12)+(J10*$AV$13)+(K10*M10)+(L10*N10) -> 0 | AA10: =D10*E10/1000 -> 0 | AB10: =D10*F10/1000 -> 0 | AC10: =D10*G10/1000 -> 0 | AD10: =D10*H10/1000 -> 0 | AE10: =D10*I10/1000 -> 0 | AF10: =D10*J10/1000 -> 0 | AG10: =D10*F10*$AV$9/1000 -> 0 | AH10: =D10*G10*$AV$10/1000 -> 0 | AI10: =D10*H10*$AV$11/1000 -> 0 | AJ10: =D10*I10*$AV$12/1000 -> 0 | AK10: =D10*J10*$AV$13/1000 -> 0 | AL10: =D10*K10*M10/1000 -> 0 | AM10: =D10*L10*N10/1000 -> 0 | AO10: =D10*Q10/1000 -> 0 | AP10: =AO10/$AO$24 -> #VALUE! | AQ10: =AO10/$AO$44 -> #VALUE! | AR10: =AO10/$AO$45 -> #VALUE! | AU10: CH4 | AV10: 28
B11: =IF($AP11="","",_xlfn.XLOOKUP($AP11,tblScope11Stationary[RowId],tblScope11Stationary[ItemLabel],"")) | C11: =IF($AP11="","",_xlfn.XLOOKUP($AP11,tblScope11Stationary[RowId],tblScope11Stationary[Unit],"")) | D11: =IF($AP11="","",SUM(INDEX(tblScope11Stationary[[M1]:[M12]],MATCH($AP11,tblScope11Stationary[RowId],0),0))) | Q11: =(E11*$AV$8)+(F11*$AV$9)+(G11*$AV$10)+(H11*$AV$11)+(I11*$AV$12)+(J11*$AV$13)+(K11*M11)+(L11*N11) -> 0 | AA11: =D11*E11/1000 -> #VALUE! | AB11: =D11*F11/1000 -> #VALUE! | AC11: =D11*G11/1000 -> #VALUE! | AD11: =D11*H11/1000 -> #VALUE! | AE11: =D11*I11/1000 -> #VALUE! | AF11: =D11*J11/1000 -> #VALUE! | AG11: =D11*F11*$AV$9/1000 -> #VALUE! | AH11: =D11*G11*$AV$10/1000 -> #VALUE! | AI11: =D11*H11*$AV$11/1000 -> #VALUE! | AJ11: =D11*I11*$AV$12/1000 -> #VALUE! | AK11: =D11*J11*$AV$13/1000 -> #VALUE! | AL11: =D11*K11*M11/1000 -> #VALUE! | AM11: =D11*L11*N11/1000 -> #VALUE! | AO11: =D11*Q11/1000 -> #VALUE! | AP11: =IFERROR(INDEX(_xlfn._xlws.FILTER(tblFR041Sel[RowId],tblFR041Sel[Include]=1),ROWS($AP$11:AP11)),"") | AQ11: =AO11/$AO$44 -> #VALUE! | AR11: =AO11/$AO$45 -> #VALUE! | AU11: N2O | AV11: 265
B12: =IF($AP12="","",_xlfn.XLOOKUP($AP12,tblScope11Stationary[RowId],tblScope11Stationary[ItemLabel],"")) | C12: =IF($AP12="","",_xlfn.XLOOKUP($AP12,tblScope11Stationary[RowId],tblScope11Stationary[Unit],"")) | D12: =IF($AP12="","",SUM(INDEX(tblScope11Stationary[[M1]:[M12]],MATCH($AP12,tblScope11Stationary[RowId],0),0))) | Q12: =(E12*$AV$8)+(F12*$AV$9)+(G12*$AV$10)+(H12*$AV$11)+(I12*$AV$12)+(J12*$AV$13)+(K12*M12)+(L12*N12) -> 0 | AA12: =D12*E12/1000 -> #VALUE! | AB12: =D12*F12/1000 -> #VALUE! | AC12: =D12*G12/1000 -> #VALUE! | AD12: =D12*H12/1000 -> #VALUE! | AE12: =D12*I12/1000 -> #VALUE! | AF12: =D12*J12/1000 -> #VALUE! | AG12: =D12*F12*$AV$9/1000 -> #VALUE! | AH12: =D12*G12*$AV$10/1000 -> #VALUE! | AI12: =D12*H12*$AV$11/1000 -> #VALUE! | AJ12: =D12*I12*$AV$12/1000 -> #VALUE! | AK12: =D12*J12*$AV$13/1000 -> #VALUE! | AL12: =D12*K12*M12/1000 -> #VALUE! | AM12: =D12*L12*N12/1000 -> #VALUE! | AO12: =D12*Q12/1000 -> #VALUE! | AP12: =IFERROR(INDEX(_xlfn._xlws.FILTER(tblFR041Sel[RowId],tblFR041Sel[Include]=1),ROWS($AP$11:AP12)),"") | AQ12: =AO12/$AO$44 -> #VALUE! | AR12: =AO12/$AO$45 -> #VALUE! | AU12: SF6 | AV12: 23500
B13: =IF($AP13="","",_xlfn.XLOOKUP($AP13,tblScope11Stationary[RowId],tblScope11Stationary[ItemLabel],"")) | C13: =IF($AP13="","",_xlfn.XLOOKUP($AP13,tblScope11Stationary[RowId],tblScope11Stationary[Unit],"")) | D13: =IF($AP13="","",SUM(INDEX(tblScope11Stationary[[M1]:[M12]],MATCH($AP13,tblScope11Stationary[RowId],0),0))) | Q13: =(E13*$AV$8)+(F13*$AV$9)+(G13*$AV$10)+(H13*$AV$11)+(I13*$AV$12)+(J13*$AV$13)+(K13*M13)+(L13*N13) -> 0 | AA13: =D13*E13/1000 -> #VALUE! | AB13: =D13*F13/1000 -> #VALUE! | AC13: =D13*G13/1000 -> #VALUE! | AD13: =D13*H13/1000 -> #VALUE! | AE13: =D13*I13/1000 -> #VALUE! | AF13: =D13*J13/1000 -> #VALUE! | AG13: =D13*F13*$AV$9/1000 -> #VALUE! | AH13: =D13*G13*$AV$10/1000 -> #VALUE! | AI13: =D13*H13*$AV$11/1000 -> #VALUE! | AJ13: =D13*I13*$AV$12/1000 -> #VALUE! | AK13: =D13*J13*$AV$13/1000 -> #VALUE! | AL13: =D13*K13*M13/1000 -> #VALUE! | AM13: =D13*L13*N13/1000 -> #VALUE! | AO13: =D13*Q13/1000 -> #VALUE! | AP13: =IFERROR(INDEX(_xlfn._xlws.FILTER(tblFR041Sel[RowId],tblFR041Sel[Include]=1),ROWS($AP$11:AP13)),"") | AQ13: =AO13/$AO$44 -> #VALUE! | AR13: =AO13/$AO$45 -> #VALUE! | AU13: NF3 | AV13: 16100
B14: =IF($AP14="","",_xlfn.XLOOKUP($AP14,tblScope11Stationary[RowId],tblScope11Stationary[ItemLabel],"")) | C14: =IF($AP14="","",_xlfn.XLOOKUP($AP14,tblScope11Stationary[RowId],tblScope11Stationary[Unit],"")) | D14: =IF($AP14="","",SUM(INDEX(tblScope11Stationary[[M1]:[M12]],MATCH($AP14,tblScope11Stationary[RowId],0),0))) | Q14: =(E14*$AV$8)+(F14*$AV$9)+(G14*$AV$10)+(H14*$AV$11)+(I14*$AV$12)+(J14*$AV$13)+(K14*M14)+(L14*N14) -> 0 | AA14: =D14*E14/1000 -> #VALUE! | AB14: =D14*F14/1000 -> #VALUE! | AC14: =D14*G14/1000 -> #VALUE! | AD14: =D14*H14/1000 -> #VALUE! | AE14: =D14*I14/1000 -> #VALUE! | AF14: =D14*J14/1000 -> #VALUE! | AG14: =D14*F14*$AV$9/1000 -> #VALUE! | AH14: =D14*G14*$AV$10/1000 -> #VALUE! | AI14: =D14*H14*$AV$11/1000 -> #VALUE! | AJ14: =D14*I14*$AV$12/1000 -> #VALUE! | AK14: =D14*J14*$AV$13/1000 -> #VALUE! | AL14: =D14*K14*M14/1000 -> #VALUE! | AM14: =D14*L14*N14/1000 -> #VALUE! | AO14: =D14*Q14/1000 -> #VALUE! | AP14: =IFERROR(INDEX(_xlfn._xlws.FILTER(tblFR041Sel[RowId],tblFR041Sel[Include]=1),ROWS($AP$11:AP14)),"") | AQ14: =AO14/$AO$44 -> #VALUE! | AR14: =AO14/$AO$45 -> #VALUE!
B15: =IF($AP15="","",_xlfn.XLOOKUP($AP15,tblScope11Stationary[RowId],tblScope11Stationary[ItemLabel],"")) | C15: =IF($AP15="","",_xlfn.XLOOKUP($AP15,tblScope11Stationary[RowId],tblScope11Stationary[Unit],"")) | D15: =IF($AP15="","",SUM(INDEX(tblScope11Stationary[[M1]:[M12]],MATCH($AP15,tblScope11Stationary[RowId],0),0))) | Q15: =(E15*$AV$8)+(F15*$AV$9)+(G15*$AV$10)+(H15*$AV$11)+(I15*$AV$12)+(J15*$AV$13)+(K15*M15)+(L15*N15) -> 0 | AA15: =D15*E15/1000 -> #VALUE! | AB15: =D15*F15/1000 -> #VALUE! | AC15: =D15*G15/1000 -> #VALUE! | AD15: =D15*H15/1000 -> #VALUE! | AE15: =D15*I15/1000 -> #VALUE! | AF15: =D15*J15/1000 -> #VALUE! | AG15: =D15*F15*$AV$9/1000 -> #VALUE! | AH15: =D15*G15*$AV$10/1000 -> #VALUE! | AI15: =D15*H15*$AV$11/1000 -> #VALUE! | AJ15: =D15*I15*$AV$12/1000 -> #VALUE! | AK15: =D15*J15*$AV$13/1000 -> #VALUE! | AL15: =D15*K15*M15/1000 -> #VALUE! | AM15: =D15*L15*N15/1000 -> #VALUE! | AO15: =D15*Q15/1000 -> #VALUE! | AP15: =IFERROR(INDEX(_xlfn._xlws.FILTER(tblFR041Sel[RowId],tblFR041Sel[Include]=1),ROWS($AP$11:AP15)),"") | AQ15: =AO15/$AO$44 -> #VALUE! | AR15: =AO15/$AO$45 -> #VALUE!
B16: =IF($AP16="","",_xlfn.XLOOKUP($AP16,tblScope11Stationary[RowId],tblScope11Stationary[ItemLabel],"")) | C16: =IF($AP16="","",_xlfn.XLOOKUP($AP16,tblScope11Stationary[RowId],tblScope11Stationary[Unit],"")) | D16: =IF($AP16="","",SUM(INDEX(tblScope11Stationary[[M1]:[M12]],MATCH($AP16,tblScope11Stationary[RowId],0),0))) | Q16: =(E16*$AV$8)+(F16*$AV$9)+(G16*$AV$10)+(H16*$AV$11)+(I16*$AV$12)+(J16*$AV$13)+(K16*M16)+(L16*N16) -> 0 | AA16: =D16*E16/1000 -> #VALUE! | AB16: =D16*F16/1000 -> #VALUE! | AC16: =D16*G16/1000 -> #VALUE! | AD16: =D16*H16/1000 -> #VALUE! | AE16: =D16*I16/1000 -> #VALUE! | AF16: =D16*J16/1000 -> #VALUE! | AG16: =D16*F16*$AV$9/1000 -> #VALUE! | AH16: =D16*G16*$AV$10/1000 -> #VALUE! | AI16: =D16*H16*$AV$11/1000 -> #VALUE! | AJ16: =D16*I16*$AV$12/1000 -> #VALUE! | AK16: =D16*J16*$AV$13/1000 -> #VALUE! | AL16: =D16*K16*M16/1000 -> #VALUE! | AM16: =D16*L16*N16/1000 -> #VALUE! | AO16: =D16*Q16/1000 -> #VALUE! | AP16: =IFERROR(INDEX(_xlfn._xlws.FILTER(tblFR041Sel[RowId],tblFR041Sel[Include]=1),ROWS($AP$11:AP16)),"") | AQ16: =AO16/$AO$44 -> #VALUE! | AR16: =AO16/$AO$45 -> #VALUE!
B17: =IF($AP17="","",_xlfn.XLOOKUP($AP17,tblScope11Stationary[RowId],tblScope11Stationary[ItemLabel],"")) | C17: =IF($AP17="","",_xlfn.XLOOKUP($AP17,tblScope11Stationary[RowId],tblScope11Stationary[Unit],"")) | D17: =IF($AP17="","",SUM(INDEX(tblScope11Stationary[[M1]:[M12]],MATCH($AP17,tblScope11Stationary[RowId],0),0))) | Q17: =(E17*$AV$8)+(F17*$AV$9)+(G17*$AV$10)+(H17*$AV$11)+(I17*$AV$12)+(J17*$AV$13)+(K17*M17)+(L17*N17) -> 0 | AA17: =D17*E17/1000 -> #VALUE! | AB17: =D17*F17/1000 -> #VALUE! | AC17: =D17*G17/1000 -> #VALUE! | AD17: =D17*H17/1000 -> #VALUE! | AE17: =D17*I17/1000 -> #VALUE! | AF17: =D17*J17/1000 -> #VALUE! | AG17: =D17*F17*$AV$9/1000 -> #VALUE! | AH17: =D17*G17*$AV$10/1000 -> #VALUE! | AI17: =D17*H17*$AV$11/1000 -> #VALUE! | AJ17: =D17*I17*$AV$12/1000 -> #VALUE! | AK17: =D17*J17*$AV$13/1000 -> #VALUE! | AL17: =D17*K17*M17/1000 -> #VALUE! | AM17: =D17*L17*N17/1000 -> #VALUE! | AO17: =D17*Q17/1000 -> #VALUE! | AP17: =IFERROR(INDEX(_xlfn._xlws.FILTER(tblFR041Sel[RowId],tblFR041Sel[Include]=1),ROWS($AP$11:AP17)),"") | AQ17: =AO17/$AO$44 -> #VALUE! | AR17: =AO17/$AO$45 -> #VALUE!
B18: =IF($AP18="","",_xlfn.XLOOKUP($AP18,tblScope11Stationary[RowId],tblScope11Stationary[ItemLabel],"")) | C18: =IF($AP18="","",_xlfn.XLOOKUP($AP18,tblScope11Stationary[RowId],tblScope11Stationary[Unit],"")) | D18: =IF($AP18="","",SUM(INDEX(tblScope11Stationary[[M1]:[M12]],MATCH($AP18,tblScope11Stationary[RowId],0),0))) | Q18: =(E18*$AV$8)+(F18*$AV$9)+(G18*$AV$10)+(H18*$AV$11)+(I18*$AV$12)+(J18*$AV$13)+(K18*M18)+(L18*N18) -> 0 | AA18: =D18*E18/1000 -> #VALUE! | AB18: =D18*F18/1000 -> #VALUE! | AC18: =D18*G18/1000 -> #VALUE! | AD18: =D18*H18/1000 -> #VALUE! | AE18: =D18*I18/1000 -> #VALUE! | AF18: =D18*J18/1000 -> #VALUE! | AG18: =D18*F18*$AV$9/1000 -> #VALUE! | AH18: =D18*G18*$AV$10/1000 -> #VALUE! | AI18: =D18*H18*$AV$11/1000 -> #VALUE! | AJ18: =D18*I18*$AV$12/1000 -> #VALUE! | AK18: =D18*J18*$AV$13/1000 -> #VALUE! | AL18: =D18*K18*M18/1000 -> #VALUE! | AM18: =D18*L18*N18/1000 -> #VALUE! | AO18: =D18*Q18/1000 -> #VALUE! | AP18: =IFERROR(INDEX(_xlfn._xlws.FILTER(tblFR041Sel[RowId],tblFR041Sel[Include]=1),ROWS($AP$11:AP18)),"") | AQ18: =AO18/$AO$44 -> #VALUE! | AR18: =AO18/$AO$45 -> #VALUE!
B19: =IF($AP19="","",_xlfn.XLOOKUP($AP19,tblScope11Stationary[RowId],tblScope11Stationary[ItemLabel],"")) | C19: =IF($AP19="","",_xlfn.XLOOKUP($AP19,tblScope11Stationary[RowId],tblScope11Stationary[Unit],"")) | D19: =IF($AP19="","",SUM(INDEX(tblScope11Stationary[[M1]:[M12]],MATCH($AP19,tblScope11Stationary[RowId],0),0))) | Q19: =(E19*$AV$8)+(F19*$AV$9)+(G19*$AV$10)+(H19*$AV$11)+(I19*$AV$12)+(J19*$AV$13)+(K19*M19)+(L19*N19) -> 0 | AA19: =D19*E19/1000 -> #VALUE! | AB19: =D19*F19/1000 -> #VALUE! | AC19: =D19*G19/1000 -> #VALUE! | AD19: =D19*H19/1000 -> #VALUE! | AE19: =D19*I19/1000 -> #VALUE! | AF19: =D19*J19/1000 -> #VALUE! | AG19: =D19*F19*$AV$9/1000 -> #VALUE! | AH19: =D19*G19*$AV$10/1000 -> #VALUE! | AI19: =D19*H19*$AV$11/1000 -> #VALUE! | AJ19: =D19*I19*$AV$12/1000 -> #VALUE! | AK19: =D19*J19*$AV$13/1000 -> #VALUE! | AL19: =D19*K19*M19/1000 -> #VALUE! | AM19: =D19*L19*N19/1000 -> #VALUE! | AO19: =D19*Q19/1000 -> #VALUE! | AP19: =IFERROR(INDEX(_xlfn._xlws.FILTER(tblFR041Sel[RowId],tblFR041Sel[Include]=1),ROWS($AP$11:AP19)),"") | AQ19: =AO19/$AO$44 -> #VALUE! | AR19: =AO19/$AO$45 -> #VALUE!
B20: =IF($AP20="","",_xlfn.XLOOKUP($AP20,tblScope11Stationary[RowId],tblScope11Stationary[ItemLabel],"")) | C20: =IF($AP20="","",_xlfn.XLOOKUP($AP20,tblScope11Stationary[RowId],tblScope11Stationary[Unit],"")) | D20: =IF($AP20="","",SUM(INDEX(tblScope11Stationary[[M1]:[M12]],MATCH($AP20,tblScope11Stationary[RowId],0),0))) | Q20: =(E20*$AV$8)+(F20*$AV$9)+(G20*$AV$10)+(H20*$AV$11)+(I20*$AV$12)+(J20*$AV$13)+(K20*M20)+(L20*N20) -> 0 | AA20: =D20*E20/1000 -> #VALUE! | AB20: =D20*F20/1000 -> #VALUE! | AC20: =D20*G20/1000 -> #VALUE! | AD20: =D20*H20/1000 -> #VALUE! | AE20: =D20*I20/1000 -> #VALUE! | AF20: =D20*J20/1000 -> #VALUE! | AG20: =D20*F20*$AV$9/1000 -> #VALUE! | AH20: =D20*G20*$AV$10/1000 -> #VALUE! | AI20: =D20*H20*$AV$11/1000 -> #VALUE! | AJ20: =D20*I20*$AV$12/1000 -> #VALUE! | AK20: =D20*J20*$AV$13/1000 -> #VALUE! | AL20: =D20*K20*M20/1000 -> #VALUE! | AM20: =D20*L20*N20/1000 -> #VALUE! | AO20: =D20*Q20/1000 -> #VALUE! | AP20: =IFERROR(INDEX(_xlfn._xlws.FILTER(tblFR041Sel[RowId],tblFR041Sel[Include]=1),ROWS($AP$11:AP20)),"") | AQ20: =AO20/$AO$44 -> #VALUE! | AR20: =AO20/$AO$45 -> #VALUE!
B21: =IF($AP21="","",_xlfn.XLOOKUP($AP21,tblScope11Stationary[RowId],tblScope11Stationary[ItemLabel],"")) | C21: =IF($AP21="","",_xlfn.XLOOKUP($AP21,tblScope11Stationary[RowId],tblScope11Stationary[Unit],"")) | D21: =IF($AP21="","",SUM(INDEX(tblScope11Stationary[[M1]:[M12]],MATCH($AP21,tblScope11Stationary[RowId],0),0))) | Q21: =(E21*$AV$8)+(F21*$AV$9)+(G21*$AV$10)+(H21*$AV$11)+(I21*$AV$12)+(J21*$AV$13)+(K21*M21)+(L21*N21) -> 0 | AA21: =D21*E21/1000 -> #VALUE! | AB21: =D21*F21/1000 -> #VALUE! | AC21: =D21*G21/1000 -> #VALUE! | AD21: =D21*H21/1000 -> #VALUE! | AE21: =D21*I21/1000 -> #VALUE! | AF21: =D21*J21/1000 -> #VALUE! | AG21: =D21*F21*$AV$9/1000 -> #VALUE! | AH21: =D21*G21*$AV$10/1000 -> #VALUE! | AI21: =D21*H21*$AV$11/1000 -> #VALUE! | AJ21: =D21*I21*$AV$12/1000 -> #VALUE! | AK21: =D21*J21*$AV$13/1000 -> #VALUE! | AL21: =D21*K21*M21/1000 -> #VALUE! | AM21: =D21*L21*N21/1000 -> #VALUE! | AO21: =D21*Q21/1000 -> #VALUE! | AP21: =IFERROR(INDEX(_xlfn._xlws.FILTER(tblFR041Sel[RowId],tblFR041Sel[Include]=1),ROWS($AP$11:AP21)),"") | AQ21: =AO21/$AO$44 -> #VALUE! | AR21: =AO21/$AO$45 -> #VALUE!
B22: =IF($AP22="","",_xlfn.XLOOKUP($AP22,tblScope11Stationary[RowId],tblScope11Stationary[ItemLabel],"")) | C22: =IF($AP22="","",_xlfn.XLOOKUP($AP22,tblScope11Stationary[RowId],tblScope11Stationary[Unit],"")) | D22: =IF($AP22="","",SUM(INDEX(tblScope11Stationary[[M1]:[M12]],MATCH($AP22,tblScope11Stationary[RowId],0),0))) | Q22: =(E22*$AV$8)+(F22*$AV$9)+(G22*$AV$10)+(H22*$AV$11)+(I22*$AV$12)+(J22*$AV$13)+(K22*M22)+(L22*N22) -> 0 | AA22: =D22*E22/1000 -> #VALUE! | AB22: =D22*F22/1000 -> #VALUE! | AC22: =D22*G22/1000 -> #VALUE! | AD22: =D22*H22/1000 -> #VALUE! | AE22: =D22*I22/1000 -> #VALUE! | AF22: =D22*J22/1000 -> #VALUE! | AG22: =D22*F22*$AV$9/1000 -> #VALUE! | AH22: =D22*G22*$AV$10/1000 -> #VALUE! | AI22: =D22*H22*$AV$11/1000 -> #VALUE! | AJ22: =D22*I22*$AV$12/1000 -> #VALUE! | AK22: =D22*J22*$AV$13/1000 -> #VALUE! | AL22: =D22*K22*M22/1000 -> #VALUE! | AM22: =D22*L22*N22/1000 -> #VALUE! | AO22: =D22*Q22/1000 -> #VALUE! | AP22: =IFERROR(INDEX(_xlfn._xlws.FILTER(tblFR041Sel[RowId],tblFR041Sel[Include]=1),ROWS($AP$11:AP22)),"") | AQ22: =AO22/$AO$44 -> #VALUE! | AR22: =AO22/$AO$45 -> #VALUE!
B23: =IF($AP23="","",_xlfn.XLOOKUP($AP23,tblScope11Stationary[RowId],tblScope11Stationary[ItemLabel],"")) | C23: =IF($AP23="","",_xlfn.XLOOKUP($AP23,tblScope11Stationary[RowId],tblScope11Stationary[Unit],"")) | D23: =IF($AP23="","",SUM(INDEX(tblScope11Stationary[[M1]:[M12]],MATCH($AP23,tblScope11Stationary[RowId],0),0))) | Q23: =(E23*$AV$8)+(F23*$AV$9)+(G23*$AV$10)+(H23*$AV$11)+(I23*$AV$12)+(J23*$AV$13)+(K23*M23)+(L23*N23) -> 0 | AA23: =D23*E23/1000 -> #VALUE! | AB23: =D23*F23/1000 -> #VALUE! | AC23: =D23*G23/1000 -> #VALUE! | AD23: =D23*H23/1000 -> #VALUE! | AE23: =D23*I23/1000 -> #VALUE! | AF23: =D23*J23/1000 -> #VALUE! | AG23: =D23*F23*$AV$9/1000 -> #VALUE! | AH23: =D23*G23*$AV$10/1000 -> #VALUE! | AI23: =D23*H23*$AV$11/1000 -> #VALUE! | AJ23: =D23*I23*$AV$12/1000 -> #VALUE! | AK23: =D23*J23*$AV$13/1000 -> #VALUE! | AL23: =D23*K23*M23/1000 -> #VALUE! | AM23: =D23*L23*N23/1000 -> #VALUE! | AO23: =D23*Q23/1000 -> #VALUE! | AP23: =IFERROR(INDEX(_xlfn._xlws.FILTER(tblFR041Sel[RowId],tblFR041Sel[Include]=1),ROWS($AP$11:AP23)),"") | AQ23: =AO23/$AO$44 -> #VALUE! | AR23: =AO23/$AO$45 -> #VALUE!
B24: =IF($AP24="","",_xlfn.XLOOKUP($AP24,tblScope11Stationary[RowId],tblScope11Stationary[ItemLabel],"")) | C24: =IF($AP24="","",_xlfn.XLOOKUP($AP24,tblScope11Stationary[RowId],tblScope11Stationary[Unit],"")) | D24: =IF($AP24="","",SUM(INDEX(tblScope11Stationary[[M1]:[M12]],MATCH($AP24,tblScope11Stationary[RowId],0),0))) | AA24: =SUM(AA10:AA23) -> #VALUE! | AB24: =SUM(AB10:AB23) -> #VALUE! | AC24: =SUM(AC10:AC23) -> #VALUE! | AD24: =SUM(AD10:AD23) -> #VALUE! | AE24: =SUM(AE10:AE23) -> #VALUE! | AF24: =SUM(AF10:AF23) -> #VALUE! | AG24: =SUM(AG10:AG23) -> #VALUE! | AH24: =SUM(AH10:AH23) -> #VALUE! | ... AO24: =SUM(AO10:AO23) -> #VALUE! | AP24: =IFERROR(INDEX(_xlfn._xlws.FILTER(tblFR041Sel[RowId],tblFR041Sel[Include]=1),ROWS($AP$11:AP24)),"")
A25: การปล่อย GHG โดยตรงที่ทำการรายงานแยก | Q25: =(E25*$AV$8)+(O25*P25) -> 0 | AA25: =D25*E25*$AV$8/1000 -> 0 | AN25: =D25*O25*P25/1000 -> 0 | AO25: =D25*Q25/1000 -> 0 | AP25: =AO25/$AO$30 -> #DIV/0!
Q26: =(E26*$AV$8)+(O26*P26) -> 0 | AA26: =D26*E26*$AV$8/1000 -> 0 | AN26: =D26*O26*P26/1000 -> 0 | AO26: =D26*Q26/1000 -> 0 | AP26: =AO26/$AO$30 -> #DIV/0!
Q27: =(E27*$AV$8)+(O27*P27) -> 0 | AA27: =D27*E27*$AV$8/1000 -> 0 | AN27: =D27*O27*P27/1000 -> 0 | AO27: =D27*Q27/1000 -> 0 | AP27: =AO27/$AO$30 -> #DIV/0!
Q28: =(E28*$AV$8)+(O28*P28) -> 0 | AA28: =D28*E28*$AV$8/1000 -> 0 | AN28: =D28*O28*P28/1000 -> 0 | AO28: =D28*Q28/1000 -> 0 | AP28: =AO28/$AO$30 -> #DIV/0!
Q29: =(E29*$AV$8)+(O29*P29) -> 0 | AA29: =D29*E29*$AV$8/1000 -> 0 | AN29: =D29*O29*P29/1000 -> 0 | AO29: =D29*Q29/1000 -> 0 | AP29: =AO29/$AO$30 -> #DIV/0!
AO30: =SUM(AO25:AO29) -> 0 | AP30: =SUM(AP25:AP29) -> #DIV/0!
A31: ขอบเขต 2 | AO31: =D31*Q31/1000 -> 0 | AP31: =AO31/$AO$35 -> #DIV/0! | AQ31: =AO31/$AO$44 -> #VALUE! | AR31: =AO31/$AO$45 -> #VALUE!
AO32: =D32*Q32/1000 -> 0 | AP32: =AO32/$AO$35 -> #DIV/0! | AQ32: =AO32/$AO$44 -> #VALUE! | AR32: =AO32/$AO$45 -> #VALUE!
AO33: =D33*Q33/1000 -> 0 | AP33: =AO33/$AO$35 -> #DIV/0! | AQ33: =AO33/$AO$44 -> #VALUE! | AR33: =AO33/$AO$45 -> #VALUE!
AP34: =AO34/$AO$35 -> #DIV/0! | AQ34: =AO34/$AO$44 -> #VALUE! | AR34: =AO34/$AO$45 -> #VALUE!
AO35: =SUM(AO31:AO34) -> 0 | AP35: =SUM(AP31:AP34) -> #DIV/0!
A36: ขอบเขต 3 | AO36: =D36*Q36/1000 -> 0 | AP36: =AO36/$AO$43 -> #DIV/0! | AR36: =AO36/$AO$45 -> #VALUE!
AO37: =D37*Q37/1000 -> 0 | AP37: =AO37/$AO$43 -> #DIV/0! | AR37: =AO37/$AO$45 -> #VALUE!
AO38: =D38*Q38/1000 -> 0 | AP38: =AO38/$AO$43 -> #DIV/0! | AR38: =AO38/$AO$45 -> #VALUE!
AO39: =D39*Q39/1000 -> 0 | AP39: =AO39/$AO$43 -> #DIV/0! | AR39: =AO39/$AO$45 -> #VALUE!
AO40: =D40*Q40/1000 -> 0 | AP40: =AO40/$AO$43 -> #DIV/0! | AR40: =AO40/$AO$45 -> #VALUE!
AO41: =D41*Q41/1000 -> 0 | AP41: =AO41/$AO$43 -> #DIV/0! | AR41: =AO41/$AO$45 -> #VALUE!
AP42: =AO42/$AO$43 -> #DIV/0! | AR42: =AO42/$AO$45 -> #VALUE!
...

Sheet Fr-04.2
B1: บัญชีรายการก๊าซเรือนกระจก ปีฐาน (base year) | AO1: TCFO_R_01 Version 04 : 21/2/2020
B3: ชื่อฟอร์ม | C3: บัญชีรายการก๊าซเรือนกระจก | H3: องค์กร | I3: ='Fr-01'!$B$6 -> ชื่อองค์กรที่ขอขึ้นทะเบียน | AB3: ปีฐาน | AE3: ='Fr-01'!H24 -> ระบุปีฐาน เช่น ม.ค.61-ธ.ค.61 | AO3: หน้าที่ | AR3: 5
B4: รหัสฟอร์ม | C4: Fr-04.2 | H4: ผู้จัดทำ | I4: ='Fr-01'!$G$4 -> 0 | AO4: วันที่
A6: ขอบเขต | B6: รายการ | C6: ค่า LCI | E6: GHG ที่ต้องรายงานตามข้อกำหนด | O6: GHG ที่อยู่นอกข้อกำหนด | Q6: Total (kgCO2e/หน่วย) | R6: ที่มา | Y6: Subsitute | Z6: แหล่งอ้างอิง | AA6: ผลคูณ (Ton GHG) | AG6: ผลคูณ (TonCO2e) | AO6: Total GHG | AP6: สัดส่วน (%) | AQ6: สัดส่วน (%) (SCOPE 1+2) | AR6: สัดส่วน (%) (SCOPE 1+2+3) | AS6: ระบุความแตกต่างระหว่างการรายงานปริมาณก๊าซเรือนกระจกของปีฐานและปีปัจจุบัน | AU6: GWP100
R7: 1st | T7: 2nd | X7: Other | AU7: ที่มา | AV7: IPCC, AR5
E8: ค่า EF (kg GHG/หน่วย) | M8: GWP100 | O8: ค่า EF (kg GHG/หน่วย) | P8: GWP100 | R8: Self collct | S8: Supplier | T8: TH LCI DB | U8: TGO EF | V8: Thai Res. | W8: Int. DB | AO8: (TonCO2e) | AU8: CO2 | AV8: 1
C9: หน่วย | D9: ปริมาณ | E9: CO2 | F9: Fossil CH4 | G9: CH4 | H9: N2O | I9: SF6 | J9: NF3 | K9: HFCs | L9: PFCs | M9: HFCs | N9: PFCs | AA9: CO2 | AB9: Fossil CH4 | AC9: CH4 | AD9: N2O | AE9: SF6 | AF9: NF3 | AG9: Fossil CH4 | AH9: CH4 | AI9: N2O | AJ9: SF6 | AK9: NF3 | AL9: HFCs | AM9: PFCs | AN9: Other | AU9: Fossil CH4 | AV9: 30
A10: ขอบเขต 1 | Q10: =(E10*$AV$8)+(F10*$AV$9)+(G10*$AV$10)+(H10*$AV$11)+(I10*$AV$12)+(J10*$AV$13)+(K10*M10)+(L10*N10) -> 0 | AA10: =D10*E10/1000 -> 0 | AB10: =D10*F10/1000 -> 0 | AC10: =D10*G10/1000 -> 0 | AD10: =D10*H10/1000 -> 0 | AE10: =D10*I10/1000 -> 0 | AF10: =D10*J10/1000 -> 0 | AG10: =D10*F10*$AV$9/1000 -> 0 | AH10: =D10*G10*$AV$10/1000 -> 0 | AI10: =D10*H10*$AV$11/1000 -> 0 | AJ10: =D10*I10*$AV$12/1000 -> 0 | AK10: =D10*J10*$AV$13/1000 -> 0 | AL10: =D10*K10*M10/1000 -> 0 | AM10: =D10*L10*N10/1000 -> 0 | AO10: =D10*Q10/1000 -> 0 | AP10: =AO10/$AO$24 -> #DIV/0! | AQ10: =AO10/$AO$44 -> #DIV/0! | AR10: =AO10/$AO$45 -> #DIV/0! | AU10: CH4 | AV10: 28
Q11: =(E11*$AV$8)+(F11*$AV$9)+(G11*$AV$10)+(H11*$AV$11)+(I11*$AV$12)+(J11*$AV$13)+(K11*M11)+(L11*N11) -> 0 | AA11: =D11*E11/1000 -> 0 | AB11: =D11*F11/1000 -> 0 | AC11: =D11*G11/1000 -> 0 | AD11: =D11*H11/1000 -> 0 | AE11: =D11*I11/1000 -> 0 | AF11: =D11*J11/1000 -> 0 | AG11: =D11*F11*$AV$9/1000 -> 0 | AH11: =D11*G11*$AV$10/1000 -> 0 | AI11: =D11*H11*$AV$11/1000 -> 0 | AJ11: =D11*I11*$AV$12/1000 -> 0 | AK11: =D11*J11*$AV$13/1000 -> 0 | AL11: =D11*K11*M11/1000 -> 0 | AM11: =D11*L11*N11/1000 -> 0 | AO11: =D11*Q11/1000 -> 0 | AP11: =AO11/$AO$24 -> #DIV/0! | AQ11: =AO11/$AO$44 -> #DIV/0! | AR11: =AO11/$AO$45 -> #DIV/0! | AU11: N2O | AV11: 265
Q12: =(E12*$AV$8)+(F12*$AV$9)+(G12*$AV$10)+(H12*$AV$11)+(I12*$AV$12)+(J12*$AV$13)+(K12*M12)+(L12*N12) -> 0 | AA12: =D12*E12/1000 -> 0 | AB12: =D12*F12/1000 -> 0 | AC12: =D12*G12/1000 -> 0 | AD12: =D12*H12/1000 -> 0 | AE12: =D12*I12/1000 -> 0 | AF12: =D12*J12/1000 -> 0 | AG12: =D12*F12*$AV$9/1000 -> 0 | AH12: =D12*G12*$AV$10/1000 -> 0 | AI12: =D12*H12*$AV$11/1000 -> 0 | AJ12: =D12*I12*$AV$12/1000 -> 0 | AK12: =D12*J12*$AV$13/1000 -> 0 | AL12: =D12*K12*M12/1000 -> 0 | AM12: =D12*L12*N12/1000 -> 0 | AO12: =D12*Q12/1000 -> 0 | AP12: =AO12/$AO$24 -> #DIV/0! | AQ12: =AO12/$AO$44 -> #DIV/0! | AR12: =AO12/$AO$45 -> #DIV/0! | AU12: SF6 | AV12: 23500
Q13: =(E13*$AV$8)+(F13*$AV$9)+(G13*$AV$10)+(H13*$AV$11)+(I13*$AV$12)+(J13*$AV$13)+(K13*M13)+(L13*N13) -> 0 | AA13: =D13*E13/1000 -> 0 | AB13: =D13*F13/1000 -> 0 | AC13: =D13*G13/1000 -> 0 | AD13: =D13*H13/1000 -> 0 | AE13: =D13*I13/1000 -> 0 | AF13: =D13*J13/1000 -> 0 | AG13: =D13*F13*$AV$9/1000 -> 0 | AH13: =D13*G13*$AV$10/1000 -> 0 | AI13: =D13*H13*$AV$11/1000 -> 0 | AJ13: =D13*I13*$AV$12/1000 -> 0 | AK13: =D13*J13*$AV$13/1000 -> 0 | AL13: =D13*K13*M13/1000 -> 0 | AM13: =D13*L13*N13/1000 -> 0 | AO13: =D13*Q13/1000 -> 0 | AP13: =AO13/$AO$24 -> #DIV/0! | AQ13: =AO13/$AO$44 -> #DIV/0! | AR13: =AO13/$AO$45 -> #DIV/0! | AU13: NF3 | AV13: 16100
Q14: =(E14*$AV$8)+(F14*$AV$9)+(G14*$AV$10)+(H14*$AV$11)+(I14*$AV$12)+(J14*$AV$13)+(K14*M14)+(L14*N14) -> 0 | AA14: =D14*E14/1000 -> 0 | AB14: =D14*F14/1000 -> 0 | AC14: =D14*G14/1000 -> 0 | AD14: =D14*H14/1000 -> 0 | AE14: =D14*I14/1000 -> 0 | AF14: =D14*J14/1000 -> 0 | AG14: =D14*F14*$AV$9/1000 -> 0 | AH14: =D14*G14*$AV$10/1000 -> 0 | AI14: =D14*H14*$AV$11/1000 -> 0 | AJ14: =D14*I14*$AV$12/1000 -> 0 | AK14: =D14*J14*$AV$13/1000 -> 0 | AL14: =D14*K14*M14/1000 -> 0 | AM14: =D14*L14*N14/1000 -> 0 | AO14: =D14*Q14/1000 -> 0 | AP14: =AO14/$AO$24 -> #DIV/0! | AQ14: =AO14/$AO$44 -> #DIV/0! | AR14: =AO14/$AO$45 -> #DIV/0!
Q15: =(E15*$AV$8)+(F15*$AV$9)+(G15*$AV$10)+(H15*$AV$11)+(I15*$AV$12)+(J15*$AV$13)+(K15*M15)+(L15*N15) -> 0 | AA15: =D15*E15/1000 -> 0 | AB15: =D15*F15/1000 -> 0 | AC15: =D15*G15/1000 -> 0 | AD15: =D15*H15/1000 -> 0 | AE15: =D15*I15/1000 -> 0 | AF15: =D15*J15/1000 -> 0 | AG15: =D15*F15*$AV$9/1000 -> 0 | AH15: =D15*G15*$AV$10/1000 -> 0 | AI15: =D15*H15*$AV$11/1000 -> 0 | AJ15: =D15*I15*$AV$12/1000 -> 0 | AK15: =D15*J15*$AV$13/1000 -> 0 | AL15: =D15*K15*M15/1000 -> 0 | AM15: =D15*L15*N15/1000 -> 0 | AO15: =D15*Q15/1000 -> 0 | AP15: =AO15/$AO$24 -> #DIV/0! | AQ15: =AO15/$AO$44 -> #DIV/0! | AR15: =AO15/$AO$45 -> #DIV/0!
Q16: =(E16*$AV$8)+(F16*$AV$9)+(G16*$AV$10)+(H16*$AV$11)+(I16*$AV$12)+(J16*$AV$13)+(K16*M16)+(L16*N16) -> 0 | AA16: =D16*E16/1000 -> 0 | AB16: =D16*F16/1000 -> 0 | AC16: =D16*G16/1000 -> 0 | AD16: =D16*H16/1000 -> 0 | AE16: =D16*I16/1000 -> 0 | AF16: =D16*J16/1000 -> 0 | AG16: =D16*F16*$AV$9/1000 -> 0 | AH16: =D16*G16*$AV$10/1000 -> 0 | AI16: =D16*H16*$AV$11/1000 -> 0 | AJ16: =D16*I16*$AV$12/1000 -> 0 | AK16: =D16*J16*$AV$13/1000 -> 0 | AL16: =D16*K16*M16/1000 -> 0 | AM16: =D16*L16*N16/1000 -> 0 | AO16: =D16*Q16/1000 -> 0 | AP16: =AO16/$AO$24 -> #DIV/0! | AQ16: =AO16/$AO$44 -> #DIV/0! | AR16: =AO16/$AO$45 -> #DIV/0!
Q17: =(E17*$AV$8)+(F17*$AV$9)+(G17*$AV$10)+(H17*$AV$11)+(I17*$AV$12)+(J17*$AV$13)+(K17*M17)+(L17*N17) -> 0 | AA17: =D17*E17/1000 -> 0 | AB17: =D17*F17/1000 -> 0 | AC17: =D17*G17/1000 -> 0 | AD17: =D17*H17/1000 -> 0 | AE17: =D17*I17/1000 -> 0 | AF17: =D17*J17/1000 -> 0 | AG17: =D17*F17*$AV$9/1000 -> 0 | AH17: =D17*G17*$AV$10/1000 -> 0 | AI17: =D17*H17*$AV$11/1000 -> 0 | AJ17: =D17*I17*$AV$12/1000 -> 0 | AK17: =D17*J17*$AV$13/1000 -> 0 | AL17: =D17*K17*M17/1000 -> 0 | AM17: =D17*L17*N17/1000 -> 0 | AO17: =D17*Q17/1000 -> 0 | AP17: =AO17/$AO$24 -> #DIV/0! | AQ17: =AO17/$AO$44 -> #DIV/0! | AR17: =AO17/$AO$45 -> #DIV/0!
Q18: =(E18*$AV$8)+(F18*$AV$9)+(G18*$AV$10)+(H18*$AV$11)+(I18*$AV$12)+(J18*$AV$13)+(K18*M18)+(L18*N18) -> 0 | AA18: =D18*E18/1000 -> 0 | AB18: =D18*F18/1000 -> 0 | AC18: =D18*G18/1000 -> 0 | AD18: =D18*H18/1000 -> 0 | AE18: =D18*I18/1000 -> 0 | AF18: =D18*J18/1000 -> 0 | AG18: =D18*F18*$AV$9/1000 -> 0 | AH18: =D18*G18*$AV$10/1000 -> 0 | AI18: =D18*H18*$AV$11/1000 -> 0 | AJ18: =D18*I18*$AV$12/1000 -> 0 | AK18: =D18*J18*$AV$13/1000 -> 0 | AL18: =D18*K18*M18/1000 -> 0 | AM18: =D18*L18*N18/1000 -> 0 | AO18: =D18*Q18/1000 -> 0 | AP18: =AO18/$AO$24 -> #DIV/0! | AQ18: =AO18/$AO$44 -> #DIV/0! | AR18: =AO18/$AO$45 -> #DIV/0!
Q19: =(E19*$AV$8)+(F19*$AV$9)+(G19*$AV$10)+(H19*$AV$11)+(I19*$AV$12)+(J19*$AV$13)+(K19*M19)+(L19*N19) -> 0 | AA19: =D19*E19/1000 -> 0 | AB19: =D19*F19/1000 -> 0 | AC19: =D19*G19/1000 -> 0 | AD19: =D19*H19/1000 -> 0 | AE19: =D19*I19/1000 -> 0 | AF19: =D19*J19/1000 -> 0 | AG19: =D19*F19*$AV$9/1000 -> 0 | AH19: =D19*G19*$AV$10/1000 -> 0 | AI19: =D19*H19*$AV$11/1000 -> 0 | AJ19: =D19*I19*$AV$12/1000 -> 0 | AK19: =D19*J19*$AV$13/1000 -> 0 | AL19: =D19*K19*M19/1000 -> 0 | AM19: =D19*L19*N19/1000 -> 0 | AO19: =D19*Q19/1000 -> 0 | AP19: =AO19/$AO$24 -> #DIV/0! | AQ19: =AO19/$AO$44 -> #DIV/0! | AR19: =AO19/$AO$45 -> #DIV/0!
Q20: =(E20*$AV$8)+(F20*$AV$9)+(G20*$AV$10)+(H20*$AV$11)+(I20*$AV$12)+(J20*$AV$13)+(K20*M20)+(L20*N20) -> 0 | AA20: =D20*E20/1000 -> 0 | AB20: =D20*F20/1000 -> 0 | AC20: =D20*G20/1000 -> 0 | AD20: =D20*H20/1000 -> 0 | AE20: =D20*I20/1000 -> 0 | AF20: =D20*J20/1000 -> 0 | AG20: =D20*F20*$AV$9/1000 -> 0 | AH20: =D20*G20*$AV$10/1000 -> 0 | AI20: =D20*H20*$AV$11/1000 -> 0 | AJ20: =D20*I20*$AV$12/1000 -> 0 | AK20: =D20*J20*$AV$13/1000 -> 0 | AL20: =D20*K20*M20/1000 -> 0 | AM20: =D20*L20*N20/1000 -> 0 | AO20: =D20*Q20/1000 -> 0 | AP20: =AO20/$AO$24 -> #DIV/0! | AQ20: =AO20/$AO$44 -> #DIV/0! | AR20: =AO20/$AO$45 -> #DIV/0!
Q21: =(E21*$AV$8)+(F21*$AV$9)+(G21*$AV$10)+(H21*$AV$11)+(I21*$AV$12)+(J21*$AV$13)+(K21*M21)+(L21*N21) -> 0 | AA21: =D21*E21/1000 -> 0 | AB21: =D21*F21/1000 -> 0 | AC21: =D21*G21/1000 -> 0 | AD21: =D21*H21/1000 -> 0 | AE21: =D21*I21/1000 -> 0 | AF21: =D21*J21/1000 -> 0 | AG21: =D21*F21*$AV$9/1000 -> 0 | AH21: =D21*G21*$AV$10/1000 -> 0 | AI21: =D21*H21*$AV$11/1000 -> 0 | AJ21: =D21*I21*$AV$12/1000 -> 0 | AK21: =D21*J21*$AV$13/1000 -> 0 | AL21: =D21*K21*M21/1000 -> 0 | AM21: =D21*L21*N21/1000 -> 0 | AO21: =D21*Q21/1000 -> 0 | AP21: =AO21/$AO$24 -> #DIV/0! | AQ21: =AO21/$AO$44 -> #DIV/0! | AR21: =AO21/$AO$45 -> #DIV/0!
Q22: =(E22*$AV$8)+(F22*$AV$9)+(G22*$AV$10)+(H22*$AV$11)+(I22*$AV$12)+(J22*$AV$13)+(K22*M22)+(L22*N22) -> 0 | AA22: =D22*E22/1000 -> 0 | AB22: =D22*F22/1000 -> 0 | AC22: =D22*G22/1000 -> 0 | AD22: =D22*H22/1000 -> 0 | AE22: =D22*I22/1000 -> 0 | AF22: =D22*J22/1000 -> 0 | AG22: =D22*F22*$AV$9/1000 -> 0 | AH22: =D22*G22*$AV$10/1000 -> 0 | AI22: =D22*H22*$AV$11/1000 -> 0 | AJ22: =D22*I22*$AV$12/1000 -> 0 | AK22: =D22*J22*$AV$13/1000 -> 0 | AL22: =D22*K22*M22/1000 -> 0 | AM22: =D22*L22*N22/1000 -> 0 | AO22: =D22*Q22/1000 -> 0 | AP22: =AO22/$AO$24 -> #DIV/0! | AQ22: =AO22/$AO$44 -> #DIV/0! | AR22: =AO22/$AO$45 -> #DIV/0!
Q23: =(E23*$AV$8)+(F23*$AV$9)+(G23*$AV$10)+(H23*$AV$11)+(I23*$AV$12)+(J23*$AV$13)+(K23*M23)+(L23*N23) -> 0 | AA23: =D23*E23/1000 -> 0 | AB23: =D23*F23/1000 -> 0 | AC23: =D23*G23/1000 -> 0 | AD23: =D23*H23/1000 -> 0 | AE23: =D23*I23/1000 -> 0 | AF23: =D23*J23/1000 -> 0 | AG23: =D23*F23*$AV$9/1000 -> 0 | AH23: =D23*G23*$AV$10/1000 -> 0 | AI23: =D23*H23*$AV$11/1000 -> 0 | AJ23: =D23*I23*$AV$12/1000 -> 0 | AK23: =D23*J23*$AV$13/1000 -> 0 | AL23: =D23*K23*M23/1000 -> 0 | AM23: =D23*L23*N23/1000 -> 0 | AO23: =D23*Q23/1000 -> 0 | AP23: =AO23/$AO$24 -> #DIV/0! | AQ23: =AO23/$AO$44 -> #DIV/0! | AR23: =AO23/$AO$45 -> #DIV/0!
AA24: =SUM(AA10:AA23) -> 0 | AB24: =SUM(AB10:AB23) -> 0 | AC24: =SUM(AC10:AC23) -> 0 | AD24: =SUM(AD10:AD23) -> 0 | AE24: =SUM(AE10:AE23) -> 0 | AF24: =SUM(AF10:AF23) -> 0 | AG24: =SUM(AG10:AG23) -> 0 | AH24: =SUM(AH10:AH23) -> 0 | ... AP24: =SUM(AP10:AP23) -> #DIV/0!
A25: การปล่อย GHG โดยตรงที่ทำการรายงานแยก | Q25: =(E25*$AV$8)+(O25*P25) -> 0 | AA25: =D25*E25*$AV$8/1000 -> 0 | AN25: =D25*O25*P25/1000 -> 0 | AO25: =D25*Q25/1000 -> 0 | AP25: =AO25/$AO$30 -> #DIV/0!
Q26: =(E26*$AV$8)+(O26*P26) -> 0 | AA26: =D26*E26*$AV$8/1000 -> 0 | AN26: =D26*O26*P26/1000 -> 0 | AO26: =D26*Q26/1000 -> 0 | AP26: =AO26/$AO$30 -> #DIV/0!
Q27: =(E27*$AV$8)+(O27*P27) -> 0 | AA27: =D27*E27*$AV$8/1000 -> 0 | AN27: =D27*O27*P27/1000 -> 0 | AO27: =D27*Q27/1000 -> 0 | AP27: =AO27/$AO$30 -> #DIV/0!
Q28: =(E28*$AV$8)+(O28*P28) -> 0 | AA28: =D28*E28*$AV$8/1000 -> 0 | AN28: =D28*O28*P28/1000 -> 0 | AO28: =D28*Q28/1000 -> 0 | AP28: =AO28/$AO$30 -> #DIV/0!
Q29: =(E29*$AV$8)+(O29*P29) -> 0 | AA29: =D29*E29*$AV$8/1000 -> 0 | AN29: =D29*O29*P29/1000 -> 0 | AO29: =D29*Q29/1000 -> 0 | AP29: =AO29/$AO$30 -> #DIV/0!
AO30: =SUM(AO25:AO29) -> 0 | AP30: =SUM(AP25:AP29) -> #DIV/0!
A31: ขอบเขต 2 | AO31: =D31*Q31/1000 -> 0 | AP31: =AO31/$AO$35 -> #DIV/0! | AQ31: =AO31/$AO$44 -> #DIV/0! | AR31: =AO31/$AO$45 -> #DIV/0!
AO32: =D32*Q32/1000 -> 0 | AP32: =AO32/$AO$35 -> #DIV/0! | AQ32: =AO32/$AO$44 -> #DIV/0! | AR32: =AO32/$AO$45 -> #DIV/0!
AO33: =D33*Q33/1000 -> 0 | AP33: =AO33/$AO$35 -> #DIV/0! | AQ33: =AO33/$AO$44 -> #DIV/0! | AR33: =AO33/$AO$45 -> #DIV/0!
AP34: =AO34/$AO$35 -> #DIV/0! | AQ34: =AO34/$AO$44 -> #DIV/0! | AR34: =AO34/$AO$45 -> #DIV/0!
AO35: =SUM(AO31:AO34) -> 0 | AP35: =SUM(AP31:AP34) -> #DIV/0!
A36: ขอบเขต 3 | AO36: =D36*Q36/1000 -> 0 | AP36: =AO36/$AO$43 -> #DIV/0! | AR36: =AO36/$AO$45 -> #DIV/0!
AO37: =D37*Q37/1000 -> 0 | AP37: =AO37/$AO$43 -> #DIV/0! | AR37: =AO37/$AO$45 -> #DIV/0!
AO38: =D38*Q38/1000 -> 0 | AP38: =AO38/$AO$43 -> #DIV/0! | AR38: =AO38/$AO$45 -> #DIV/0!
AO39: =D39*Q39/1000 -> 0 | AP39: =AO39/$AO$43 -> #DIV/0! | AR39: =AO39/$AO$45 -> #DIV/0!
AO40: =D40*Q40/1000 -> 0 | AP40: =AO40/$AO$43 -> #DIV/0! | AR40: =AO40/$AO$45 -> #DIV/0!
AO41: =D41*Q41/1000 -> 0 | AP41: =AO41/$AO$43 -> #DIV/0! | AR41: =AO41/$AO$45 -> #DIV/0!
AP42: =AO42/$AO$43 -> #DIV/0! | AR42: =AO42/$AO$45 -> #DIV/0!
...

Sheet Fr-05
B1: สรุปการปล่อยก๊าซเรือนกระจกขององค์กร | I1: TCFO_R_01 Version 04 : 21/2/2020
B3: ชื่อฟอร์ม | C3: บัญชีรายการก๊าซเรือนกระจก | E3: องค์กร | F3: ='Fr-01'!$B$6 -> ชื่อองค์กรที่ขอขึ้นทะเบียน | I3: หน้าที่ | J3: 6
B4: รหัสฟอร์ม | C4: Fr-05 | E4: ผู้จัดทำ | F4: ='Fr-01'!$G$4 -> 0 | I4: วันที่จัดทำ
A5: ปีปัจจุบัน | B5: ='Fr-01'!H22 -> ระบุปีที่เก็บข้อมูล เช่น ม.ค.63-ธ.ค.63
B6: ขอบเขต | C6: การปล่อยก๊าซเรือนกระจกขององค์กร | D6: สัดส่วนเมื่อเทียบขอบเขต 1 และ 2 | E6: สัดส่วนเมื่อเทียบขอบเขต 1, 2 และ 3
B10: ประเภท 1 | C10: =ROUNDUP('Fr-04.1'!AO24,0) -> #VALUE! | D10: =C10/C$14% -> #VALUE! | E10: =C10/SUM(C10:C12)% -> #VALUE!
B11: ประเภท 2 | C11: =ROUNDUP('Fr-04.1'!AO35,0) -> 0 | D11: =C11/C$14% -> #VALUE! | E11: =C11/SUM(C10:C12)% -> #VALUE!
B12: ประเภท 3 | C12: =ROUNDUP('Fr-04.1'!AO43,0) -> 0 | E12: =C12/SUM(C10:C12)% -> #VALUE!
B13: อื่น ๆ | C13: =ROUNDUP('Fr-04.1'!AO30,0) -> 0
B14: รวม Scope 1 & 2 | C14: =SUM(C10:C11) -> #VALUE! | D14: =SUM(D10:D11) -> #VALUE!
B15: รวม Scope 1 & 2 & 3 | C15: =SUM(C10:C12) -> #VALUE! | E15: =SUM(E10:E12) -> #VALUE!
B17: Carbon intensity (Scope 1+2) | D17: =C14/'Fr-01'!H23 -> #VALUE! | E17: TonCO2eq/ | F17: ='Fr-01'!J23 -> ระบุหน่วย
B18: Carbon intensity (Scope 1+2+3) | D18: =C15/'Fr-01'!H23 -> #VALUE! | E18: TonCO2eq/ | F18: ='Fr-01'!J23 -> ระบุหน่วย
A20: ปีฐาน | B20: ='Fr-01'!H24 -> ระบุปีฐาน เช่น ม.ค.61-ธ.ค.61
B22: ขอบเขต | C22: การปล่อยก๊าซเรือนกระจกขององค์กร | D22: สัดส่วนเมื่อเทียบขอบเขต 1 และ 2 | E22: สัดส่วนเมื่อเทียบขอบเขต 1, 2 และ 3 | G22: เปรียบเทียบ
B26: ประเภท 1 | C26: =ROUNDUP('Fr-04.2'!AO24,0) -> 0 | D26: =C26/C$14% -> #VALUE! | E26: =C26/SUM(C26:C28)% -> #DIV/0!
B27: ประเภท 2 | C27: =ROUNDUP('Fr-04.2'!AO35,0) -> 0 | D27: =C27/C$14% -> #VALUE! | E27: =C27/SUM(C26:C28)% -> #DIV/0!
B28: ประเภท 3 | C28: =ROUNDUP('Fr-04.2'!AO43,0) -> 0 | E28: =C28/SUM(C26:C28)% -> #DIV/0!
B29: อื่น ๆ | C29: =ROUNDUP('Fr-04.2'!AO46,0) -> 0
B30: รวม Scope 1 & 2 | C30: =SUM(C26:C27) -> 0 | D30: =SUM(D26:D27) -> #VALUE!
B31: รวม Scope 1 & 2 & 3 | C31: =SUM(C26:C28) -> 0 | E31: =SUM(E26:E28) -> #DIV/0!
B33: Carbon intensity (Scope 1+2) | D33: =C30/'Fr-01'!H25 -> #DIV/0! | E33: TonCO2eq/ | F33: =F17 -> ระบุหน่วย
B34: Carbon intensity (Scope 1+2+3) | D34: =C31/'Fr-01'!H25 -> #DIV/0! | E34: TonCO2eq/ | F34: =F18 -> ระบุหน่วย
A37: จัดทำโดย | G37: เสร็จสิ้นวันที่ | H37: 0

Sheet EF TGO AR4
B2: ชื่อ | C2: Units | D2: EMISSION FACTORS | H2: แหล่งอ้างอิงข้อมูล | J2: GWP100
D3: CO2 | E3: CH4 | F3: N2O | G3: Total | J3: ที่มา | K3: IPCC, AR4 | L3: IPCC, AR5
D4: [kg CO2/unit] | E4: [kg CH4/unit] | F4: [kg N2O/unit] | G4: [kg CO2eq/unit] | J4: CO2 | K4: 1 | L4: 1
A5: Stationary Combustion | J5: CH4 | K5: 25 | L5: 28
B6: Natural gas | C6: scf | D6: =D48*$G$48*10^-6 -> 0.057222 | E6: =E48*$G$48*10^-6 -> 1.02e-06 | F6: =F48*$G$48*10^-6 -> 1.02e-07 | G6: =D6+(E6*$K$5)+(F6*$K$6) -> 0.057277896 | H6: IPCC Vol.2 table 2.2, DEDE | J6: N2O | K6: 298 | L6: 265
B7: Natural gas | C7: MJ | D7: =D48/1000000 -> 0.0561 | E7: =E48/1000000 -> 1e-06 | F7: =F48/1000000 -> 1e-07 | G7: =D7+(E7*$K$5)+(F7*$K$6) -> 0.0561548 | H7: IPCC Vol.2 table 2.2, DEDE | J7: SF6 | K7: 22800 | L7: 23500
B8: Lignite | C8: kg | D8: =D49*$G$49*10^-6 -> 1.05747 | E8: =E49*$G$49*10^-6 -> 1.047e-05 | F8: =F49*$G$49*10^-6 -> 1.5705e-05 | G8: =D8+(E8*$K$5)+(F8*$K$6) -> 1.0624118 | H8: IPCC Vol.2 table 2.2, DEDE | J8: NF3 | K8: 17200 | L8: 16100
B9: Fuel oil A | C9: litre | D9: =D50*$G$50*10^-6 -> 3.2096984 | E9: =E50*$G$50*10^-6 -> 0.00012440692 | F9: =F50*$G$50*10^-6 -> 2.4881383e-05 | G9: =D9+(E9*$K$5)+(F9*$K$6) -> 3.2202233 | H9: IPCC Vol.2 table 2.2, PTT | J9: PASS: 12345678
B10: Fuel oil C | C10: litre | D10: =D51*$G$51*10^-6 -> 3.2353401 | E10: =E51*$G$51*10^-6 -> 0.00012540078 | F10: =F51*$G$51*10^-6 -> 2.5080156e-05 | G10: =D10+(E10*$K$5)+(F10*$K$6) -> 3.245949 | H10: IPCC Vol.2 table 2.2, PTT
B11: Gas/Diesel oil | C11: litre | D11: =D52*$G$52*10^-6 -> 2.698722 | E11: =E52*$G$52*10^-6 -> 0.00010926 | F11: =F52*$G$52*10^-6 -> 2.1852e-05 | G11: =D11+(E11*$K$5)+(F11*$K$6) -> 2.7079654 | H11: IPCC Vol.2 table 2.2, DEDE
B12: Anthracite | C12: kg | D12: =D53*$G$53*10^-6 -> 3.08662 | E12: =E53*$G$53*10^-6 -> 3.14e-05 | F12: =F53*$G$53*10^-6 -> 4.71e-05 | G12: =D12+(E12*$K$5)+(F12*$K$6) -> 3.1014408 | H12: IPCC Vol.2 table 2.2, DEDE
B13: Sub-bituminous coal | C13: kg | D13: =D54*$G$54*10^-6 -> 2.534157 | E13: =E54*$G$54*10^-6 -> 2.637e-05 | F13: =F54*$G$54*10^-6 -> 3.9555e-05 | G13: =D13+(E13*$K$5)+(F13*$K$6) -> 2.5466036 | H13: IPCC Vol.2 table 2.2, DEDE
B14: Jet Kerosene | C14: litre | D14: =D55*$G$55*10^-6 -> 2.468895 | E14: =E55*$G$55*10^-6 -> 0.00010359 | F14: =F55*$G$55*10^-6 -> 2.0718e-05 | G14: =D14+(E14*$K$5)+(F14*$K$6) -> 2.4776587 | H14: IPCC Vol.2 table 2.2, DEDE
B15: LPG | C15: litre | D15: =D56*$G$56*10^-6 -> 1.679722 | E15: =E56*$G$56*10^-6 -> 2.662e-05 | F15: =F56*$G$56*10^-6 -> 2.662e-06 | G15: =D15+(E15*$K$5)+(F15*$K$6) -> 1.6811808 | H15: IPCC Vol.2 table 2.2, DEDE
B16: LPG | C16: kg | D16: =D15/0.54 -> 3.1105963 | E16: =E15/0.54 -> 4.9296296e-05 | F16: =F15/0.54 -> 4.9296296e-06 | G16: =D16+(E16*$K$5)+(F16*$K$6) -> 3.1132977 | H16: IPCC Vol.2 table 2.2, DEDE LPG 1 litre = 0.54 kg
B17: Motor gasoline | C17: litre | D17: =D57*$G$57*10^-6 -> 2.181564 | E17: =E57*$G$57*10^-6 -> 9.444e-05 | F17: =F57*$G$57*10^-6 -> 1.8888e-05 | G17: =D17+(E17*$K$5)+(F17*$K$6) -> 2.1895536 | H17: IPCC Vol.2 table 2.2, DEDE
A19: Mobile Combustion (On road)
B20: Motor Gasoline - uncontrolled | C20: litre | D20: =D63*$G$63*10^-6 -> 2.181564 | E20: =E63*$G$63*10^-6 -> 0.00103884 | F20: =F63*$G$63*10^-6 -> 0.000100736 | G20: =D20+(E20*$K$5)+(F20*$K$6) -> 2.2375543 | H20: IPCC Vol.2 table 3.2.1, 3.2.2, DEDE
B21: Motor Gasoline - oxydation catalyst | C21: litre | D21: =D64*$G$64*10^-6 -> 2.181564 | E21: =E64*$G$64*10^-6 -> 0.000787 | F21: =F64*$G$64*10^-6 -> 0.00025184 | G21: =D21+(E21*$K$5)+(F21*$K$6) -> 2.2762873 | H21: IPCC Vol.2 table 3.2.1, 3.2.2, DEDE
B22: Motor Gasoline - low mileage light duty vihicle vintage 1995 or later | C22: litre | D22: =D65*$G$65*10^-6 -> 2.181564 | E22: =E65*$G$65*10^-6 -> 0.000119624 | F22: =F65*$G$65*10^-6 -> 0.000179436 | G22: =D22+(E22*$K$5)+(F22*$K$6) -> 2.2380265 | H22: IPCC Vol.2 table 3.2.1, 3.2.2, DEDE
B23: Gas/ Diesel Oil | C23: litre | D23: =D66*$G$66*10^-6 -> 2.698722 | E23: =E66*$G$66*10^-6 -> 0.000142038 | F23: =F66*$G$66*10^-6 -> 0.000142038 | G23: =D23+(E23*$K$5)+(F23*$K$6) -> 2.7446003 | H23: IPCC Vol.2 table 3.2.1, 3.2.2, DEDE
B24: Compressed Natural Gas | C24: kg | D24: =D67*$G$67*10^-6 -> 2.12619 | E24: =E67*$G$67*10^-6 -> 0.0034868 | F24: =F67*$G$67*10^-6 -> 0.0001137 | G24: =D24+(E24*$K$5)+(F24*$K$6) -> 2.2472426 | H24: IPCC Vol.2 table 3.2.1, 3.2.2, PTT
B25: Liquified Petroleum Gas | C25: litre | D25: =D68*$G$68*10^-6 -> 1.679722 | E25: =E68*$G$68*10^-6 -> 0.00165044 | F25: =F68*$G$68*10^-6 -> 5.324e-06 | G25: =D25+(E25*$K$5)+(F25*$K$6) -> 1.7225696 | H25: IPCC Vol.2 table 3.2.1, 3.2.2, DEDE
B26: Liquified Petroleum Gas | C26: kg | D26: =D25/0.54 -> 3.1105963 | E26: =E25/0.54 -> 0.0030563704 | F26: =F25/0.54 -> 9.8592593e-06 | G26: =D26+(E26*$K$5)+(F26*$K$6) -> 3.1899436 | H26: IPCC Vol.2 table 3.2.1, 3.2.2, DEDE LPG 1 litre = 0.54 kg
A27: Mobile Combustion (Off road)
B28: Diesel
B29: - Agriculture | C29: litre | D29: =D75*$G$75/(10^6) -> 2.698722 | E29: =E75*$G$75/(10^6) -> 0.000151143 | F29: =F75*$G$75/(10^6) -> 0.001041612 | G29: =D29+(E29*$K$5)+(F29*$K$6) -> 3.012901 | H29: IPCC Vol.2 table 3.3.1, DEDE
B30: - Forestry | C30: litre | D30: =D76*$G$76/(10^6) -> 2.698722 | E30: =E76*$G$76/(10^6) -> 0.000151143 | F30: =F76*$G$76/(10^6) -> 0.001041612 | G30: =D30+(E30*$K$5)+(F30*$K$6) -> 3.012901 | H30: IPCC Vol.2 table 3.3.1, DEDE
B31: - Industry | C31: litre | D31: =D77*$G$77/(10^6) -> 2.698722 | E31: =E77*$G$77/(10^6) -> 0.000151143 | F31: =F77*$G$77/(10^6) -> 0.001041612 | G31: =D31+(E31*$K$5)+(F31*$K$6) -> 3.012901 | H31: IPCC Vol.2 table 3.3.1, DEDE
B32: - Household | C32: litre | D32: =D78*$G$78/(10^6) -> 2.698722 | E32: =E78*$G$78/(10^6) -> 0.000151143 | F32: =F78*$G$78/(10^6) -> 0.001041612 | G32: =D32+(E32*$K$5)+(F32*$K$6) -> 3.012901 | H32: IPCC Vol.2 table 3.3.1, DEDE
B33: Motor Gasoline - 4 stroke
B34: - Agriculture | C34: litre | D34: =D80*$G$80/(10^6) -> 2.181564 | E34: =E80*$G$80/(10^6) -> 0.0025184 | F34: =F80*$G$80/(10^6) -> 6.296e-05 | G34: =D34+(E34*$K$5)+(F34*$K$6) -> 2.2632861 | H34: IPCC Vol.2 table 3.3.1, DEDE
B35: - Forestry | C35: litre | D35: =D81*$G$81/(10^6) -> 2.181564 | E35: =E81*$G$81/(10^6) -> 0 | F35: =F81*$G$81/(10^6) -> 0 | G35: =D35+(E35*$K$5)+(F35*$K$6) -> 2.181564 | H35: IPCC Vol.2 table 3.3.1, DEDE
B36: - Industry | C36: litre | D36: =D82*$G$82/(10^6) -> 2.181564 | E36: =E82*$G$82/(10^6) -> 0.001574 | F36: =F82*$G$82/(10^6) -> 6.296e-05 | G36: =D36+(E36*$K$5)+(F36*$K$6) -> 2.2396761 | H36: IPCC Vol.2 table 3.3.1, DEDE
B37: - Household | C37: litre | D37: =D83*$G$83/(10^6) -> 2.181564 | E37: =E83*$G$83/(10^6) -> 0.0037776 | F37: =F83*$G$83/(10^6) -> 6.296e-05 | G37: =D37+(E37*$K$5)+(F37*$K$6) -> 2.2947661 | H37: IPCC Vol.2 table 3.3.1, DEDE
B38: Motor Gasoline - 2 stroke
B39: - Agriculture | C39: litre | D39: =D85*$G$85/(10^6) -> 2.181564 | E39: =E85*$G$85/(10^6) -> 0.0044072 | F39: =F85*$G$85/(10^6) -> 1.2592e-05 | G39: =D39+(E39*$K$5)+(F39*$K$6) -> 2.2954964 | H39: IPCC Vol.2 table 3.3.1, DEDE
B40: - Forestry | C40: litre | D40: =D86*$G$86/(10^6) -> 2.181564 | E40: =E86*$G$86/(10^6) -> 0.0053516 | F40: =F86*$G$86/(10^6) -> 1.2592e-05 | G40: =D40+(E40*$K$5)+(F40*$K$6) -> 2.3191064 | H40: IPCC Vol.2 table 3.3.1, DEDE
B41: - Industry | C41: litre | D41: =D87*$G$87/(10^6) -> 2.181564 | E41: =E87*$G$87/(10^6) -> 0.0040924 | F41: =F87*$G$87/(10^6) -> 1.2592e-05 | G41: =D41+(E41*$K$5)+(F41*$K$6) -> 2.2876264 | H41: IPCC Vol.2 table 3.3.1, DEDE
B42: - Household | C42: litre | D42: =D88*$G$88/(10^6) -> 2.181564 | E42: =E88*$G$88/(10^6) -> 0.0056664 | F42: =F88*$G$88/(10^6) -> 1.2592e-05 | G42: =D42+(E42*$K$5)+(F42*$K$6) -> 2.3269764 | H42: IPCC Vol.2 table 3.3.1, DEDE
...

Sheet EF TGO AR5
B2: ชื่อ | C2: Units | D2: EMISSION FACTORS | I2: แหล่งอ้างอิงข้อมูล | K2: GWP100
D3: CO2 | E3: Fossil CH4 | F3: CH4 | G3: N2O | H3: Total | K3: ที่มา | L3: IPCC, AR5
D4: [kg CO2/unit] | E4: [kg CH4/unit] | F4: [kg CH4/unit] | G4: [kg N2O/unit] | H4: [kg CO2eq/unit] | K4: CO2 | L4: 1
A5: Stationary Combustion | K5: Fossil CH4 | L5: 30
B6: Natural gas | C6: scf | D6: =D70*$G$70*10^-6 -> 0.057222 | E6: =E70*$G$70*10^-6 -> 1.02e-06 | G6: =F70*$G$70*10^-6 -> 1.02e-07 | H6: =D6+(E6*$L$5)+(G6*$L$7) -> 0.05727963 | I6: IPCC Vol.2 table 2.2, DEDE | K6: CH4 | L6: 28
B7: Natural gas | C7: MJ | D7: =D70/1000000 -> 0.0561 | E7: =E70/1000000 -> 1e-06 | G7: =F70/1000000 -> 1e-07 | H7: =D7+(E7*$L$5)+(G7*$L$7) -> 0.0561565 | I7: IPCC Vol.2 table 2.2, DEDE | K7: N2O | L7: 265
B8: Lignite | C8: kg | D8: =D71*$G$71*10^-6 -> 1.05747 | E8: =E71*$G$71*10^-6 -> 1.047e-05 | G8: =F71*$G$71*10^-6 -> 1.5705e-05 | H8: =D8+(E8*$L$5)+(G8*$L$7) -> 1.0619459 | I8: IPCC Vol.2 table 2.2, DEDE | K8: SF6 | L8: 23500
B9: Fuel oil A | C9: litre | D9: =D72*$G$72*10^-6 -> 3.2096984 | E9: =E72*$G$72*10^-6 -> 0.00012440692 | G9: =F72*$G$72*10^-6 -> 2.4881383e-05 | H9: =D9+(E9*$L$5)+(G9*$L$7) -> 3.2200242 | I9: IPCC Vol.2 table 2.2, PTT | K9: NF3 | L9: 16100
B10: Fuel oil C | C10: litre | D10: =D73*$G$73*10^-6 -> 3.2353401 | E10: =E73*$G$73*10^-6 -> 0.00012540078 | G10: =F73*$G$73*10^-6 -> 2.5080156e-05 | H10: =D10+(E10*$L$5)+(G10*$L$7) -> 3.2457484 | I10: IPCC Vol.2 table 2.2, PTT | K10: PASS: 12345678
B11: Gas/Diesel oil | C11: litre | D11: =D74*$G$74*10^-6 -> 2.698722 | E11: =E74*$G$74*10^-6 -> 0.00010926 | G11: =F74*$G$74*10^-6 -> 2.1852e-05 | H11: =D11+(E11*$L$5)+(G11*$L$7) -> 2.7077906 | I11: IPCC Vol.2 table 2.2, DEDE
B12: Anthracite | C12: kg | D12: =D75*$G$75*10^-6 -> 3.08662 | E12: =E75*$G$75*10^-6 -> 3.14e-05 | G12: =F75*$G$75*10^-6 -> 4.71e-05 | H12: =D12+(E12*$L$5)+(G12*$L$7) -> 3.1000435 | I12: IPCC Vol.2 table 2.2, DEDE
B13: Sub-bituminous coal | C13: kg | D13: =D76*$G$76*10^-6 -> 2.534157 | E13: =E76*$G$76*10^-6 -> 2.637e-05 | G13: =F76*$G$76*10^-6 -> 3.9555e-05 | H13: =D13+(E13*$L$5)+(G13*$L$7) -> 2.5454302 | I13: IPCC Vol.2 table 2.2, DEDE
B14: Jet Kerosene | C14: litre | D14: =D77*$G$77*10^-6 -> 2.468895 | E14: =E77*$G$77*10^-6 -> 0.00010359 | G14: =F77*$G$77*10^-6 -> 2.0718e-05 | H14: =D14+(E14*$L$5)+(G14*$L$7) -> 2.477493 | I14: IPCC Vol.2 table 2.2, DEDE
B15: LPG | C15: litre | D15: =D78*$G$78*10^-6 -> 1.679722 | E15: =E78*$G$78*10^-6 -> 2.662e-05 | G15: =F78*$G$78*10^-6 -> 2.662e-06 | H15: =D15+(E15*$L$5)+(G15*$L$7) -> 1.681226 | I15: IPCC Vol.2 table 2.2, DEDE
B16: LPG | C16: kg | D16: =D15/0.54 -> 3.1105963 | E16: =E15/0.54 -> 4.9296296e-05 | G16: =G15/0.54 -> 4.9296296e-06 | H16: =D16+(E16*$L$5)+(G16*$L$7) -> 3.1133815 | I16: IPCC Vol.2 table 2.2, DEDE LPG 1 litre = 0.54 kg
B17: Motor gasoline | C17: litre | D17: =D79*$G$79*10^-6 -> 2.181564 | E17: =E79*$G$79*10^-6 -> 9.444e-05 | G17: =F79*$G$79*10^-6 -> 1.8888e-05 | H17: =D17+(E17*$L$5)+(G17*$L$7) -> 2.1894025 | I17: IPCC Vol.2 table 2.2, DEDE
B18: FUEL WOOD | C18: kg | F18: =E80*$G$80*10^-6 -> 0.0004797 | G18: =F80*$G$80*10^-6 -> 6.396e-05 | H18: =D18+(F18*$L$6)+(G18*$L$7) -> 0.030381 | I18: IPCC Vol.2 table 2.2, DEDE
B19: Bagasse | C19: kg | F19: =E82*$G$82*10^-6 -> 0.0002259 | G19: =F82*$G$82*10^-6 -> 3.012e-05 | H19: =D19+(F19*$L$6)+(G19*$L$7) -> 0.014307 | I19: IPCC Vol.2 table 2.2, DEDE
B20: Palm kernel shell | C20: kg | F20: =E83*$G$83*10^-6 -> 0.0005559 | G20: =F83*$G$83*10^-6 -> 7.412e-05 | H20: =D20+(F20*$L$6)+(G20*$L$7) -> 0.035207 | I20: IPCC Vol.2 table 2.2, DEDE
B21: Cob | C21: kg | F21: =E84*$G$84*10^-6 -> 0.0005034 | G21: =F84*$G$84*10^-6 -> 6.712e-05 | H21: =D21+(F21*$L$6)+(G21*$L$7) -> 0.031882 | I21: IPCC Vol.2 table 2.2, DEDE
B22: Biogas | C22: m3 | F22: =E85*$G$85*10^-6 -> 2.093e-05 | G22: =F85*$G$85*10^-6 -> 2.093e-06 | H22: =D22+(F22*$L$6)+(G22*$L$7) -> 0.001140685 | I22: IPCC Vol.2 table 2.2, DEDE
B23: FUEL WOOD (CO2only) | C23: kg | D23: =D80*$G$80*10^-6 -> 1.79088 | H23: =D23+(E23*$L$5)+(G23*$L$7) -> 1.79088 | I23: IPCC Vol.2 table 2.2, DEDE
B24: Bagasse (CO2only) | C24: kg | D24: =D82*$G$82*10^-6 -> 0.753 | H24: =D24+(E24*$L$5)+(G24*$L$7) -> 0.753 | I24: IPCC Vol.2 table 2.2, DEDE
B25: Palm kernel shell (CO2only) | C25: kg | D25: =D83*$G$83*10^-6 -> 1.853 | H25: =D25+(E25*$L$5)+(G25*$L$7) -> 1.853 | I25: IPCC Vol.2 table 2.2, DEDE
B26: Cob (CO2only) | C26: kg | D26: =D84*$G$84*10^-6 -> 1.678 | H26: =D26+(E26*$L$5)+(G26*$L$7) -> 1.678 | I26: IPCC Vol.2 table 2.2, DEDE
B27: Biogas (CO2only) | C27: m3 | D27: =D85*$G$85*10^-6 -> 1.142778 | H27: =D27+(E27*$L$5)+(G27*$L$7) -> 1.142778 | I27: IPCC Vol.2 table 2.2, DEDE
A28: Mobile Combustion (On road)
B29: Motor Gasoline - uncontrolled | C29: litre | D29: =D91*$G$91*10^-6 -> 2.181564 | E29: =E91*$G$91*10^-6 -> 0.00103884 | G29: =F91*$G$91*10^-6 -> 0.000100736 | H29: =D29+(E29*$L$5)+(G29*$L$7) -> 2.2394242 | I29: IPCC Vol.2 table 3.2.1, 3.2.2, DEDE
B30: Motor Gasoline - oxydation catalyst | C30: litre | D30: =D92*$G$92*10^-6 -> 2.181564 | E30: =E92*$G$92*10^-6 -> 0.000787 | G30: =F92*$G$92*10^-6 -> 0.00025184 | H30: =D30+(E30*$L$5)+(G30*$L$7) -> 2.2719116 | I30: IPCC Vol.2 table 3.2.1, 3.2.2, DEDE
B31: Motor Gasoline - low mileage light duty vihicle vintage 1995 or later | C31: litre | D31: =D93*$G$93*10^-6 -> 2.181564 | E31: =E93*$G$93*10^-6 -> 0.000119624 | G31: =F93*$G$93*10^-6 -> 0.000179436 | H31: =D31+(E31*$L$5)+(G31*$L$7) -> 2.2327033 | I31: IPCC Vol.2 table 3.2.1, 3.2.2, DEDE
B32: Gas/ Diesel Oil | C32: litre | D32: =D94*$G$94*10^-6 -> 2.698722 | E32: =E94*$G$94*10^-6 -> 0.000142038 | G32: =F94*$G$94*10^-6 -> 0.000142038 | H32: =D32+(E32*$L$5)+(G32*$L$7) -> 2.7406232 | I32: IPCC Vol.2 table 3.2.1, 3.2.2, DEDE
B33: Compressed Natural Gas | C33: kg | D33: =D95*$G$95*10^-6 -> 2.12619 | E33: =E95*$G$95*10^-6 -> 0.0034868 | G33: =F95*$G$95*10^-6 -> 0.0001137 | H33: =D33+(E33*$L$5)+(G33*$L$7) -> 2.2609245 | I33: IPCC Vol.2 table 3.2.1, 3.2.2, PTT
B34: Liquified Petroleum Gas | C34: litre | D34: =D96*$G$96*10^-6 -> 1.679722 | E34: =E96*$G$96*10^-6 -> 0.00165044 | G34: =F96*$G$96*10^-6 -> 5.324e-06 | H34: =D34+(E34*$L$5)+(G34*$L$7) -> 1.7306461 | I34: IPCC Vol.2 table 3.2.1, 3.2.2, DEDE
B35: Liquified Petroleum Gas | C35: kg | D35: =D34/0.54 -> 3.1105963 | E35: =E34/0.54 -> 0.0030563704 | G35: =G34/0.54 -> 9.8592593e-06 | H35: =D35+(E35*$L$5)+(G35*$L$7) -> 3.2049001 | I35: IPCC Vol.2 table 3.2.1, 3.2.2, DEDE LPG 1 litre = 0.54 kg
A36: Mobile Combustion (Off road)
B37: Diesel
B38: - Agriculture | C38: litre | D38: =D103*$G$103/(10^6) -> 2.698722 | E38: =E103*$G$103/(10^6) -> 0.000151143 | G38: =F103*$G$103/(10^6) -> 0.001041612 | H38: =D38+(E38*$L$5)+(G38*$L$7) -> 2.9792835 | I38: IPCC Vol.2 table 3.3.1, DEDE
B39: - Forestry | C39: litre | D39: =D104*$G$104/(10^6) -> 2.698722 | E39: =E104*$G$104/(10^6) -> 0.000151143 | G39: =F104*$G$104/(10^6) -> 0.001041612 | H39: =D39+(E39*$L$5)+(G39*$L$7) -> 2.9792835 | I39: IPCC Vol.2 table 3.3.1, DEDE
B40: - Industry | C40: litre | D40: =D105*$G$105/(10^6) -> 2.698722 | E40: =E105*$G$105/(10^6) -> 0.000151143 | G40: =F105*$G$105/(10^6) -> 0.001041612 | H40: =D40+(E40*$L$5)+(G40*$L$7) -> 2.9792835 | I40: IPCC Vol.2 table 3.3.1, DEDE
B41: - Household | C41: litre | D41: =D106*$G$106/(10^6) -> 2.698722 | E41: =E106*$G$106/(10^6) -> 0.000151143 | G41: =F106*$G$106/(10^6) -> 0.001041612 | H41: =D41+(E41*$L$5)+(G41*$L$7) -> 2.9792835 | I41: IPCC Vol.2 table 3.3.1, DEDE
...

Sheet บันทึกการปรับปรุง
A1: บันทึกการแก้ไข
A2: วันที่ | B2: ลำดับ | C2: Sheet | D2: Cell | E2: รายละเอียด | F2: ผู้ทำการแก้ไข
A4: 241864 | B4: 1 | C4: Fr-04 | D4: AM,AN,AO | E4: เพิ่มการคำนวณสัดส่วน (%) | F4: มนต์ชัย จิตติปัญญากุล
A5: 241864 | B5: 2 | C5: Fr-05 | D5: C10-C13 | E5: ลบสูตร Round up | F5: มนต์ชัย จิตติปัญญากุล
A6: 241864 | B6: 3 | C6: Fr-05 | D6: B15 | E6: เพิ่มการคำนวณรวม Scope 1 & 2 & 3 | F6: มนต์ชัย จิตติปัญญากุล
A7: 241864 | B7: 4 | C7: TGO_EF | E7: เพิ่ม EF Gasoline Stationary Combustion | F7: มนต์ชัย จิตติปัญญากุล
A8: 242229 | B8: 5 | C8: TGO_EF | E8: เพิ่ม Sheet EF TGO AR5 | F8: มนต์ชัย จิตติปัญญากุล
A9: 242229 | B9: 6 | C9: Fr-04 | E9: แก้ไขสูตรการคำนวณให้ใช้ GWP AR5 | F9: มนต์ชัย จิตติปัญญากุล
A10: 242355 | B10: 7 | C10: Fr-05 | E10: ใส่สูตร Roundup ในแต่ละ SCOPE | F10: มนต์ชัย จิตติปัญญากุล
A11: 242433 | B11: 8 | C11: TGO_EF | E11: เพิ่ม EF ไฟฟ้า และสารทำความเย็น | F11: มนต์ชัย จิตติปัญญากุล
A12: 242433 | B12: 9 | C12: Fr-01 Fr-05 | E12: เพิ่ม การคำนวณ Carbon Intensity | F12: มนต์ชัย จิตติปัญญากุล
A13: 242783 | B13: 10 | C13: Fr-01, Fr-04.2, Fr-05 | E13: เพิ่ม การคำนวณปีฐาน | F13: มนต์ชัย จิตติปัญญากุล
A14: 242783 | B14: 11 | C14: EF TGO AR5 | E14: เพิ่ม EF Biomass | F14: มนต์ชัย จิตติปัญญากุล
A15: 242783 | B15: 12 | C15: Fr-03.2 | E15: เพิ่ม Fr-03.2 ประเมินความมีนัยสำคัญของการปล่อยก๊าซเรือนกระจกทางอ้อม (SCOPE 3) | F15: มนต์ชัย จิตติปัญญากุล
A16: 242879 | B16: 13 | C16: EF TGO AR5 | E16: เพิ่มค่า GWP Fossil CH4 และแก้ไขการคำนวณ EF การเผาไหม้เชื้อเพลิงฟอสซิล | F16: มนต์ชัย จิตติปัญญากุล
A17: 242879 | B17: 14 | C17: Fr-04.1 | E17: เพิ่มค่า GWP Fossil CH4 และแก้ไขการคำนวณ Total (kgCO2e/หน่วย) | F17: มนต์ชัย จิตติปัญญากุล
A18: 243016 | B18: 15 | C18: Fr-04.1 | E18: เพิ่มคอลัมน์ Fossil CH4 | F18: มนต์ชัย จิตติปัญญากุล
... A20: 243016 | B20: 17 | C20: EF TGO AR5 | E20: เพิ่มคอลัมน์ Fossil CH4 | F20: มนต์ชัย จิตติปัญญากุล

Sheet 1.1 Stationary 
A1: Stationary combustion
A2: รายการ | C2: ชนิด | D2: หลักฐาน | E2: หน่วย | F2: ปริมาณน้ำมัน | G2: Diesel (Stationary combustion) | H2: Biodiesel (Stationary combustion) | J2: Gasoline (Stationary combustion) | K2: Ethanol (Stationary combustion)
G3: L | H3: L | I3: kg | J3: L | K3: L | L3: kg
A4: =A9 -> น้ำมัน Diesel B7 (Fire Pump) | C4: B7 | D4: =B9 -> 0 | E4: L | F4: =D9 -> 0 | G4: =F4*0.93 -> 0 | H4: =F4-G4 -> 0 | I4: =H4*0.87 -> 0
A5: =A10 -> น้ำมัน Gasohol 91/95 (เครื่องตัดหญ้า) | C5: 91/95 | D5: =B10 -> 0 | E5: L | F5: =D10 -> 0 | J5: =F5*0.9 -> 0 | K5: =F5-J5 -> 0 | L5: =K5*0.79 -> 0
A7: รายการ | B7: หลักฐาน | C7: หน่วย | D7: รวม | E7: ปริมาณการใช้แต่ละเดือน/2566
E8: 1 | F8: 2 | G8: 3 | H8: 4 | I8: 5 | J8: 6 | K8: 7 | L8: 8 | M8: 9 | N8: 10 | O8: 11 | P8: 12
A9: น้ำมัน Diesel B7 (Fire Pump) | B9: =IFERROR(_xlfn.XLOOKUP("DIESEL_B7_STATIONARY",tblScope11Stationary[RowId],tblScope11Stationary[Evidence],""),"") | C9: =IFERROR(_xlfn.XLOOKUP("DIESEL_B7_STATIONARY",tblScope11Stationary[RowId],tblScope11Stationary[Unit],""),"") | D9: =SUM(E9:P9) -> 0 | E9: =IFERROR(_xlfn.XLOOKUP("DIESEL_B7_STATIONARY",tblScope11Stationary[RowId],tblScope11Stationary[M1],""),"") | F9: =IFERROR(_xlfn.XLOOKUP("DIESEL_B7_STATIONARY",tblScope11Stationary[RowId],tblScope11Stationary[M2],""),"") | G9: =IFERROR(_xlfn.XLOOKUP("DIESEL_B7_STATIONARY",tblScope11Stationary[RowId],tblScope11Stationary[M3],""),"") | H9: =IFERROR(_xlfn.XLOOKUP("DIESEL_B7_STATIONARY",tblScope11Stationary[RowId],tblScope11Stationary[M4],""),"") | I9: =IFERROR(_xlfn.XLOOKUP("DIESEL_B7_STATIONARY",tblScope11Stationary[RowId],tblScope11Stationary[M5],""),"") | J9: =IFERROR(_xlfn.XLOOKUP("DIESEL_B7_STATIONARY",tblScope11Stationary[RowId],tblScope11Stationary[M6],""),"") | K9: =IFERROR(_xlfn.XLOOKUP("DIESEL_B7_STATIONARY",tblScope11Stationary[RowId],tblScope11Stationary[M7],""),"") | L9: =IFERROR(_xlfn.XLOOKUP("DIESEL_B7_STATIONARY",tblScope11Stationary[RowId],tblScope11Stationary[M8],""),"") | M9: =IFERROR(_xlfn.XLOOKUP("DIESEL_B7_STATIONARY",tblScope11Stationary[RowId],tblScope11Stationary[M9],""),"") | N9: =IFERROR(_xlfn.XLOOKUP("DIESEL_B7_STATIONARY",tblScope11Stationary[RowId],tblScope11Stationary[M10],""),"") | O9: =IFERROR(_xlfn.XLOOKUP("DIESEL_B7_STATIONARY",tblScope11Stationary[RowId],tblScope11Stationary[M11],""),"") | P9: =IFERROR(_xlfn.XLOOKUP("DIESEL_B7_STATIONARY",tblScope11Stationary[RowId],tblScope11Stationary[M12],""),"")
